Workbook
Name a: #REF!
Name a: #REF!
Name a: #REF!
Name a: #REF!
Name AGGREGATION: #REF!
Name AGGREGATION: #REF!
Name AGGREGATION: #REF!
Name AGGREGATION: #REF!
Name BankCode: [1]Cover!$E$3
Name CHECK: #REF!
Name CHECK: #REF!
Name CHECK: #REF!
Name CHECK: #REF!
Name CurrencyCode: OFFSET([1]wksCurrency!$B$2:$B$27,1,0,ROWS([1]wksCurrency!$B$2:$B$27)-2)
Name CurrencyName: OFFSET([1]wksCurrency!$A$2:$A$27,1,0,ROWS([1]wksCurrency!$A$2:$A$27)-2)
Name date: [2]BSY_현지화!#REF!
Name date: [2]BSY_현지화!#REF!
Name date: [2]BSY_현지화!#REF!
Name date: [2]BSY_현지화!#REF!
Name DOMAIN: #REF!
Name DOMAIN: #REF!
Name DOMAIN: #REF!
Name DOMAIN: #REF!
Name ENTITY: #REF!
Name ENTITY: #REF!
Name ENTITY: #REF!
Name ENTITY: #REF!
Name FORMAT: #REF!
Name FORMAT: #REF!
Name FORMAT: #REF!
Name FORMAT: #REF!
Name half: [2]BSY_현지화!#REF!
Name half: [2]BSY_현지화!#REF!
Name half: [2]BSY_현지화!#REF!
Name half: [2]BSY_현지화!#REF!
Name ODB_DATA_TYPE: #REF!
Name ODB_DATA_TYPE: #REF!
Name ODB_DATA_TYPE: #REF!
Name ODB_DATA_TYPE: #REF!
Name PREPOPULATE: #REF!
Name PREPOPULATE: #REF!
Name PREPOPULATE: #REF!
Name PREPOPULATE: #REF!
Name REPORTING_CONS: [3]Lists!$J$2:$J$7
Name SEVERITY: #REF!
Name SEVERITY: #REF!
Name SEVERITY: #REF!
Name SEVERITY: #REF!
Name STATUS: #REF!
Name STATUS: #REF!
Name STATUS: #REF!
Name STATUS: #REF!
Name term: [2]BSY_현지화!#REF!
Name term: [2]BSY_현지화!#REF!
Name term: [2]BSY_현지화!#REF!
Name term: [2]BSY_현지화!#REF!
Name YD: [2]BSY_현지화!#REF!
Name YD: [2]BSY_현지화!#REF!
Name YD: [2]BSY_현지화!#REF!
Name YD: [2]BSY_현지화!#REF!

Sheet Reviews
B1: Reviews & Comments
B3: Form Code | C3: Form Name | D3: Form Items | E3: Questions/Comments | F3: By | G3: Date (DD/MM/YY) | H3: Responses | I3: By | J3: Date (DD/MM/YY)
B4: ARF 117_0A | C4: Repricing analysis - denominated in AUD | D4: N/A | E4: N/A | F4: YH | G4: ='[5]Checklist & Lodgement'!K17 -> 44868
B5: ARF 117_0B_1 | C5: Repricing analysis - denominated in foreign currency_1 | D5: N/A | E5: N/A | F5: YH | G5: =G4 -> 44868
B6: ARF 117_0B_2 | C6: Repricing analysis - denominated in foreign currency_2 | D6: N/A | E6: N/A | F6: YH | G6: =G5 -> 44868
B7: ARF 117_0B_3 | C7: Repricing analysis - denominated in foreign currency_3 | D7: N/A | E7: N/A | F7: YH | G7: =G6 -> 44868
B8: ARF 117_0B_4 | C8: Repricing analysis - denominated in foreign currency_4 | D8: N/A | E8: N/A | F8: YH | G8: =G7 -> 44868

Sheet RE33(IRRBB)
A1: ※ 주의
A2: 10690001 | B2: --Allowance For Loan Losses - General | C2: 계수 부호 변경 및 Liability 항목 | K2: Compounded SOFR (Repricing: Overnight (O/N)) | L2: 10630001_USD_100000014_PERDAMAN CHEMICALS & FERTILISERS (FINANCE)PTY LTD | P2: =ROUND(SUM(Q3:AG3)-SUM(Q4:AG4),0)=ROUND(SUM(Q5:AG5),0) -> TRUE | Q2: Overnight (O/N) | R2: 0 to <1 month (excluding O/N) | S2: 1 to < 2 months | T2: 2 to < 3 months | U2: 3 to < 6 months | V2: 6 to < 9 months | W2: 9 to < 12 months | X2: 1 to < 2 years | Y2: 2 to < 3 years | Z2: 3 to < 4 years | AA2: 4 to < 5 years | AB2: 5 to < 7 years | AC2: 7 to < 10 years | AD2: 10 to < 15 years | AE2: 15 to < 20 years | AF2: 20+ years | AG2: Non-interest rate sensitive
A3: 10690001 | B3: Allowance For Loan Losses - General | L3: 10620001_USD_100000033_MACQUARIE GROUP LIMITED | P3: Asset | Q3: =SUMIF($P$12:$P$681,$P$3,Q12:Q681) -> 1.3026423e+08 | R3: =SUMIF($P$12:$P$681,$P$3,R12:R681) -> 82224385 | S3: =SUMIF($P$12:$P$681,$P$3,S12:S681) -> 17184061 | T3: =SUMIF($P$12:$P$681,$P$3,T12:T681) -> 28000000 | U3: =SUMIF($P$12:$P$681,$P$3,U12:U681) -> 10000000 | V3: =SUMIF($P$12:$P$681,$P$3,V12:V681) -> 5053962.5 | W3: =SUMIF($P$12:$P$681,$P$3,W12:W681) -> 0 | X3: =SUMIF($P$12:$P$681,$P$3,X12:X681) -> 16463021 | ... AG3: =SUMIF($P$12:$P$681,$P$3,AG12:AG681) -> 2765808.7
A4: 10690003 | B4: --Allowance for Due from Banks | P4: Liability | Q4: =SUMIF($P$12:$P$681,$P$4,Q12:Q681) -> 0 | R4: =SUMIF($P$12:$P$681,$P$4,R12:R681) -> 1.1426042e+08 | S4: =SUMIF($P$12:$P$681,$P$4,S12:S681) -> 74955979 | T4: =SUMIF($P$12:$P$681,$P$4,T12:T681) -> 31437554 | U4: =SUMIF($P$12:$P$681,$P$4,U12:U681) -> 15718777 | V4: =SUMIF($P$12:$P$681,$P$4,V12:V681) -> 0 | W4: =SUMIF($P$12:$P$681,$P$4,W12:W681) -> 0 | X4: =SUMIF($P$12:$P$681,$P$4,X12:X681) -> 0 | ... AG4: =SUMIF($P$12:$P$681,$P$4,AG12:AG681) -> 55129544
A5: 10690004 | B5: Allowance for NCD | P5: Equity | Q5: =SUMIF($P$12:$P$681,$P$5,Q12:Q681) -> 0 | R5: =SUMIF($P$12:$P$681,$P$5,R12:R681) -> 138.06 | S5: =SUMIF($P$12:$P$681,$P$5,S12:S681) -> 66917.51 | T5: =SUMIF($P$12:$P$681,$P$5,T12:T681) -> 0 | U5: =SUMIF($P$12:$P$681,$P$5,U12:U681) -> 0 | V5: =SUMIF($P$12:$P$681,$P$5,V12:V681) -> 712.5 | W5: =SUMIF($P$12:$P$681,$P$5,W12:W681) -> 0 | X5: =SUMIF($P$12:$P$681,$P$5,X12:X681) -> 66354.42 | ... AG5: =SUMIF($P$12:$P$681,$P$5,AG12:AG681) -> 319075.03
A6: 10690006 | B6: Allowance for Lending
A7: 10690007 | B7: Allowance for Call Loan | P7: Net position/gap | Q7: =Q3-Q4 -> 1.3026423e+08 | R7: =R3-R4 -> -32036037 | S7: =S3-S4 -> -57771918 | T7: =T3-T4 -> -3437553.6 | U7: =U3-U4 -> -5718776.8 | V7: =V3-V4 -> 5053962.5 | W7: =W3-W4 -> 0 | X7: =X3-X4 -> 16463021 | ... AG7: =AG3-AG4 -> -52363735
A8: 20920006 | B8: Unearned Income ON SYNDICATED LOANS | C8: 계수 부호 변경 및 Asset 항목
N9: Repricing Maturity Buckets | P9: From | Q9: =M10 -> 46058 | R9: =Q10 -> 46059 | S9: =R10 -> 46112 | T9: =S10 -> 46142 | U9: =T10 -> 46173 | V9: =U10 -> 46265 | W9: =V10 -> 46356 | X9: =W10 -> 46446 | Y9: =X10 -> 46812 | ... AF9: =AE10 -> 53386 | AG9: Non_sensitive
M10: 46058 | P10: To | Q10: =Q9+1 -> 46059 | R10: =EOMONTH(Q9,1) -> 46112 | S10: =EOMONTH(S9,1) -> 46142 | T10: =EOMONTH(T9,1) -> 46173 | U10: =EOMONTH(U9,3) -> 46265 | V10: =EOMONTH(V9,3) -> 46356 | W10: =EOMONTH(W9,3) -> 46446 | X10: =EOMONTH(X9,12) -> 46812 | Y10: =EOMONTH(Y9,12) -> 47177 | Z10: =EOMONTH(Z9,12) -> 47542 | AA10: =EOMONTH(AA9,12) -> 47907 | AB10: =EOMONTH(AB9,24) -> 48638 | AC10: =EOMONTH(AC9,36) -> 49734 | AD10: =EOMONTH(AD9,60) -> 51560 | AE10: =EOMONTH(AE9,60) -> 53386 | AF10: =EOMONTH(AF9,120) -> 57039
A11: A/C Code | B11: A/C Name | C11: Ref No | D11: Counterparty/Customer No | E11: Counterparty/Customer Name | F11: Ccy | G11: Balance Amt | H11: Base Ccy Amt | I11: Approval/Contract Date | J11: Maturity Date | K11: Next Interest Reset Date | L11: Ref. | M11: Adjusted Amount | N11: Repricing Date | O11: Check | P11: Asset / Liability | Q11: Overnight (O/N) | R11: 0 to <1 month (excluding O/N) | S11: 1 to < 2 months | T11: 2 to < 3 months | U11: 3 to < 6 months | V11: 6 to < 9 months | W11: 9 to < 12 months | X11: 1 to < 2 years | Y11: 2 to < 3 years | Z11: 3 to < 4 years | AA11: 4 to < 5 years | AB11: 5 to < 7 years | AC11: 7 to < 10 years | AD11: 10 to < 15 years | AE11: 15 to < 20 years | AF11: 20+ years | AG11: Non-interest rate sensitive
A12: 10212001 | B12: Due from Domestic Banks on Demand | C12: RCH3001AUD | D12: 100000006 | E12: AUSTRALIA AND NEW ZEALAND BANKING GROUP LTD | F12: AUD | G12: 7807.52 | H12: 7807.52 | L12: =A12&"_"&F12&"_"&D12&"_"&E12 -> 10212001_AUD_100000006_AUSTRALIA AND NEW ZEALAND BANKING GROUP LTD | M12: =IF(COUNTIF($A$2:$A$8,A12)>0,-H12,H12) -> 7807.52 | N12: =IF(OR(L12=$L$2,L12=$L$3),$M$10+1,IFERROR(VLOOKUP(A12,'Repricing Maturity Adj.'!$A$3:$C$170,3,0),(IF(K12<$M$10,"Check",K12)))) -> 46059 | O12: =M12=SUM(Q12:AG12) -> TRUE | P12: =IF(A12="","N/A",IF(COUNTIF($A$2:$A$7,A12)>0,"Liability",IF(COUNTIF($A$8,A12)>0,"Asset",IF(A12<20000000,"Asset",IF(AND(A12>20000000,A12<28800000),"Liability",IF(A12>28800000,"Equity","")))))) -> Asset | Q12: =IF(AND(N12>$Q$9,N12<$Q$10),M12,IF(N12=$Q$10,M12,0)) -> 7807.52 | R12: =IF(AND(N12>$R$9,N12<$R$10),M12,IF(N12=$R$10,M12,0)) -> 0 | S12: =IF(AND(N12>$S$9,N12<$S$10),M12,IF(N12=$S$10,M12,0)) -> 0 | T12: =IF(AND(N12>$T$9,N12<$T$10),M12,IF(N12=$T$10,M12,0)) -> 0 | U12: =IF(AND(N12>$U$9,N12<$U$10),M12,IF(N12=$U$10,M12,0)) -> 0 | V12: =IF(AND(N12>$V$9,N12<$V$10),M12,IF(N12=$V$10,M12,0)) -> 0 | W12: =IF(AND(N12>$W$9,N12<$W$10),M12,IF(N12=$W$10,M12,0)) -> 0 | X12: =IF(AND(N12>$X$9,N12<$X$10),M12,IF(N12=$X$10,M12,0)) -> 0 | Y12: =IF(AND(N12>$Y$9,N12<$Y$10),M12,IF(N12=$Y$10,M12,0)) -> 0 | Z12: =IF(AND(N12>$Z$9,N12<$Z$10),M12,IF(N12=$Z$10,M12,0)) -> 0 | AA12: =IF(AND(N12>$AA$9,N12<$AA$10),M12,IF(N12=$AA$10,M12,0)) -> 0 | AB12: =IF(AND(N12>$AB$9,N12<$AB$10),M12,IF(N12=$AB$10,M12,0)) -> 0 | AC12: =IF(AND(N12>$AC$9,N12<$AC$10),M12,IF(N12=$AC$10,M12,0)) -> 0 | AD12: =IF(AND(N12>$AD$9,N12<$AD$10),M12,IF(N12=$AD$10,M12,0)) -> 0 | AE12: =IF(AND(N12>$AE$9,N12<$AE$10),M12,IF(N12=$AE$10,M12,0)) -> 0 | AF12: =IF(AND(N12>$AF$9,N12<$AF$10),M12,IF(N12=$AF$10,M12,0)) -> 0 | AG12: =IF(N12=$AG$9,M12,0) -> 0
A13: 10212001 | B13: Due from Domestic Banks on Demand | C13: RCH3002AUD | D13: 100000006 | E13: AUSTRALIA AND NEW ZEALAND BANKING GROUP LTD | F13: AUD | G13: 4896.04 | H13: 4896.04 | L13: =A13&"_"&F13&"_"&D13&"_"&E13 -> 10212001_AUD_100000006_AUSTRALIA AND NEW ZEALAND BANKING GROUP LTD | M13: =IF(COUNTIF($A$2:$A$8,A13)>0,-H13,H13) -> 4896.04 | N13: =IF(OR(L13=$L$2,L13=$L$3),$M$10+1,IFERROR(VLOOKUP(A13,'Repricing Maturity Adj.'!$A$3:$C$170,3,0),(IF(K13<$M$10,"Check",K13)))) -> 46059 | O13: =M13=SUM(Q13:AG13) -> TRUE | P13: =IF(A13="","N/A",IF(COUNTIF($A$2:$A$7,A13)>0,"Liability",IF(COUNTIF($A$8,A13)>0,"Asset",IF(A13<20000000,"Asset",IF(AND(A13>20000000,A13<28800000),"Liability",IF(A13>28800000,"Equity","")))))) -> Asset | Q13: =IF(AND(N13>$Q$9,N13<$Q$10),M13,IF(N13=$Q$10,M13,0)) -> 4896.04 | R13: =IF(AND(N13>$R$9,N13<$R$10),M13,IF(N13=$R$10,M13,0)) -> 0 | S13: =IF(AND(N13>$S$9,N13<$S$10),M13,IF(N13=$S$10,M13,0)) -> 0 | T13: =IF(AND(N13>$T$9,N13<$T$10),M13,IF(N13=$T$10,M13,0)) -> 0 | U13: =IF(AND(N13>$U$9,N13<$U$10),M13,IF(N13=$U$10,M13,0)) -> 0 | V13: =IF(AND(N13>$V$9,N13<$V$10),M13,IF(N13=$V$10,M13,0)) -> 0 | W13: =IF(AND(N13>$W$9,N13<$W$10),M13,IF(N13=$W$10,M13,0)) -> 0 | X13: =IF(AND(N13>$X$9,N13<$X$10),M13,IF(N13=$X$10,M13,0)) -> 0 | Y13: =IF(AND(N13>$Y$9,N13<$Y$10),M13,IF(N13=$Y$10,M13,0)) -> 0 | Z13: =IF(AND(N13>$Z$9,N13<$Z$10),M13,IF(N13=$Z$10,M13,0)) -> 0 | AA13: =IF(AND(N13>$AA$9,N13<$AA$10),M13,IF(N13=$AA$10,M13,0)) -> 0 | AB13: =IF(AND(N13>$AB$9,N13<$AB$10),M13,IF(N13=$AB$10,M13,0)) -> 0 | AC13: =IF(AND(N13>$AC$9,N13<$AC$10),M13,IF(N13=$AC$10,M13,0)) -> 0 | AD13: =IF(AND(N13>$AD$9,N13<$AD$10),M13,IF(N13=$AD$10,M13,0)) -> 0 | AE13: =IF(AND(N13>$AE$9,N13<$AE$10),M13,IF(N13=$AE$10,M13,0)) -> 0 | AF13: =IF(AND(N13>$AF$9,N13<$AF$10),M13,IF(N13=$AF$10,M13,0)) -> 0 | AG13: =IF(N13=$AG$9,M13,0) -> 0
A14: 10212001 | B14: Due from Domestic Banks on Demand | C14: RCH3003AUD | D14: 100000006 | E14: AUSTRALIA AND NEW ZEALAND BANKING GROUP LTD | F14: AUD | G14: 87377.23 | H14: 87377.23 | L14: =A14&"_"&F14&"_"&D14&"_"&E14 -> 10212001_AUD_100000006_AUSTRALIA AND NEW ZEALAND BANKING GROUP LTD | M14: =IF(COUNTIF($A$2:$A$8,A14)>0,-H14,H14) -> 87377.23 | N14: =IF(OR(L14=$L$2,L14=$L$3),$M$10+1,IFERROR(VLOOKUP(A14,'Repricing Maturity Adj.'!$A$3:$C$170,3,0),(IF(K14<$M$10,"Check",K14)))) -> 46059 | O14: =M14=SUM(Q14:AG14) -> TRUE | P14: =IF(A14="","N/A",IF(COUNTIF($A$2:$A$7,A14)>0,"Liability",IF(COUNTIF($A$8,A14)>0,"Asset",IF(A14<20000000,"Asset",IF(AND(A14>20000000,A14<28800000),"Liability",IF(A14>28800000,"Equity","")))))) -> Asset | Q14: =IF(AND(N14>$Q$9,N14<$Q$10),M14,IF(N14=$Q$10,M14,0)) -> 87377.23 | R14: =IF(AND(N14>$R$9,N14<$R$10),M14,IF(N14=$R$10,M14,0)) -> 0 | S14: =IF(AND(N14>$S$9,N14<$S$10),M14,IF(N14=$S$10,M14,0)) -> 0 | T14: =IF(AND(N14>$T$9,N14<$T$10),M14,IF(N14=$T$10,M14,0)) -> 0 | U14: =IF(AND(N14>$U$9,N14<$U$10),M14,IF(N14=$U$10,M14,0)) -> 0 | V14: =IF(AND(N14>$V$9,N14<$V$10),M14,IF(N14=$V$10,M14,0)) -> 0 | W14: =IF(AND(N14>$W$9,N14<$W$10),M14,IF(N14=$W$10,M14,0)) -> 0 | X14: =IF(AND(N14>$X$9,N14<$X$10),M14,IF(N14=$X$10,M14,0)) -> 0 | Y14: =IF(AND(N14>$Y$9,N14<$Y$10),M14,IF(N14=$Y$10,M14,0)) -> 0 | Z14: =IF(AND(N14>$Z$9,N14<$Z$10),M14,IF(N14=$Z$10,M14,0)) -> 0 | AA14: =IF(AND(N14>$AA$9,N14<$AA$10),M14,IF(N14=$AA$10,M14,0)) -> 0 | AB14: =IF(AND(N14>$AB$9,N14<$AB$10),M14,IF(N14=$AB$10,M14,0)) -> 0 | AC14: =IF(AND(N14>$AC$9,N14<$AC$10),M14,IF(N14=$AC$10,M14,0)) -> 0 | AD14: =IF(AND(N14>$AD$9,N14<$AD$10),M14,IF(N14=$AD$10,M14,0)) -> 0 | AE14: =IF(AND(N14>$AE$9,N14<$AE$10),M14,IF(N14=$AE$10,M14,0)) -> 0 | AF14: =IF(AND(N14>$AF$9,N14<$AF$10),M14,IF(N14=$AF$10,M14,0)) -> 0 | AG14: =IF(N14=$AG$9,M14,0) -> 0
A15: 10212001 | B15: Due from Domestic Banks on Demand | C15: RCH3004AUD | D15: 100000013 | E15: KEB HANA BANK | F15: AUD | G15: 4600972.1 | H15: 4600972.1 | L15: =A15&"_"&F15&"_"&D15&"_"&E15 -> 10212001_AUD_100000013_KEB HANA BANK | M15: =IF(COUNTIF($A$2:$A$8,A15)>0,-H15,H15) -> 4600972.1 | N15: =IF(OR(L15=$L$2,L15=$L$3),$M$10+1,IFERROR(VLOOKUP(A15,'Repricing Maturity Adj.'!$A$3:$C$170,3,0),(IF(K15<$M$10,"Check",K15)))) -> 46059 | O15: =M15=SUM(Q15:AG15) -> TRUE | P15: =IF(A15="","N/A",IF(COUNTIF($A$2:$A$7,A15)>0,"Liability",IF(COUNTIF($A$8,A15)>0,"Asset",IF(A15<20000000,"Asset",IF(AND(A15>20000000,A15<28800000),"Liability",IF(A15>28800000,"Equity","")))))) -> Asset | Q15: =IF(AND(N15>$Q$9,N15<$Q$10),M15,IF(N15=$Q$10,M15,0)) -> 4600972.1 | R15: =IF(AND(N15>$R$9,N15<$R$10),M15,IF(N15=$R$10,M15,0)) -> 0 | S15: =IF(AND(N15>$S$9,N15<$S$10),M15,IF(N15=$S$10,M15,0)) -> 0 | T15: =IF(AND(N15>$T$9,N15<$T$10),M15,IF(N15=$T$10,M15,0)) -> 0 | U15: =IF(AND(N15>$U$9,N15<$U$10),M15,IF(N15=$U$10,M15,0)) -> 0 | V15: =IF(AND(N15>$V$9,N15<$V$10),M15,IF(N15=$V$10,M15,0)) -> 0 | W15: =IF(AND(N15>$W$9,N15<$W$10),M15,IF(N15=$W$10,M15,0)) -> 0 | X15: =IF(AND(N15>$X$9,N15<$X$10),M15,IF(N15=$X$10,M15,0)) -> 0 | Y15: =IF(AND(N15>$Y$9,N15<$Y$10),M15,IF(N15=$Y$10,M15,0)) -> 0 | Z15: =IF(AND(N15>$Z$9,N15<$Z$10),M15,IF(N15=$Z$10,M15,0)) -> 0 | AA15: =IF(AND(N15>$AA$9,N15<$AA$10),M15,IF(N15=$AA$10,M15,0)) -> 0 | AB15: =IF(AND(N15>$AB$9,N15<$AB$10),M15,IF(N15=$AB$10,M15,0)) -> 0 | AC15: =IF(AND(N15>$AC$9,N15<$AC$10),M15,IF(N15=$AC$10,M15,0)) -> 0 | AD15: =IF(AND(N15>$AD$9,N15<$AD$10),M15,IF(N15=$AD$10,M15,0)) -> 0 | AE15: =IF(AND(N15>$AE$9,N15<$AE$10),M15,IF(N15=$AE$10,M15,0)) -> 0 | AF15: =IF(AND(N15>$AF$9,N15<$AF$10),M15,IF(N15=$AF$10,M15,0)) -> 0 | AG15: =IF(N15=$AG$9,M15,0) -> 0
A16: 10212001 | B16: Due from Domestic Banks on Demand | C16: RCH3004USD | D16: 100000013 | E16: KEB HANA BANK | F16: USD | G16: 1351406.1 | H16: 1931131.9 | L16: =A16&"_"&F16&"_"&D16&"_"&E16 -> 10212001_USD_100000013_KEB HANA BANK | M16: =IF(COUNTIF($A$2:$A$8,A16)>0,-H16,H16) -> 1931131.9 | N16: =IF(OR(L16=$L$2,L16=$L$3),$M$10+1,IFERROR(VLOOKUP(A16,'Repricing Maturity Adj.'!$A$3:$C$170,3,0),(IF(K16<$M$10,"Check",K16)))) -> 46059 | O16: =M16=SUM(Q16:AG16) -> TRUE | P16: =IF(A16="","N/A",IF(COUNTIF($A$2:$A$7,A16)>0,"Liability",IF(COUNTIF($A$8,A16)>0,"Asset",IF(A16<20000000,"Asset",IF(AND(A16>20000000,A16<28800000),"Liability",IF(A16>28800000,"Equity","")))))) -> Asset | Q16: =IF(AND(N16>$Q$9,N16<$Q$10),M16,IF(N16=$Q$10,M16,0)) -> 1931131.9 | R16: =IF(AND(N16>$R$9,N16<$R$10),M16,IF(N16=$R$10,M16,0)) -> 0 | S16: =IF(AND(N16>$S$9,N16<$S$10),M16,IF(N16=$S$10,M16,0)) -> 0 | T16: =IF(AND(N16>$T$9,N16<$T$10),M16,IF(N16=$T$10,M16,0)) -> 0 | U16: =IF(AND(N16>$U$9,N16<$U$10),M16,IF(N16=$U$10,M16,0)) -> 0 | V16: =IF(AND(N16>$V$9,N16<$V$10),M16,IF(N16=$V$10,M16,0)) -> 0 | W16: =IF(AND(N16>$W$9,N16<$W$10),M16,IF(N16=$W$10,M16,0)) -> 0 | X16: =IF(AND(N16>$X$9,N16<$X$10),M16,IF(N16=$X$10,M16,0)) -> 0 | Y16: =IF(AND(N16>$Y$9,N16<$Y$10),M16,IF(N16=$Y$10,M16,0)) -> 0 | Z16: =IF(AND(N16>$Z$9,N16<$Z$10),M16,IF(N16=$Z$10,M16,0)) -> 0 | AA16: =IF(AND(N16>$AA$9,N16<$AA$10),M16,IF(N16=$AA$10,M16,0)) -> 0 | AB16: =IF(AND(N16>$AB$9,N16<$AB$10),M16,IF(N16=$AB$10,M16,0)) -> 0 | AC16: =IF(AND(N16>$AC$9,N16<$AC$10),M16,IF(N16=$AC$10,M16,0)) -> 0 | AD16: =IF(AND(N16>$AD$9,N16<$AD$10),M16,IF(N16=$AD$10,M16,0)) -> 0 | AE16: =IF(AND(N16>$AE$9,N16<$AE$10),M16,IF(N16=$AE$10,M16,0)) -> 0 | AF16: =IF(AND(N16>$AF$9,N16<$AF$10),M16,IF(N16=$AF$10,M16,0)) -> 0 | AG16: =IF(N16=$AG$9,M16,0) -> 0
A17: 10212002 | B17: Due from Oversea Banks on Demand | C17: RCH4001USD | D17: 100000016 | E17: BANK OF AMERICA N.A.(H.O.) | F17: USD | G17: 2889.33 | H17: 4128.79 | L17: =A17&"_"&F17&"_"&D17&"_"&E17 -> 10212002_USD_100000016_BANK OF AMERICA N.A.(H.O.) | M17: =IF(COUNTIF($A$2:$A$8,A17)>0,-H17,H17) -> 4128.79 | N17: =IF(OR(L17=$L$2,L17=$L$3),$M$10+1,IFERROR(VLOOKUP(A17,'Repricing Maturity Adj.'!$A$3:$C$170,3,0),(IF(K17<$M$10,"Check",K17)))) -> 46059 | O17: =M17=SUM(Q17:AG17) -> TRUE | P17: =IF(A17="","N/A",IF(COUNTIF($A$2:$A$7,A17)>0,"Liability",IF(COUNTIF($A$8,A17)>0,"Asset",IF(A17<20000000,"Asset",IF(AND(A17>20000000,A17<28800000),"Liability",IF(A17>28800000,"Equity","")))))) -> Asset | Q17: =IF(AND(N17>$Q$9,N17<$Q$10),M17,IF(N17=$Q$10,M17,0)) -> 4128.79 | R17: =IF(AND(N17>$R$9,N17<$R$10),M17,IF(N17=$R$10,M17,0)) -> 0 | S17: =IF(AND(N17>$S$9,N17<$S$10),M17,IF(N17=$S$10,M17,0)) -> 0 | T17: =IF(AND(N17>$T$9,N17<$T$10),M17,IF(N17=$T$10,M17,0)) -> 0 | U17: =IF(AND(N17>$U$9,N17<$U$10),M17,IF(N17=$U$10,M17,0)) -> 0 | V17: =IF(AND(N17>$V$9,N17<$V$10),M17,IF(N17=$V$10,M17,0)) -> 0 | W17: =IF(AND(N17>$W$9,N17<$W$10),M17,IF(N17=$W$10,M17,0)) -> 0 | X17: =IF(AND(N17>$X$9,N17<$X$10),M17,IF(N17=$X$10,M17,0)) -> 0 | Y17: =IF(AND(N17>$Y$9,N17<$Y$10),M17,IF(N17=$Y$10,M17,0)) -> 0 | Z17: =IF(AND(N17>$Z$9,N17<$Z$10),M17,IF(N17=$Z$10,M17,0)) -> 0 | AA17: =IF(AND(N17>$AA$9,N17<$AA$10),M17,IF(N17=$AA$10,M17,0)) -> 0 | AB17: =IF(AND(N17>$AB$9,N17<$AB$10),M17,IF(N17=$AB$10,M17,0)) -> 0 | AC17: =IF(AND(N17>$AC$9,N17<$AC$10),M17,IF(N17=$AC$10,M17,0)) -> 0 | AD17: =IF(AND(N17>$AD$9,N17<$AD$10),M17,IF(N17=$AD$10,M17,0)) -> 0 | AE17: =IF(AND(N17>$AE$9,N17<$AE$10),M17,IF(N17=$AE$10,M17,0)) -> 0 | AF17: =IF(AND(N17>$AF$9,N17<$AF$10),M17,IF(N17=$AF$10,M17,0)) -> 0 | AG17: =IF(N17=$AG$9,M17,0) -> 0
A18: 10251002 | B18: Call Loan within 3M - Domestic | C18: FM5904250000051 | D18: 100000008 | E18: E.SUN COMMERCIAL BANK LTD | F18: AUD | G18: 10000000 | H18: 10000000 | I18: 46015 | J18: 46106 | K18: 46106 | L18: =A18&"_"&F18&"_"&D18&"_"&E18 -> 10251002_AUD_100000008_E.SUN COMMERCIAL BANK LTD | M18: =IF(COUNTIF($A$2:$A$8,A18)>0,-H18,H18) -> 10000000 | N18: =IF(OR(L18=$L$2,L18=$L$3),$M$10+1,IFERROR(VLOOKUP(A18,'Repricing Maturity Adj.'!$A$3:$C$170,3,0),(IF(K18<$M$10,"Check",K18)))) -> 46106 | O18: =M18=SUM(Q18:AG18) -> TRUE | P18: =IF(A18="","N/A",IF(COUNTIF($A$2:$A$7,A18)>0,"Liability",IF(COUNTIF($A$8,A18)>0,"Asset",IF(A18<20000000,"Asset",IF(AND(A18>20000000,A18<28800000),"Liability",IF(A18>28800000,"Equity","")))))) -> Asset | Q18: =IF(AND(N18>$Q$9,N18<$Q$10),M18,IF(N18=$Q$10,M18,0)) -> 0 | R18: =IF(AND(N18>$R$9,N18<$R$10),M18,IF(N18=$R$10,M18,0)) -> 10000000 | S18: =IF(AND(N18>$S$9,N18<$S$10),M18,IF(N18=$S$10,M18,0)) -> 0 | T18: =IF(AND(N18>$T$9,N18<$T$10),M18,IF(N18=$T$10,M18,0)) -> 0 | U18: =IF(AND(N18>$U$9,N18<$U$10),M18,IF(N18=$U$10,M18,0)) -> 0 | V18: =IF(AND(N18>$V$9,N18<$V$10),M18,IF(N18=$V$10,M18,0)) -> 0 | W18: =IF(AND(N18>$W$9,N18<$W$10),M18,IF(N18=$W$10,M18,0)) -> 0 | X18: =IF(AND(N18>$X$9,N18<$X$10),M18,IF(N18=$X$10,M18,0)) -> 0 | Y18: =IF(AND(N18>$Y$9,N18<$Y$10),M18,IF(N18=$Y$10,M18,0)) -> 0 | Z18: =IF(AND(N18>$Z$9,N18<$Z$10),M18,IF(N18=$Z$10,M18,0)) -> 0 | AA18: =IF(AND(N18>$AA$9,N18<$AA$10),M18,IF(N18=$AA$10,M18,0)) -> 0 | AB18: =IF(AND(N18>$AB$9,N18<$AB$10),M18,IF(N18=$AB$10,M18,0)) -> 0 | AC18: =IF(AND(N18>$AC$9,N18<$AC$10),M18,IF(N18=$AC$10,M18,0)) -> 0 | AD18: =IF(AND(N18>$AD$9,N18<$AD$10),M18,IF(N18=$AD$10,M18,0)) -> 0 | AE18: =IF(AND(N18>$AE$9,N18<$AE$10),M18,IF(N18=$AE$10,M18,0)) -> 0 | AF18: =IF(AND(N18>$AF$9,N18<$AF$10),M18,IF(N18=$AF$10,M18,0)) -> 0 | AG18: =IF(N18=$AG$9,M18,0) -> 0
A19: 10251002 | B19: Call Loan within 3M - Domestic | C19: FM5904260000003 | D19: 100000008 | E19: E.SUN COMMERCIAL BANK LTD | F19: AUD | G19: 3000000 | H19: 3000000 | I19: 46035 | J19: 46090 | K19: 46090 | L19: =A19&"_"&F19&"_"&D19&"_"&E19 -> 10251002_AUD_100000008_E.SUN COMMERCIAL BANK LTD | M19: =IF(COUNTIF($A$2:$A$8,A19)>0,-H19,H19) -> 3000000 | N19: =IF(OR(L19=$L$2,L19=$L$3),$M$10+1,IFERROR(VLOOKUP(A19,'Repricing Maturity Adj.'!$A$3:$C$170,3,0),(IF(K19<$M$10,"Check",K19)))) -> 46090 | O19: =M19=SUM(Q19:AG19) -> TRUE | P19: =IF(A19="","N/A",IF(COUNTIF($A$2:$A$7,A19)>0,"Liability",IF(COUNTIF($A$8,A19)>0,"Asset",IF(A19<20000000,"Asset",IF(AND(A19>20000000,A19<28800000),"Liability",IF(A19>28800000,"Equity","")))))) -> Asset | Q19: =IF(AND(N19>$Q$9,N19<$Q$10),M19,IF(N19=$Q$10,M19,0)) -> 0 | R19: =IF(AND(N19>$R$9,N19<$R$10),M19,IF(N19=$R$10,M19,0)) -> 3000000 | S19: =IF(AND(N19>$S$9,N19<$S$10),M19,IF(N19=$S$10,M19,0)) -> 0 | T19: =IF(AND(N19>$T$9,N19<$T$10),M19,IF(N19=$T$10,M19,0)) -> 0 | U19: =IF(AND(N19>$U$9,N19<$U$10),M19,IF(N19=$U$10,M19,0)) -> 0 | V19: =IF(AND(N19>$V$9,N19<$V$10),M19,IF(N19=$V$10,M19,0)) -> 0 | W19: =IF(AND(N19>$W$9,N19<$W$10),M19,IF(N19=$W$10,M19,0)) -> 0 | X19: =IF(AND(N19>$X$9,N19<$X$10),M19,IF(N19=$X$10,M19,0)) -> 0 | Y19: =IF(AND(N19>$Y$9,N19<$Y$10),M19,IF(N19=$Y$10,M19,0)) -> 0 | Z19: =IF(AND(N19>$Z$9,N19<$Z$10),M19,IF(N19=$Z$10,M19,0)) -> 0 | AA19: =IF(AND(N19>$AA$9,N19<$AA$10),M19,IF(N19=$AA$10,M19,0)) -> 0 | AB19: =IF(AND(N19>$AB$9,N19<$AB$10),M19,IF(N19=$AB$10,M19,0)) -> 0 | AC19: =IF(AND(N19>$AC$9,N19<$AC$10),M19,IF(N19=$AC$10,M19,0)) -> 0 | AD19: =IF(AND(N19>$AD$9,N19<$AD$10),M19,IF(N19=$AD$10,M19,0)) -> 0 | AE19: =IF(AND(N19>$AE$9,N19<$AE$10),M19,IF(N19=$AE$10,M19,0)) -> 0 | AF19: =IF(AND(N19>$AF$9,N19<$AF$10),M19,IF(N19=$AF$10,M19,0)) -> 0 | AG19: =IF(N19=$AG$9,M19,0) -> 0
A20: 10251002 | B20: Call Loan within 3M - Domestic | C20: FM5904260000004 | D20: 100000008 | E20: E.SUN COMMERCIAL BANK LTD | F20: AUD | G20: 4000000 | H20: 4000000 | I20: 46035 | J20: 46125 | K20: 46125 | L20: =A20&"_"&F20&"_"&D20&"_"&E20 -> 10251002_AUD_100000008_E.SUN COMMERCIAL BANK LTD | M20: =IF(COUNTIF($A$2:$A$8,A20)>0,-H20,H20) -> 4000000 | N20: =IF(OR(L20=$L$2,L20=$L$3),$M$10+1,IFERROR(VLOOKUP(A20,'Repricing Maturity Adj.'!$A$3:$C$170,3,0),(IF(K20<$M$10,"Check",K20)))) -> 46125 | O20: =M20=SUM(Q20:AG20) -> TRUE | P20: =IF(A20="","N/A",IF(COUNTIF($A$2:$A$7,A20)>0,"Liability",IF(COUNTIF($A$8,A20)>0,"Asset",IF(A20<20000000,"Asset",IF(AND(A20>20000000,A20<28800000),"Liability",IF(A20>28800000,"Equity","")))))) -> Asset | Q20: =IF(AND(N20>$Q$9,N20<$Q$10),M20,IF(N20=$Q$10,M20,0)) -> 0 | R20: =IF(AND(N20>$R$9,N20<$R$10),M20,IF(N20=$R$10,M20,0)) -> 0 | S20: =IF(AND(N20>$S$9,N20<$S$10),M20,IF(N20=$S$10,M20,0)) -> 4000000 | T20: =IF(AND(N20>$T$9,N20<$T$10),M20,IF(N20=$T$10,M20,0)) -> 0 | U20: =IF(AND(N20>$U$9,N20<$U$10),M20,IF(N20=$U$10,M20,0)) -> 0 | V20: =IF(AND(N20>$V$9,N20<$V$10),M20,IF(N20=$V$10,M20,0)) -> 0 | W20: =IF(AND(N20>$W$9,N20<$W$10),M20,IF(N20=$W$10,M20,0)) -> 0 | X20: =IF(AND(N20>$X$9,N20<$X$10),M20,IF(N20=$X$10,M20,0)) -> 0 | Y20: =IF(AND(N20>$Y$9,N20<$Y$10),M20,IF(N20=$Y$10,M20,0)) -> 0 | Z20: =IF(AND(N20>$Z$9,N20<$Z$10),M20,IF(N20=$Z$10,M20,0)) -> 0 | AA20: =IF(AND(N20>$AA$9,N20<$AA$10),M20,IF(N20=$AA$10,M20,0)) -> 0 | AB20: =IF(AND(N20>$AB$9,N20<$AB$10),M20,IF(N20=$AB$10,M20,0)) -> 0 | AC20: =IF(AND(N20>$AC$9,N20<$AC$10),M20,IF(N20=$AC$10,M20,0)) -> 0 | AD20: =IF(AND(N20>$AD$9,N20<$AD$10),M20,IF(N20=$AD$10,M20,0)) -> 0 | AE20: =IF(AND(N20>$AE$9,N20<$AE$10),M20,IF(N20=$AE$10,M20,0)) -> 0 | AF20: =IF(AND(N20>$AF$9,N20<$AF$10),M20,IF(N20=$AF$10,M20,0)) -> 0 | AG20: =IF(N20=$AG$9,M20,0) -> 0
A21: 10310002 | B21: Securities - FVOCI State | C21: FB5904240000001 | D21: 100000027 | E21: TREASURY CORPORATION OF VICTORIA | F21: AUD | G21: 5053962.5 | H21: 5053962.5 | I21: 45387 | J21: 46343 | K21: 46342 | L21: =A21&"_"&F21&"_"&D21&"_"&E21 -> 10310002_AUD_100000027_TREASURY CORPORATION OF VICTORIA | M21: =IF(COUNTIF($A$2:$A$8,A21)>0,-H21,H21) -> 5053962.5 | N21: =IF(OR(L21=$L$2,L21=$L$3),$M$10+1,IFERROR(VLOOKUP(A21,'Repricing Maturity Adj.'!$A$3:$C$170,3,0),(IF(K21<$M$10,"Check",K21)))) -> 46342 | O21: =M21=SUM(Q21:AG21) -> TRUE | P21: =IF(A21="","N/A",IF(COUNTIF($A$2:$A$7,A21)>0,"Liability",IF(COUNTIF($A$8,A21)>0,"Asset",IF(A21<20000000,"Asset",IF(AND(A21>20000000,A21<28800000),"Liability",IF(A21>28800000,"Equity","")))))) -> Asset | Q21: =IF(AND(N21>$Q$9,N21<$Q$10),M21,IF(N21=$Q$10,M21,0)) -> 0 | R21: =IF(AND(N21>$R$9,N21<$R$10),M21,IF(N21=$R$10,M21,0)) -> 0 | S21: =IF(AND(N21>$S$9,N21<$S$10),M21,IF(N21=$S$10,M21,0)) -> 0 | T21: =IF(AND(N21>$T$9,N21<$T$10),M21,IF(N21=$T$10,M21,0)) -> 0 | U21: =IF(AND(N21>$U$9,N21<$U$10),M21,IF(N21=$U$10,M21,0)) -> 0 | V21: =IF(AND(N21>$V$9,N21<$V$10),M21,IF(N21=$V$10,M21,0)) -> 5053962.5 | W21: =IF(AND(N21>$W$9,N21<$W$10),M21,IF(N21=$W$10,M21,0)) -> 0 | X21: =IF(AND(N21>$X$9,N21<$X$10),M21,IF(N21=$X$10,M21,0)) -> 0 | Y21: =IF(AND(N21>$Y$9,N21<$Y$10),M21,IF(N21=$Y$10,M21,0)) -> 0 | Z21: =IF(AND(N21>$Z$9,N21<$Z$10),M21,IF(N21=$Z$10,M21,0)) -> 0 | AA21: =IF(AND(N21>$AA$9,N21<$AA$10),M21,IF(N21=$AA$10,M21,0)) -> 0 | AB21: =IF(AND(N21>$AB$9,N21<$AB$10),M21,IF(N21=$AB$10,M21,0)) -> 0 | AC21: =IF(AND(N21>$AC$9,N21<$AC$10),M21,IF(N21=$AC$10,M21,0)) -> 0 | AD21: =IF(AND(N21>$AD$9,N21<$AD$10),M21,IF(N21=$AD$10,M21,0)) -> 0 | AE21: =IF(AND(N21>$AE$9,N21<$AE$10),M21,IF(N21=$AE$10,M21,0)) -> 0 | AF21: =IF(AND(N21>$AF$9,N21<$AF$10),M21,IF(N21=$AF$10,M21,0)) -> 0 | AG21: =IF(N21=$AG$9,M21,0) -> 0
A22: 10310002 | B22: Securities - FVOCI State | C22: FB5904240000003 | D22: 100000034 | E22: WESTERN AUSTRALIAN TREASURY CORPORATION | F22: AUD | G22: 4000347.4 | H22: 4000347.4 | I22: 45552 | J22: 46091 | K22: 46090 | L22: =A22&"_"&F22&"_"&D22&"_"&E22 -> 10310002_AUD_100000034_WESTERN AUSTRALIAN TREASURY CORPORATION | M22: =IF(COUNTIF($A$2:$A$8,A22)>0,-H22,H22) -> 4000347.4 | N22: =IF(OR(L22=$L$2,L22=$L$3),$M$10+1,IFERROR(VLOOKUP(A22,'Repricing Maturity Adj.'!$A$3:$C$170,3,0),(IF(K22<$M$10,"Check",K22)))) -> 46090 | O22: =M22=SUM(Q22:AG22) -> TRUE | P22: =IF(A22="","N/A",IF(COUNTIF($A$2:$A$7,A22)>0,"Liability",IF(COUNTIF($A$8,A22)>0,"Asset",IF(A22<20000000,"Asset",IF(AND(A22>20000000,A22<28800000),"Liability",IF(A22>28800000,"Equity","")))))) -> Asset | Q22: =IF(AND(N22>$Q$9,N22<$Q$10),M22,IF(N22=$Q$10,M22,0)) -> 0 | R22: =IF(AND(N22>$R$9,N22<$R$10),M22,IF(N22=$R$10,M22,0)) -> 4000347.4 | S22: =IF(AND(N22>$S$9,N22<$S$10),M22,IF(N22=$S$10,M22,0)) -> 0 | T22: =IF(AND(N22>$T$9,N22<$T$10),M22,IF(N22=$T$10,M22,0)) -> 0 | U22: =IF(AND(N22>$U$9,N22<$U$10),M22,IF(N22=$U$10,M22,0)) -> 0 | V22: =IF(AND(N22>$V$9,N22<$V$10),M22,IF(N22=$V$10,M22,0)) -> 0 | W22: =IF(AND(N22>$W$9,N22<$W$10),M22,IF(N22=$W$10,M22,0)) -> 0 | X22: =IF(AND(N22>$X$9,N22<$X$10),M22,IF(N22=$X$10,M22,0)) -> 0 | Y22: =IF(AND(N22>$Y$9,N22<$Y$10),M22,IF(N22=$Y$10,M22,0)) -> 0 | Z22: =IF(AND(N22>$Z$9,N22<$Z$10),M22,IF(N22=$Z$10,M22,0)) -> 0 | AA22: =IF(AND(N22>$AA$9,N22<$AA$10),M22,IF(N22=$AA$10,M22,0)) -> 0 | AB22: =IF(AND(N22>$AB$9,N22<$AB$10),M22,IF(N22=$AB$10,M22,0)) -> 0 | AC22: =IF(AND(N22>$AC$9,N22<$AC$10),M22,IF(N22=$AC$10,M22,0)) -> 0 | AD22: =IF(AND(N22>$AD$9,N22<$AD$10),M22,IF(N22=$AD$10,M22,0)) -> 0 | AE22: =IF(AND(N22>$AE$9,N22<$AE$10),M22,IF(N22=$AE$10,M22,0)) -> 0 | AF22: =IF(AND(N22>$AF$9,N22<$AF$10),M22,IF(N22=$AF$10,M22,0)) -> 0 | AG22: =IF(N22=$AG$9,M22,0) -> 0
A23: 10310002 | B23: Securities - FVOCI State | C23: FB5904250000003 | D23: 100000038 | E23: TASMANIAN PUBLIC FINANCE CORPORATION | F23: AUD | G23: 4891657.6 | H23: 4891657.6 | I23: 45755 | J23: 46776 | K23: 46775 | L23: =A23&"_"&F23&"_"&D23&"_"&E23 -> 10310002_AUD_100000038_TASMANIAN PUBLIC FINANCE CORPORATION | M23: =IF(COUNTIF($A$2:$A$8,A23)>0,-H23,H23) -> 4891657.6 | N23: =IF(OR(L23=$L$2,L23=$L$3),$M$10+1,IFERROR(VLOOKUP(A23,'Repricing Maturity Adj.'!$A$3:$C$170,3,0),(IF(K23<$M$10,"Check",K23)))) -> 46775 | O23: =M23=SUM(Q23:AG23) -> TRUE | P23: =IF(A23="","N/A",IF(COUNTIF($A$2:$A$7,A23)>0,"Liability",IF(COUNTIF($A$8,A23)>0,"Asset",IF(A23<20000000,"Asset",IF(AND(A23>20000000,A23<28800000),"Liability",IF(A23>28800000,"Equity","")))))) -> Asset | Q23: =IF(AND(N23>$Q$9,N23<$Q$10),M23,IF(N23=$Q$10,M23,0)) -> 0 | R23: =IF(AND(N23>$R$9,N23<$R$10),M23,IF(N23=$R$10,M23,0)) -> 0 | S23: =IF(AND(N23>$S$9,N23<$S$10),M23,IF(N23=$S$10,M23,0)) -> 0 | T23: =IF(AND(N23>$T$9,N23<$T$10),M23,IF(N23=$T$10,M23,0)) -> 0 | U23: =IF(AND(N23>$U$9,N23<$U$10),M23,IF(N23=$U$10,M23,0)) -> 0 | V23: =IF(AND(N23>$V$9,N23<$V$10),M23,IF(N23=$V$10,M23,0)) -> 0 | W23: =IF(AND(N23>$W$9,N23<$W$10),M23,IF(N23=$W$10,M23,0)) -> 0 | X23: =IF(AND(N23>$X$9,N23<$X$10),M23,IF(N23=$X$10,M23,0)) -> 4891657.6 | Y23: =IF(AND(N23>$Y$9,N23<$Y$10),M23,IF(N23=$Y$10,M23,0)) -> 0 | Z23: =IF(AND(N23>$Z$9,N23<$Z$10),M23,IF(N23=$Z$10,M23,0)) -> 0 | AA23: =IF(AND(N23>$AA$9,N23<$AA$10),M23,IF(N23=$AA$10,M23,0)) -> 0 | AB23: =IF(AND(N23>$AB$9,N23<$AB$10),M23,IF(N23=$AB$10,M23,0)) -> 0 | AC23: =IF(AND(N23>$AC$9,N23<$AC$10),M23,IF(N23=$AC$10,M23,0)) -> 0 | AD23: =IF(AND(N23>$AD$9,N23<$AD$10),M23,IF(N23=$AD$10,M23,0)) -> 0 | AE23: =IF(AND(N23>$AE$9,N23<$AE$10),M23,IF(N23=$AE$10,M23,0)) -> 0 | AF23: =IF(AND(N23>$AF$9,N23<$AF$10),M23,IF(N23=$AF$10,M23,0)) -> 0 | AG23: =IF(N23=$AG$9,M23,0) -> 0
A24: 10310003 | B24: Foreign GovT & Official Institution - FVOCI | C24: FB5904240000005 | D24: 100000037 | E24: THE EXPORT-IMPORT BANK OF KOREA | F24: USD | G24: 5027405.6 | H24: 7184060.6 | I24: 45624 | J24: 46677 | K24: 46128 | L24: =A24&"_"&F24&"_"&D24&"_"&E24 -> 10310003_USD_100000037_THE EXPORT-IMPORT BANK OF KOREA | M24: =IF(COUNTIF($A$2:$A$8,A24)>0,-H24,H24) -> 7184060.6 | N24: =IF(OR(L24=$L$2,L24=$L$3),$M$10+1,IFERROR(VLOOKUP(A24,'Repricing Maturity Adj.'!$A$3:$C$170,3,0),(IF(K24<$M$10,"Check",K24)))) -> 46128 | O24: =M24=SUM(Q24:AG24) -> TRUE | P24: =IF(A24="","N/A",IF(COUNTIF($A$2:$A$7,A24)>0,"Liability",IF(COUNTIF($A$8,A24)>0,"Asset",IF(A24<20000000,"Asset",IF(AND(A24>20000000,A24<28800000),"Liability",IF(A24>28800000,"Equity","")))))) -> Asset | Q24: =IF(AND(N24>$Q$9,N24<$Q$10),M24,IF(N24=$Q$10,M24,0)) -> 0 | R24: =IF(AND(N24>$R$9,N24<$R$10),M24,IF(N24=$R$10,M24,0)) -> 0 | S24: =IF(AND(N24>$S$9,N24<$S$10),M24,IF(N24=$S$10,M24,0)) -> 7184060.6 | T24: =IF(AND(N24>$T$9,N24<$T$10),M24,IF(N24=$T$10,M24,0)) -> 0 | U24: =IF(AND(N24>$U$9,N24<$U$10),M24,IF(N24=$U$10,M24,0)) -> 0 | V24: =IF(AND(N24>$V$9,N24<$V$10),M24,IF(N24=$V$10,M24,0)) -> 0 | W24: =IF(AND(N24>$W$9,N24<$W$10),M24,IF(N24=$W$10,M24,0)) -> 0 | X24: =IF(AND(N24>$X$9,N24<$X$10),M24,IF(N24=$X$10,M24,0)) -> 0 | Y24: =IF(AND(N24>$Y$9,N24<$Y$10),M24,IF(N24=$Y$10,M24,0)) -> 0 | Z24: =IF(AND(N24>$Z$9,N24<$Z$10),M24,IF(N24=$Z$10,M24,0)) -> 0 | AA24: =IF(AND(N24>$AA$9,N24<$AA$10),M24,IF(N24=$AA$10,M24,0)) -> 0 | AB24: =IF(AND(N24>$AB$9,N24<$AB$10),M24,IF(N24=$AB$10,M24,0)) -> 0 | AC24: =IF(AND(N24>$AC$9,N24<$AC$10),M24,IF(N24=$AC$10,M24,0)) -> 0 | AD24: =IF(AND(N24>$AD$9,N24<$AD$10),M24,IF(N24=$AD$10,M24,0)) -> 0 | AE24: =IF(AND(N24>$AE$9,N24<$AE$10),M24,IF(N24=$AE$10,M24,0)) -> 0 | AF24: =IF(AND(N24>$AF$9,N24<$AF$10),M24,IF(N24=$AF$10,M24,0)) -> 0 | AG24: =IF(N24=$AG$9,M24,0) -> 0
A25: 10310003 | B25: Foreign GovT & Official Institution - FVOCI | C25: FB5904250000001 | D25: 100000037 | E25: THE EXPORT-IMPORT BANK OF KOREA | F25: USD | G25: -15.6 | H25: -22.29 | I25: 45692 | J25: 46766 | L25: =A25&"_"&F25&"_"&D25&"_"&E25 -> 10310003_USD_100000037_THE EXPORT-IMPORT BANK OF KOREA | M25: =IF(COUNTIF($A$2:$A$8,A25)>0,-H25,H25) -> -22.29 | N25: =IF(OR(L25=$L$2,L25=$L$3),$M$10+1,IFERROR(VLOOKUP(A25,'Repricing Maturity Adj.'!$A$3:$C$170,3,0),(IF(K25<$M$10,"Check",K25)))) -> Check | O25: =M25=SUM(Q25:AG25) -> FALSE | P25: =IF(A25="","N/A",IF(COUNTIF($A$2:$A$7,A25)>0,"Liability",IF(COUNTIF($A$8,A25)>0,"Asset",IF(A25<20000000,"Asset",IF(AND(A25>20000000,A25<28800000),"Liability",IF(A25>28800000,"Equity","")))))) -> Asset | Q25: =IF(AND(N25>$Q$9,N25<$Q$10),M25,IF(N25=$Q$10,M25,0)) -> 0 | R25: =IF(AND(N25>$R$9,N25<$R$10),M25,IF(N25=$R$10,M25,0)) -> 0 | S25: =IF(AND(N25>$S$9,N25<$S$10),M25,IF(N25=$S$10,M25,0)) -> 0 | T25: =IF(AND(N25>$T$9,N25<$T$10),M25,IF(N25=$T$10,M25,0)) -> 0 | U25: =IF(AND(N25>$U$9,N25<$U$10),M25,IF(N25=$U$10,M25,0)) -> 0 | V25: =IF(AND(N25>$V$9,N25<$V$10),M25,IF(N25=$V$10,M25,0)) -> 0 | W25: =IF(AND(N25>$W$9,N25<$W$10),M25,IF(N25=$W$10,M25,0)) -> 0 | X25: =IF(AND(N25>$X$9,N25<$X$10),M25,IF(N25=$X$10,M25,0)) -> 0 | Y25: =IF(AND(N25>$Y$9,N25<$Y$10),M25,IF(N25=$Y$10,M25,0)) -> 0 | Z25: =IF(AND(N25>$Z$9,N25<$Z$10),M25,IF(N25=$Z$10,M25,0)) -> 0 | AA25: =IF(AND(N25>$AA$9,N25<$AA$10),M25,IF(N25=$AA$10,M25,0)) -> 0 | AB25: =IF(AND(N25>$AB$9,N25<$AB$10),M25,IF(N25=$AB$10,M25,0)) -> 0 | AC25: =IF(AND(N25>$AC$9,N25<$AC$10),M25,IF(N25=$AC$10,M25,0)) -> 0 | AD25: =IF(AND(N25>$AD$9,N25<$AD$10),M25,IF(N25=$AD$10,M25,0)) -> 0 | AE25: =IF(AND(N25>$AE$9,N25<$AE$10),M25,IF(N25=$AE$10,M25,0)) -> 0 | AF25: =IF(AND(N25>$AF$9,N25<$AF$10),M25,IF(N25=$AF$10,M25,0)) -> 0 | AG25: =IF(N25=$AG$9,M25,0) -> 0
A26: 10310003 | B26: Foreign GovT & Official Institution - FVOCI | C26: FB5904250000002 | D26: 100000037 | E26: THE EXPORT-IMPORT BANK OF KOREA | F26: USD | G26: 5076634.8 | H26: 7254408.2 | I26: 45692 | J26: 46766 | K26: 46765 | L26: =A26&"_"&F26&"_"&D26&"_"&E26 -> 10310003_USD_100000037_THE EXPORT-IMPORT BANK OF KOREA | M26: =IF(COUNTIF($A$2:$A$8,A26)>0,-H26,H26) -> 7254408.2 | N26: =IF(OR(L26=$L$2,L26=$L$3),$M$10+1,IFERROR(VLOOKUP(A26,'Repricing Maturity Adj.'!$A$3:$C$170,3,0),(IF(K26<$M$10,"Check",K26)))) -> 46765 | O26: =M26=SUM(Q26:AG26) -> TRUE | P26: =IF(A26="","N/A",IF(COUNTIF($A$2:$A$7,A26)>0,"Liability",IF(COUNTIF($A$8,A26)>0,"Asset",IF(A26<20000000,"Asset",IF(AND(A26>20000000,A26<28800000),"Liability",IF(A26>28800000,"Equity","")))))) -> Asset | Q26: =IF(AND(N26>$Q$9,N26<$Q$10),M26,IF(N26=$Q$10,M26,0)) -> 0 | R26: =IF(AND(N26>$R$9,N26<$R$10),M26,IF(N26=$R$10,M26,0)) -> 0 | S26: =IF(AND(N26>$S$9,N26<$S$10),M26,IF(N26=$S$10,M26,0)) -> 0 | T26: =IF(AND(N26>$T$9,N26<$T$10),M26,IF(N26=$T$10,M26,0)) -> 0 | U26: =IF(AND(N26>$U$9,N26<$U$10),M26,IF(N26=$U$10,M26,0)) -> 0 | V26: =IF(AND(N26>$V$9,N26<$V$10),M26,IF(N26=$V$10,M26,0)) -> 0 | W26: =IF(AND(N26>$W$9,N26<$W$10),M26,IF(N26=$W$10,M26,0)) -> 0 | X26: =IF(AND(N26>$X$9,N26<$X$10),M26,IF(N26=$X$10,M26,0)) -> 7254408.2 | Y26: =IF(AND(N26>$Y$9,N26<$Y$10),M26,IF(N26=$Y$10,M26,0)) -> 0 | Z26: =IF(AND(N26>$Z$9,N26<$Z$10),M26,IF(N26=$Z$10,M26,0)) -> 0 | AA26: =IF(AND(N26>$AA$9,N26<$AA$10),M26,IF(N26=$AA$10,M26,0)) -> 0 | AB26: =IF(AND(N26>$AB$9,N26<$AB$10),M26,IF(N26=$AB$10,M26,0)) -> 0 | AC26: =IF(AND(N26>$AC$9,N26<$AC$10),M26,IF(N26=$AC$10,M26,0)) -> 0 | AD26: =IF(AND(N26>$AD$9,N26<$AD$10),M26,IF(N26=$AD$10,M26,0)) -> 0 | AE26: =IF(AND(N26>$AE$9,N26<$AE$10),M26,IF(N26=$AE$10,M26,0)) -> 0 | AF26: =IF(AND(N26>$AF$9,N26<$AF$10),M26,IF(N26=$AF$10,M26,0)) -> 0 | AG26: =IF(N26=$AG$9,M26,0) -> 0
A27: 10310003 | B27: Foreign GovT & Official Institution - FVOCI | C27: FB5904250000004 | D27: 100000037 | E27: THE EXPORT-IMPORT BANK OF KOREA | F27: USD | G27: 3021005.4 | H27: 4316955.4 | I27: 45818 | J27: 46645 | K27: 46644 | L27: =A27&"_"&F27&"_"&D27&"_"&E27 -> 10310003_USD_100000037_THE EXPORT-IMPORT BANK OF KOREA | M27: =IF(COUNTIF($A$2:$A$8,A27)>0,-H27,H27) -> 4316955.4 | N27: =IF(OR(L27=$L$2,L27=$L$3),$M$10+1,IFERROR(VLOOKUP(A27,'Repricing Maturity Adj.'!$A$3:$C$170,3,0),(IF(K27<$M$10,"Check",K27)))) -> 46644 | O27: =M27=SUM(Q27:AG27) -> TRUE | P27: =IF(A27="","N/A",IF(COUNTIF($A$2:$A$7,A27)>0,"Liability",IF(COUNTIF($A$8,A27)>0,"Asset",IF(A27<20000000,"Asset",IF(AND(A27>20000000,A27<28800000),"Liability",IF(A27>28800000,"Equity","")))))) -> Asset | Q27: =IF(AND(N27>$Q$9,N27<$Q$10),M27,IF(N27=$Q$10,M27,0)) -> 0 | R27: =IF(AND(N27>$R$9,N27<$R$10),M27,IF(N27=$R$10,M27,0)) -> 0 | S27: =IF(AND(N27>$S$9,N27<$S$10),M27,IF(N27=$S$10,M27,0)) -> 0 | T27: =IF(AND(N27>$T$9,N27<$T$10),M27,IF(N27=$T$10,M27,0)) -> 0 | U27: =IF(AND(N27>$U$9,N27<$U$10),M27,IF(N27=$U$10,M27,0)) -> 0 | V27: =IF(AND(N27>$V$9,N27<$V$10),M27,IF(N27=$V$10,M27,0)) -> 0 | W27: =IF(AND(N27>$W$9,N27<$W$10),M27,IF(N27=$W$10,M27,0)) -> 0 | X27: =IF(AND(N27>$X$9,N27<$X$10),M27,IF(N27=$X$10,M27,0)) -> 4316955.4 | Y27: =IF(AND(N27>$Y$9,N27<$Y$10),M27,IF(N27=$Y$10,M27,0)) -> 0 | Z27: =IF(AND(N27>$Z$9,N27<$Z$10),M27,IF(N27=$Z$10,M27,0)) -> 0 | AA27: =IF(AND(N27>$AA$9,N27<$AA$10),M27,IF(N27=$AA$10,M27,0)) -> 0 | AB27: =IF(AND(N27>$AB$9,N27<$AB$10),M27,IF(N27=$AB$10,M27,0)) -> 0 | AC27: =IF(AND(N27>$AC$9,N27<$AC$10),M27,IF(N27=$AC$10,M27,0)) -> 0 | AD27: =IF(AND(N27>$AD$9,N27<$AD$10),M27,IF(N27=$AD$10,M27,0)) -> 0 | AE27: =IF(AND(N27>$AE$9,N27<$AE$10),M27,IF(N27=$AE$10,M27,0)) -> 0 | AF27: =IF(AND(N27>$AF$9,N27<$AF$10),M27,IF(N27=$AF$10,M27,0)) -> 0 | AG27: =IF(N27=$AG$9,M27,0) -> 0
A28: 10310003 | B28: Foreign GovT & Official Institution - FVOCI | C28: OT5904250000017 | D28: 100000037 | E28: THE EXPORT-IMPORT BANK OF KOREA | F28: USD | G28: 15.6 | H28: 22.29 | L28: =A28&"_"&F28&"_"&D28&"_"&E28 -> 10310003_USD_100000037_THE EXPORT-IMPORT BANK OF KOREA | M28: =IF(COUNTIF($A$2:$A$8,A28)>0,-H28,H28) -> 22.29 | N28: =IF(OR(L28=$L$2,L28=$L$3),$M$10+1,IFERROR(VLOOKUP(A28,'Repricing Maturity Adj.'!$A$3:$C$170,3,0),(IF(K28<$M$10,"Check",K28)))) -> Check | O28: =M28=SUM(Q28:AG28) -> FALSE | P28: =IF(A28="","N/A",IF(COUNTIF($A$2:$A$7,A28)>0,"Liability",IF(COUNTIF($A$8,A28)>0,"Asset",IF(A28<20000000,"Asset",IF(AND(A28>20000000,A28<28800000),"Liability",IF(A28>28800000,"Equity","")))))) -> Asset | Q28: =IF(AND(N28>$Q$9,N28<$Q$10),M28,IF(N28=$Q$10,M28,0)) -> 0 | R28: =IF(AND(N28>$R$9,N28<$R$10),M28,IF(N28=$R$10,M28,0)) -> 0 | S28: =IF(AND(N28>$S$9,N28<$S$10),M28,IF(N28=$S$10,M28,0)) -> 0 | T28: =IF(AND(N28>$T$9,N28<$T$10),M28,IF(N28=$T$10,M28,0)) -> 0 | U28: =IF(AND(N28>$U$9,N28<$U$10),M28,IF(N28=$U$10,M28,0)) -> 0 | V28: =IF(AND(N28>$V$9,N28<$V$10),M28,IF(N28=$V$10,M28,0)) -> 0 | W28: =IF(AND(N28>$W$9,N28<$W$10),M28,IF(N28=$W$10,M28,0)) -> 0 | X28: =IF(AND(N28>$X$9,N28<$X$10),M28,IF(N28=$X$10,M28,0)) -> 0 | Y28: =IF(AND(N28>$Y$9,N28<$Y$10),M28,IF(N28=$Y$10,M28,0)) -> 0 | Z28: =IF(AND(N28>$Z$9,N28<$Z$10),M28,IF(N28=$Z$10,M28,0)) -> 0 | AA28: =IF(AND(N28>$AA$9,N28<$AA$10),M28,IF(N28=$AA$10,M28,0)) -> 0 | AB28: =IF(AND(N28>$AB$9,N28<$AB$10),M28,IF(N28=$AB$10,M28,0)) -> 0 | AC28: =IF(AND(N28>$AC$9,N28<$AC$10),M28,IF(N28=$AC$10,M28,0)) -> 0 | AD28: =IF(AND(N28>$AD$9,N28<$AD$10),M28,IF(N28=$AD$10,M28,0)) -> 0 | AE28: =IF(AND(N28>$AE$9,N28<$AE$10),M28,IF(N28=$AE$10,M28,0)) -> 0 | AF28: =IF(AND(N28>$AF$9,N28<$AF$10),M28,IF(N28=$AF$10,M28,0)) -> 0 | AG28: =IF(N28=$AG$9,M28,0) -> 0
A29: 10610005 | B29: Loans On Bills (Operation-Short Term-Domestic) | C29: 6115904000018 | D29: 100000003 | E29: COSMAX NBT AUSTRALIA PTY LTD | F29: AUD | G29: 6000000 | H29: 6000000 | I29: 44859 | J29: 46318 | K29: 46136 | L29: =A29&"_"&F29&"_"&D29&"_"&E29 -> 10610005_AUD_100000003_COSMAX NBT AUSTRALIA PTY LTD | M29: =IF(COUNTIF($A$2:$A$8,A29)>0,-H29,H29) -> 6000000 | N29: =IF(OR(L29=$L$2,L29=$L$3),$M$10+1,IFERROR(VLOOKUP(A29,'Repricing Maturity Adj.'!$A$3:$C$170,3,0),(IF(K29<$M$10,"Check",K29)))) -> 46136 | O29: =M29=SUM(Q29:AG29) -> TRUE | P29: =IF(A29="","N/A",IF(COUNTIF($A$2:$A$7,A29)>0,"Liability",IF(COUNTIF($A$8,A29)>0,"Asset",IF(A29<20000000,"Asset",IF(AND(A29>20000000,A29<28800000),"Liability",IF(A29>28800000,"Equity","")))))) -> Asset | Q29: =IF(AND(N29>$Q$9,N29<$Q$10),M29,IF(N29=$Q$10,M29,0)) -> 0 | R29: =IF(AND(N29>$R$9,N29<$R$10),M29,IF(N29=$R$10,M29,0)) -> 0 | S29: =IF(AND(N29>$S$9,N29<$S$10),M29,IF(N29=$S$10,M29,0)) -> 6000000 | T29: =IF(AND(N29>$T$9,N29<$T$10),M29,IF(N29=$T$10,M29,0)) -> 0 | U29: =IF(AND(N29>$U$9,N29<$U$10),M29,IF(N29=$U$10,M29,0)) -> 0 | V29: =IF(AND(N29>$V$9,N29<$V$10),M29,IF(N29=$V$10,M29,0)) -> 0 | W29: =IF(AND(N29>$W$9,N29<$W$10),M29,IF(N29=$W$10,M29,0)) -> 0 | X29: =IF(AND(N29>$X$9,N29<$X$10),M29,IF(N29=$X$10,M29,0)) -> 0 | Y29: =IF(AND(N29>$Y$9,N29<$Y$10),M29,IF(N29=$Y$10,M29,0)) -> 0 | Z29: =IF(AND(N29>$Z$9,N29<$Z$10),M29,IF(N29=$Z$10,M29,0)) -> 0 | AA29: =IF(AND(N29>$AA$9,N29<$AA$10),M29,IF(N29=$AA$10,M29,0)) -> 0 | AB29: =IF(AND(N29>$AB$9,N29<$AB$10),M29,IF(N29=$AB$10,M29,0)) -> 0 | AC29: =IF(AND(N29>$AC$9,N29<$AC$10),M29,IF(N29=$AC$10,M29,0)) -> 0 | AD29: =IF(AND(N29>$AD$9,N29<$AD$10),M29,IF(N29=$AD$10,M29,0)) -> 0 | AE29: =IF(AND(N29>$AE$9,N29<$AE$10),M29,IF(N29=$AE$10,M29,0)) -> 0 | AF29: =IF(AND(N29>$AF$9,N29<$AF$10),M29,IF(N29=$AF$10,M29,0)) -> 0 | AG29: =IF(N29=$AG$9,M29,0) -> 0
A30: 10620001 | B30: SYN-Working Capital Loan - Domestic | C30: 6115904000139 | D30: 100000020 | E30: APA INFRASTRUCTURE LIMITED | F30: AUD | G30: 8000000 | H30: 8000000 | I30: 45240 | J30: 48883 | K30: 46153 | L30: =A30&"_"&F30&"_"&D30&"_"&E30 -> 10620001_AUD_100000020_APA INFRASTRUCTURE LIMITED | M30: =IF(COUNTIF($A$2:$A$8,A30)>0,-H30,H30) -> 8000000 | N30: =IF(OR(L30=$L$2,L30=$L$3),$M$10+1,IFERROR(VLOOKUP(A30,'Repricing Maturity Adj.'!$A$3:$C$170,3,0),(IF(K30<$M$10,"Check",K30)))) -> 46153 | O30: =M30=SUM(Q30:AG30) -> TRUE | P30: =IF(A30="","N/A",IF(COUNTIF($A$2:$A$7,A30)>0,"Liability",IF(COUNTIF($A$8,A30)>0,"Asset",IF(A30<20000000,"Asset",IF(AND(A30>20000000,A30<28800000),"Liability",IF(A30>28800000,"Equity","")))))) -> Asset | Q30: =IF(AND(N30>$Q$9,N30<$Q$10),M30,IF(N30=$Q$10,M30,0)) -> 0 | R30: =IF(AND(N30>$R$9,N30<$R$10),M30,IF(N30=$R$10,M30,0)) -> 0 | S30: =IF(AND(N30>$S$9,N30<$S$10),M30,IF(N30=$S$10,M30,0)) -> 0 | T30: =IF(AND(N30>$T$9,N30<$T$10),M30,IF(N30=$T$10,M30,0)) -> 8000000 | U30: =IF(AND(N30>$U$9,N30<$U$10),M30,IF(N30=$U$10,M30,0)) -> 0 | V30: =IF(AND(N30>$V$9,N30<$V$10),M30,IF(N30=$V$10,M30,0)) -> 0 | W30: =IF(AND(N30>$W$9,N30<$W$10),M30,IF(N30=$W$10,M30,0)) -> 0 | X30: =IF(AND(N30>$X$9,N30<$X$10),M30,IF(N30=$X$10,M30,0)) -> 0 | Y30: =IF(AND(N30>$Y$9,N30<$Y$10),M30,IF(N30=$Y$10,M30,0)) -> 0 | Z30: =IF(AND(N30>$Z$9,N30<$Z$10),M30,IF(N30=$Z$10,M30,0)) -> 0 | AA30: =IF(AND(N30>$AA$9,N30<$AA$10),M30,IF(N30=$AA$10,M30,0)) -> 0 | AB30: =IF(AND(N30>$AB$9,N30<$AB$10),M30,IF(N30=$AB$10,M30,0)) -> 0 | AC30: =IF(AND(N30>$AC$9,N30<$AC$10),M30,IF(N30=$AC$10,M30,0)) -> 0 | AD30: =IF(AND(N30>$AD$9,N30<$AD$10),M30,IF(N30=$AD$10,M30,0)) -> 0 | AE30: =IF(AND(N30>$AE$9,N30<$AE$10),M30,IF(N30=$AE$10,M30,0)) -> 0 | AF30: =IF(AND(N30>$AF$9,N30<$AF$10),M30,IF(N30=$AF$10,M30,0)) -> 0 | AG30: =IF(N30=$AG$9,M30,0) -> 0
A31: 10620001 | B31: SYN-Working Capital Loan - Domestic | C31: 6115904000300 | D31: 100000031 | E31: ORIGIN ENERGY LIMITED | F31: AUD | G31: 10000000 | H31: 10000000 | I31: 45463 | J31: 48005 | K31: 46195 | L31: =A31&"_"&F31&"_"&D31&"_"&E31 -> 10620001_AUD_100000031_ORIGIN ENERGY LIMITED | M31: =IF(COUNTIF($A$2:$A$8,A31)>0,-H31,H31) -> 10000000 | N31: =IF(OR(L31=$L$2,L31=$L$3),$M$10+1,IFERROR(VLOOKUP(A31,'Repricing Maturity Adj.'!$A$3:$C$170,3,0),(IF(K31<$M$10,"Check",K31)))) -> 46195 | O31: =M31=SUM(Q31:AG31) -> TRUE | P31: =IF(A31="","N/A",IF(COUNTIF($A$2:$A$7,A31)>0,"Liability",IF(COUNTIF($A$8,A31)>0,"Asset",IF(A31<20000000,"Asset",IF(AND(A31>20000000,A31<28800000),"Liability",IF(A31>28800000,"Equity","")))))) -> Asset | Q31: =IF(AND(N31>$Q$9,N31<$Q$10),M31,IF(N31=$Q$10,M31,0)) -> 0 | R31: =IF(AND(N31>$R$9,N31<$R$10),M31,IF(N31=$R$10,M31,0)) -> 0 | S31: =IF(AND(N31>$S$9,N31<$S$10),M31,IF(N31=$S$10,M31,0)) -> 0 | T31: =IF(AND(N31>$T$9,N31<$T$10),M31,IF(N31=$T$10,M31,0)) -> 0 | U31: =IF(AND(N31>$U$9,N31<$U$10),M31,IF(N31=$U$10,M31,0)) -> 10000000 | V31: =IF(AND(N31>$V$9,N31<$V$10),M31,IF(N31=$V$10,M31,0)) -> 0 | W31: =IF(AND(N31>$W$9,N31<$W$10),M31,IF(N31=$W$10,M31,0)) -> 0 | X31: =IF(AND(N31>$X$9,N31<$X$10),M31,IF(N31=$X$10,M31,0)) -> 0 | Y31: =IF(AND(N31>$Y$9,N31<$Y$10),M31,IF(N31=$Y$10,M31,0)) -> 0 | Z31: =IF(AND(N31>$Z$9,N31<$Z$10),M31,IF(N31=$Z$10,M31,0)) -> 0 | AA31: =IF(AND(N31>$AA$9,N31<$AA$10),M31,IF(N31=$AA$10,M31,0)) -> 0 | AB31: =IF(AND(N31>$AB$9,N31<$AB$10),M31,IF(N31=$AB$10,M31,0)) -> 0 | AC31: =IF(AND(N31>$AC$9,N31<$AC$10),M31,IF(N31=$AC$10,M31,0)) -> 0 | AD31: =IF(AND(N31>$AD$9,N31<$AD$10),M31,IF(N31=$AD$10,M31,0)) -> 0 | AE31: =IF(AND(N31>$AE$9,N31<$AE$10),M31,IF(N31=$AE$10,M31,0)) -> 0 | AF31: =IF(AND(N31>$AF$9,N31<$AF$10),M31,IF(N31=$AF$10,M31,0)) -> 0 | AG31: =IF(N31=$AG$9,M31,0) -> 0
A32: 10620001 | B32: SYN-Working Capital Loan - Domestic | C32: 6115904000395 | D32: 100000033 | E32: MACQUARIE GROUP LIMITED | F32: USD | G32: 30000000 | H32: 42869391 | I32: 45565 | J32: 48136 | K32: 46107 | L32: =A32&"_"&F32&"_"&D32&"_"&E32 -> 10620001_USD_100000033_MACQUARIE GROUP LIMITED | M32: =IF(COUNTIF($A$2:$A$8,A32)>0,-H32,H32) -> 42869391 | N32: =IF(OR(L32=$L$2,L32=$L$3),$M$10+1,IFERROR(VLOOKUP(A32,'Repricing Maturity Adj.'!$A$3:$C$170,3,0),(IF(K32<$M$10,"Check",K32)))) -> 46059 | O32: =M32=SUM(Q32:AG32) -> TRUE | P32: =IF(A32="","N/A",IF(COUNTIF($A$2:$A$7,A32)>0,"Liability",IF(COUNTIF($A$8,A32)>0,"Asset",IF(A32<20000000,"Asset",IF(AND(A32>20000000,A32<28800000),"Liability",IF(A32>28800000,"Equity","")))))) -> Asset | Q32: =IF(AND(N32>$Q$9,N32<$Q$10),M32,IF(N32=$Q$10,M32,0)) -> 42869391 | R32: =IF(AND(N32>$R$9,N32<$R$10),M32,IF(N32=$R$10,M32,0)) -> 0 | S32: =IF(AND(N32>$S$9,N32<$S$10),M32,IF(N32=$S$10,M32,0)) -> 0 | T32: =IF(AND(N32>$T$9,N32<$T$10),M32,IF(N32=$T$10,M32,0)) -> 0 | U32: =IF(AND(N32>$U$9,N32<$U$10),M32,IF(N32=$U$10,M32,0)) -> 0 | V32: =IF(AND(N32>$V$9,N32<$V$10),M32,IF(N32=$V$10,M32,0)) -> 0 | W32: =IF(AND(N32>$W$9,N32<$W$10),M32,IF(N32=$W$10,M32,0)) -> 0 | X32: =IF(AND(N32>$X$9,N32<$X$10),M32,IF(N32=$X$10,M32,0)) -> 0 | Y32: =IF(AND(N32>$Y$9,N32<$Y$10),M32,IF(N32=$Y$10,M32,0)) -> 0 | Z32: =IF(AND(N32>$Z$9,N32<$Z$10),M32,IF(N32=$Z$10,M32,0)) -> 0 | AA32: =IF(AND(N32>$AA$9,N32<$AA$10),M32,IF(N32=$AA$10,M32,0)) -> 0 | AB32: =IF(AND(N32>$AB$9,N32<$AB$10),M32,IF(N32=$AB$10,M32,0)) -> 0 | AC32: =IF(AND(N32>$AC$9,N32<$AC$10),M32,IF(N32=$AC$10,M32,0)) -> 0 | AD32: =IF(AND(N32>$AD$9,N32<$AD$10),M32,IF(N32=$AD$10,M32,0)) -> 0 | AE32: =IF(AND(N32>$AE$9,N32<$AE$10),M32,IF(N32=$AE$10,M32,0)) -> 0 | AF32: =IF(AND(N32>$AF$9,N32<$AF$10),M32,IF(N32=$AF$10,M32,0)) -> 0 | AG32: =IF(N32=$AG$9,M32,0) -> 0
A33: 10620001 | B33: SYN-Working Capital Loan - Domestic | C33: 6115904000452 | D33: 100000035 | E33: NEXTDC LIMITED | F33: AUD | G33: 20000000 | H33: 20000000 | I33: 45629 | J33: 48185 | K33: 46084 | L33: =A33&"_"&F33&"_"&D33&"_"&E33 -> 10620001_AUD_100000035_NEXTDC LIMITED | M33: =IF(COUNTIF($A$2:$A$8,A33)>0,-H33,H33) -> 20000000 | N33: =IF(OR(L33=$L$2,L33=$L$3),$M$10+1,IFERROR(VLOOKUP(A33,'Repricing Maturity Adj.'!$A$3:$C$170,3,0),(IF(K33<$M$10,"Check",K33)))) -> 46084 | O33: =M33=SUM(Q33:AG33) -> TRUE | P33: =IF(A33="","N/A",IF(COUNTIF($A$2:$A$7,A33)>0,"Liability",IF(COUNTIF($A$8,A33)>0,"Asset",IF(A33<20000000,"Asset",IF(AND(A33>20000000,A33<28800000),"Liability",IF(A33>28800000,"Equity","")))))) -> Asset | Q33: =IF(AND(N33>$Q$9,N33<$Q$10),M33,IF(N33=$Q$10,M33,0)) -> 0 | R33: =IF(AND(N33>$R$9,N33<$R$10),M33,IF(N33=$R$10,M33,0)) -> 20000000 | S33: =IF(AND(N33>$S$9,N33<$S$10),M33,IF(N33=$S$10,M33,0)) -> 0 | T33: =IF(AND(N33>$T$9,N33<$T$10),M33,IF(N33=$T$10,M33,0)) -> 0 | U33: =IF(AND(N33>$U$9,N33<$U$10),M33,IF(N33=$U$10,M33,0)) -> 0 | V33: =IF(AND(N33>$V$9,N33<$V$10),M33,IF(N33=$V$10,M33,0)) -> 0 | W33: =IF(AND(N33>$W$9,N33<$W$10),M33,IF(N33=$W$10,M33,0)) -> 0 | X33: =IF(AND(N33>$X$9,N33<$X$10),M33,IF(N33=$X$10,M33,0)) -> 0 | Y33: =IF(AND(N33>$Y$9,N33<$Y$10),M33,IF(N33=$Y$10,M33,0)) -> 0 | Z33: =IF(AND(N33>$Z$9,N33<$Z$10),M33,IF(N33=$Z$10,M33,0)) -> 0 | AA33: =IF(AND(N33>$AA$9,N33<$AA$10),M33,IF(N33=$AA$10,M33,0)) -> 0 | AB33: =IF(AND(N33>$AB$9,N33<$AB$10),M33,IF(N33=$AB$10,M33,0)) -> 0 | AC33: =IF(AND(N33>$AC$9,N33<$AC$10),M33,IF(N33=$AC$10,M33,0)) -> 0 | AD33: =IF(AND(N33>$AD$9,N33<$AD$10),M33,IF(N33=$AD$10,M33,0)) -> 0 | AE33: =IF(AND(N33>$AE$9,N33<$AE$10),M33,IF(N33=$AE$10,M33,0)) -> 0 | AF33: =IF(AND(N33>$AF$9,N33<$AF$10),M33,IF(N33=$AF$10,M33,0)) -> 0 | AG33: =IF(N33=$AG$9,M33,0) -> 0
A34: 10620001 | B34: SYN-Working Capital Loan - Domestic | C34: 6115904000573 | D34: 100000039 | E34: QANTAS AIRWAYS LIMITED | F34: AUD | G34: 5000000 | H34: 5000000 | I34: 45791 | J34: 48341 | K34: 46066 | L34: =A34&"_"&F34&"_"&D34&"_"&E34 -> 10620001_AUD_100000039_QANTAS AIRWAYS LIMITED | M34: =IF(COUNTIF($A$2:$A$8,A34)>0,-H34,H34) -> 5000000 | N34: =IF(OR(L34=$L$2,L34=$L$3),$M$10+1,IFERROR(VLOOKUP(A34,'Repricing Maturity Adj.'!$A$3:$C$170,3,0),(IF(K34<$M$10,"Check",K34)))) -> 46066 | O34: =M34=SUM(Q34:AG34) -> TRUE | P34: =IF(A34="","N/A",IF(COUNTIF($A$2:$A$7,A34)>0,"Liability",IF(COUNTIF($A$8,A34)>0,"Asset",IF(A34<20000000,"Asset",IF(AND(A34>20000000,A34<28800000),"Liability",IF(A34>28800000,"Equity","")))))) -> Asset | Q34: =IF(AND(N34>$Q$9,N34<$Q$10),M34,IF(N34=$Q$10,M34,0)) -> 0 | R34: =IF(AND(N34>$R$9,N34<$R$10),M34,IF(N34=$R$10,M34,0)) -> 5000000 | S34: =IF(AND(N34>$S$9,N34<$S$10),M34,IF(N34=$S$10,M34,0)) -> 0 | T34: =IF(AND(N34>$T$9,N34<$T$10),M34,IF(N34=$T$10,M34,0)) -> 0 | U34: =IF(AND(N34>$U$9,N34<$U$10),M34,IF(N34=$U$10,M34,0)) -> 0 | V34: =IF(AND(N34>$V$9,N34<$V$10),M34,IF(N34=$V$10,M34,0)) -> 0 | W34: =IF(AND(N34>$W$9,N34<$W$10),M34,IF(N34=$W$10,M34,0)) -> 0 | X34: =IF(AND(N34>$X$9,N34<$X$10),M34,IF(N34=$X$10,M34,0)) -> 0 | Y34: =IF(AND(N34>$Y$9,N34<$Y$10),M34,IF(N34=$Y$10,M34,0)) -> 0 | Z34: =IF(AND(N34>$Z$9,N34<$Z$10),M34,IF(N34=$Z$10,M34,0)) -> 0 | AA34: =IF(AND(N34>$AA$9,N34<$AA$10),M34,IF(N34=$AA$10,M34,0)) -> 0 | AB34: =IF(AND(N34>$AB$9,N34<$AB$10),M34,IF(N34=$AB$10,M34,0)) -> 0 | AC34: =IF(AND(N34>$AC$9,N34<$AC$10),M34,IF(N34=$AC$10,M34,0)) -> 0 | AD34: =IF(AND(N34>$AD$9,N34<$AD$10),M34,IF(N34=$AD$10,M34,0)) -> 0 | AE34: =IF(AND(N34>$AE$9,N34<$AE$10),M34,IF(N34=$AE$10,M34,0)) -> 0 | AF34: =IF(AND(N34>$AF$9,N34<$AF$10),M34,IF(N34=$AF$10,M34,0)) -> 0 | AG34: =IF(N34=$AG$9,M34,0) -> 0
A35: 10620001 | B35: SYN-Working Capital Loan - Domestic | C35: 6115904000609 | D35: 100000040 | E35: DOWNER GROUP FINANCE PTY LIMITED | F35: AUD | G35: 35000000 | H35: 35000000 | I35: 45828 | J35: 48383 | K35: 46080 | L35: =A35&"_"&F35&"_"&D35&"_"&E35 -> 10620001_AUD_100000040_DOWNER GROUP FINANCE PTY LIMITED | M35: =IF(COUNTIF($A$2:$A$8,A35)>0,-H35,H35) -> 35000000 | N35: =IF(OR(L35=$L$2,L35=$L$3),$M$10+1,IFERROR(VLOOKUP(A35,'Repricing Maturity Adj.'!$A$3:$C$170,3,0),(IF(K35<$M$10,"Check",K35)))) -> 46080 | O35: =M35=SUM(Q35:AG35) -> TRUE | P35: =IF(A35="","N/A",IF(COUNTIF($A$2:$A$7,A35)>0,"Liability",IF(COUNTIF($A$8,A35)>0,"Asset",IF(A35<20000000,"Asset",IF(AND(A35>20000000,A35<28800000),"Liability",IF(A35>28800000,"Equity","")))))) -> Asset | Q35: =IF(AND(N35>$Q$9,N35<$Q$10),M35,IF(N35=$Q$10,M35,0)) -> 0 | R35: =IF(AND(N35>$R$9,N35<$R$10),M35,IF(N35=$R$10,M35,0)) -> 35000000 | S35: =IF(AND(N35>$S$9,N35<$S$10),M35,IF(N35=$S$10,M35,0)) -> 0 | T35: =IF(AND(N35>$T$9,N35<$T$10),M35,IF(N35=$T$10,M35,0)) -> 0 | U35: =IF(AND(N35>$U$9,N35<$U$10),M35,IF(N35=$U$10,M35,0)) -> 0 | V35: =IF(AND(N35>$V$9,N35<$V$10),M35,IF(N35=$V$10,M35,0)) -> 0 | W35: =IF(AND(N35>$W$9,N35<$W$10),M35,IF(N35=$W$10,M35,0)) -> 0 | X35: =IF(AND(N35>$X$9,N35<$X$10),M35,IF(N35=$X$10,M35,0)) -> 0 | Y35: =IF(AND(N35>$Y$9,N35<$Y$10),M35,IF(N35=$Y$10,M35,0)) -> 0 | Z35: =IF(AND(N35>$Z$9,N35<$Z$10),M35,IF(N35=$Z$10,M35,0)) -> 0 | AA35: =IF(AND(N35>$AA$9,N35<$AA$10),M35,IF(N35=$AA$10,M35,0)) -> 0 | AB35: =IF(AND(N35>$AB$9,N35<$AB$10),M35,IF(N35=$AB$10,M35,0)) -> 0 | AC35: =IF(AND(N35>$AC$9,N35<$AC$10),M35,IF(N35=$AC$10,M35,0)) -> 0 | AD35: =IF(AND(N35>$AD$9,N35<$AD$10),M35,IF(N35=$AD$10,M35,0)) -> 0 | AE35: =IF(AND(N35>$AE$9,N35<$AE$10),M35,IF(N35=$AE$10,M35,0)) -> 0 | AF35: =IF(AND(N35>$AF$9,N35<$AF$10),M35,IF(N35=$AF$10,M35,0)) -> 0 | AG35: =IF(N35=$AG$9,M35,0) -> 0
A36: 10620001 | B36: SYN-Working Capital Loan - Domestic | C36: 6115904000623 | D36: 100000020 | E36: APA INFRASTRUCTURE LIMITED | F36: AUD | G36: 20000000 | H36: 20000000 | I36: 45833 | J36: 48426 | K36: 46153 | L36: =A36&"_"&F36&"_"&D36&"_"&E36 -> 10620001_AUD_100000020_APA INFRASTRUCTURE LIMITED | M36: =IF(COUNTIF($A$2:$A$8,A36)>0,-H36,H36) -> 20000000 | N36: =IF(OR(L36=$L$2,L36=$L$3),$M$10+1,IFERROR(VLOOKUP(A36,'Repricing Maturity Adj.'!$A$3:$C$170,3,0),(IF(K36<$M$10,"Check",K36)))) -> 46153 | O36: =M36=SUM(Q36:AG36) -> TRUE | P36: =IF(A36="","N/A",IF(COUNTIF($A$2:$A$7,A36)>0,"Liability",IF(COUNTIF($A$8,A36)>0,"Asset",IF(A36<20000000,"Asset",IF(AND(A36>20000000,A36<28800000),"Liability",IF(A36>28800000,"Equity","")))))) -> Asset | Q36: =IF(AND(N36>$Q$9,N36<$Q$10),M36,IF(N36=$Q$10,M36,0)) -> 0 | R36: =IF(AND(N36>$R$9,N36<$R$10),M36,IF(N36=$R$10,M36,0)) -> 0 | S36: =IF(AND(N36>$S$9,N36<$S$10),M36,IF(N36=$S$10,M36,0)) -> 0 | T36: =IF(AND(N36>$T$9,N36<$T$10),M36,IF(N36=$T$10,M36,0)) -> 20000000 | U36: =IF(AND(N36>$U$9,N36<$U$10),M36,IF(N36=$U$10,M36,0)) -> 0 | V36: =IF(AND(N36>$V$9,N36<$V$10),M36,IF(N36=$V$10,M36,0)) -> 0 | W36: =IF(AND(N36>$W$9,N36<$W$10),M36,IF(N36=$W$10,M36,0)) -> 0 | X36: =IF(AND(N36>$X$9,N36<$X$10),M36,IF(N36=$X$10,M36,0)) -> 0 | Y36: =IF(AND(N36>$Y$9,N36<$Y$10),M36,IF(N36=$Y$10,M36,0)) -> 0 | Z36: =IF(AND(N36>$Z$9,N36<$Z$10),M36,IF(N36=$Z$10,M36,0)) -> 0 | AA36: =IF(AND(N36>$AA$9,N36<$AA$10),M36,IF(N36=$AA$10,M36,0)) -> 0 | AB36: =IF(AND(N36>$AB$9,N36<$AB$10),M36,IF(N36=$AB$10,M36,0)) -> 0 | AC36: =IF(AND(N36>$AC$9,N36<$AC$10),M36,IF(N36=$AC$10,M36,0)) -> 0 | AD36: =IF(AND(N36>$AD$9,N36<$AD$10),M36,IF(N36=$AD$10,M36,0)) -> 0 | AE36: =IF(AND(N36>$AE$9,N36<$AE$10),M36,IF(N36=$AE$10,M36,0)) -> 0 | AF36: =IF(AND(N36>$AF$9,N36<$AF$10),M36,IF(N36=$AF$10,M36,0)) -> 0 | AG36: =IF(N36=$AG$9,M36,0) -> 0
A37: 10620001 | B37: SYN-Working Capital Loan - Domestic | C37: 6115904000705 | D37: 100000039 | E37: QANTAS AIRWAYS LIMITED | F37: AUD | G37: 5000000 | H37: 5000000 | I37: 45924 | J37: 48487 | K37: 46105 | L37: =A37&"_"&F37&"_"&D37&"_"&E37 -> 10620001_AUD_100000039_QANTAS AIRWAYS LIMITED | M37: =IF(COUNTIF($A$2:$A$8,A37)>0,-H37,H37) -> 5000000 | N37: =IF(OR(L37=$L$2,L37=$L$3),$M$10+1,IFERROR(VLOOKUP(A37,'Repricing Maturity Adj.'!$A$3:$C$170,3,0),(IF(K37<$M$10,"Check",K37)))) -> 46105 | O37: =M37=SUM(Q37:AG37) -> TRUE | P37: =IF(A37="","N/A",IF(COUNTIF($A$2:$A$7,A37)>0,"Liability",IF(COUNTIF($A$8,A37)>0,"Asset",IF(A37<20000000,"Asset",IF(AND(A37>20000000,A37<28800000),"Liability",IF(A37>28800000,"Equity","")))))) -> Asset | Q37: =IF(AND(N37>$Q$9,N37<$Q$10),M37,IF(N37=$Q$10,M37,0)) -> 0 | R37: =IF(AND(N37>$R$9,N37<$R$10),M37,IF(N37=$R$10,M37,0)) -> 5000000 | S37: =IF(AND(N37>$S$9,N37<$S$10),M37,IF(N37=$S$10,M37,0)) -> 0 | T37: =IF(AND(N37>$T$9,N37<$T$10),M37,IF(N37=$T$10,M37,0)) -> 0 | U37: =IF(AND(N37>$U$9,N37<$U$10),M37,IF(N37=$U$10,M37,0)) -> 0 | V37: =IF(AND(N37>$V$9,N37<$V$10),M37,IF(N37=$V$10,M37,0)) -> 0 | W37: =IF(AND(N37>$W$9,N37<$W$10),M37,IF(N37=$W$10,M37,0)) -> 0 | X37: =IF(AND(N37>$X$9,N37<$X$10),M37,IF(N37=$X$10,M37,0)) -> 0 | Y37: =IF(AND(N37>$Y$9,N37<$Y$10),M37,IF(N37=$Y$10,M37,0)) -> 0 | Z37: =IF(AND(N37>$Z$9,N37<$Z$10),M37,IF(N37=$Z$10,M37,0)) -> 0 | AA37: =IF(AND(N37>$AA$9,N37<$AA$10),M37,IF(N37=$AA$10,M37,0)) -> 0 | AB37: =IF(AND(N37>$AB$9,N37<$AB$10),M37,IF(N37=$AB$10,M37,0)) -> 0 | AC37: =IF(AND(N37>$AC$9,N37<$AC$10),M37,IF(N37=$AC$10,M37,0)) -> 0 | AD37: =IF(AND(N37>$AD$9,N37<$AD$10),M37,IF(N37=$AD$10,M37,0)) -> 0 | AE37: =IF(AND(N37>$AE$9,N37<$AE$10),M37,IF(N37=$AE$10,M37,0)) -> 0 | AF37: =IF(AND(N37>$AF$9,N37<$AF$10),M37,IF(N37=$AF$10,M37,0)) -> 0 | AG37: =IF(N37=$AG$9,M37,0) -> 0
A38: 10620001 | B38: SYN-Working Capital Loan - Domestic | C38: 6115904000744 | D38: 100000033 | E38: MACQUARIE GROUP LIMITED | F38: USD | G38: 10000000 | H38: 14289797 | I38: 45974 | J38: 48136 | K38: 46066 | L38: =A38&"_"&F38&"_"&D38&"_"&E38 -> 10620001_USD_100000033_MACQUARIE GROUP LIMITED | M38: =IF(COUNTIF($A$2:$A$8,A38)>0,-H38,H38) -> 14289797 | N38: =IF(OR(L38=$L$2,L38=$L$3),$M$10+1,IFERROR(VLOOKUP(A38,'Repricing Maturity Adj.'!$A$3:$C$170,3,0),(IF(K38<$M$10,"Check",K38)))) -> 46059 | O38: =M38=SUM(Q38:AG38) -> TRUE | P38: =IF(A38="","N/A",IF(COUNTIF($A$2:$A$7,A38)>0,"Liability",IF(COUNTIF($A$8,A38)>0,"Asset",IF(A38<20000000,"Asset",IF(AND(A38>20000000,A38<28800000),"Liability",IF(A38>28800000,"Equity","")))))) -> Asset | Q38: =IF(AND(N38>$Q$9,N38<$Q$10),M38,IF(N38=$Q$10,M38,0)) -> 14289797 | R38: =IF(AND(N38>$R$9,N38<$R$10),M38,IF(N38=$R$10,M38,0)) -> 0 | S38: =IF(AND(N38>$S$9,N38<$S$10),M38,IF(N38=$S$10,M38,0)) -> 0 | T38: =IF(AND(N38>$T$9,N38<$T$10),M38,IF(N38=$T$10,M38,0)) -> 0 | U38: =IF(AND(N38>$U$9,N38<$U$10),M38,IF(N38=$U$10,M38,0)) -> 0 | V38: =IF(AND(N38>$V$9,N38<$V$10),M38,IF(N38=$V$10,M38,0)) -> 0 | W38: =IF(AND(N38>$W$9,N38<$W$10),M38,IF(N38=$W$10,M38,0)) -> 0 | X38: =IF(AND(N38>$X$9,N38<$X$10),M38,IF(N38=$X$10,M38,0)) -> 0 | Y38: =IF(AND(N38>$Y$9,N38<$Y$10),M38,IF(N38=$Y$10,M38,0)) -> 0 | Z38: =IF(AND(N38>$Z$9,N38<$Z$10),M38,IF(N38=$Z$10,M38,0)) -> 0 | AA38: =IF(AND(N38>$AA$9,N38<$AA$10),M38,IF(N38=$AA$10,M38,0)) -> 0 | AB38: =IF(AND(N38>$AB$9,N38<$AB$10),M38,IF(N38=$AB$10,M38,0)) -> 0 | AC38: =IF(AND(N38>$AC$9,N38<$AC$10),M38,IF(N38=$AC$10,M38,0)) -> 0 | AD38: =IF(AND(N38>$AD$9,N38<$AD$10),M38,IF(N38=$AD$10,M38,0)) -> 0 | AE38: =IF(AND(N38>$AE$9,N38<$AE$10),M38,IF(N38=$AE$10,M38,0)) -> 0 | AF38: =IF(AND(N38>$AF$9,N38<$AF$10),M38,IF(N38=$AF$10,M38,0)) -> 0 | AG38: =IF(N38=$AG$9,M38,0) -> 0
A39: 10630001 | B39: Syndicated Loans (Long Term) - Domestic | C39: 6115904000025 | D39: 100000014 | E39: PERDAMAN CHEMICALS & FERTILISERS (FINANCE)PTY LTD | F39: USD | G39: 7591892 | H39: 10848660 | I39: 45106 | J39: 47579 | K39: 46087 | L39: =A39&"_"&F39&"_"&D39&"_"&E39 -> 10630001_USD_100000014_PERDAMAN CHEMICALS & FERTILISERS (FINANCE)PTY LTD | M39: =IF(COUNTIF($A$2:$A$8,A39)>0,-H39,H39) -> 10848660 | N39: =IF(OR(L39=$L$2,L39=$L$3),$M$10+1,IFERROR(VLOOKUP(A39,'Repricing Maturity Adj.'!$A$3:$C$170,3,0),(IF(K39<$M$10,"Check",K39)))) -> 46059 | O39: =M39=SUM(Q39:AG39) -> TRUE | P39: =IF(A39="","N/A",IF(COUNTIF($A$2:$A$7,A39)>0,"Liability",IF(COUNTIF($A$8,A39)>0,"Asset",IF(A39<20000000,"Asset",IF(AND(A39>20000000,A39<28800000),"Liability",IF(A39>28800000,"Equity","")))))) -> Asset | Q39: =IF(AND(N39>$Q$9,N39<$Q$10),M39,IF(N39=$Q$10,M39,0)) -> 10848660 | R39: =IF(AND(N39>$R$9,N39<$R$10),M39,IF(N39=$R$10,M39,0)) -> 0 | S39: =IF(AND(N39>$S$9,N39<$S$10),M39,IF(N39=$S$10,M39,0)) -> 0 | T39: =IF(AND(N39>$T$9,N39<$T$10),M39,IF(N39=$T$10,M39,0)) -> 0 | U39: =IF(AND(N39>$U$9,N39<$U$10),M39,IF(N39=$U$10,M39,0)) -> 0 | V39: =IF(AND(N39>$V$9,N39<$V$10),M39,IF(N39=$V$10,M39,0)) -> 0 | W39: =IF(AND(N39>$W$9,N39<$W$10),M39,IF(N39=$W$10,M39,0)) -> 0 | X39: =IF(AND(N39>$X$9,N39<$X$10),M39,IF(N39=$X$10,M39,0)) -> 0 | Y39: =IF(AND(N39>$Y$9,N39<$Y$10),M39,IF(N39=$Y$10,M39,0)) -> 0 | Z39: =IF(AND(N39>$Z$9,N39<$Z$10),M39,IF(N39=$Z$10,M39,0)) -> 0 | AA39: =IF(AND(N39>$AA$9,N39<$AA$10),M39,IF(N39=$AA$10,M39,0)) -> 0 | AB39: =IF(AND(N39>$AB$9,N39<$AB$10),M39,IF(N39=$AB$10,M39,0)) -> 0 | AC39: =IF(AND(N39>$AC$9,N39<$AC$10),M39,IF(N39=$AC$10,M39,0)) -> 0 | AD39: =IF(AND(N39>$AD$9,N39<$AD$10),M39,IF(N39=$AD$10,M39,0)) -> 0 | AE39: =IF(AND(N39>$AE$9,N39<$AE$10),M39,IF(N39=$AE$10,M39,0)) -> 0 | AF39: =IF(AND(N39>$AF$9,N39<$AF$10),M39,IF(N39=$AF$10,M39,0)) -> 0 | AG39: =IF(N39=$AG$9,M39,0) -> 0
