Workbook
Name a: #REF!
Name a: #REF!
Name a: #REF!
Name a: #REF!
Name a: #REF!
Name a: #REF!
Name a: #REF!
Name a: #REF!
Name a: #REF!
Name a: #REF!
Name a: #REF!
Name a: #REF!
Name a: #REF!
Name a: #REF!
Name AGGREGATION: #REF!
Name AGGREGATION: #REF!
Name AGGREGATION: #REF!
Name AGGREGATION: #REF!
Name AGGREGATION: #REF!
Name AGGREGATION: #REF!
Name AGGREGATION: #REF!
Name AGGREGATION: #REF!
Name AGGREGATION: #REF!
Name AGGREGATION: #REF!
Name AGGREGATION: #REF!
Name AGGREGATION: #REF!
Name AGGREGATION: #REF!
Name AGGREGATION: #REF!
Name BankCode: [1]Cover!$E$3
Name CHECK: #REF!
Name CHECK: #REF!
Name CHECK: #REF!
Name CHECK: #REF!
Name CHECK: #REF!
Name CHECK: #REF!
Name CHECK: #REF!
Name CHECK: #REF!
Name CHECK: #REF!
Name CHECK: #REF!
Name CHECK: #REF!
Name CHECK: #REF!
Name CHECK: #REF!
Name CHECK: #REF!
Name CurrencyCode: OFFSET([1]wksCurrency!$B$2:$B$27,1,0,ROWS([1]wksCurrency!$B$2:$B$27)-2)
Name CurrencyName: OFFSET([1]wksCurrency!$A$2:$A$27,1,0,ROWS([1]wksCurrency!$A$2:$A$27)-2)
Name date: [2]BSY_현지화!#REF!
Name date: [2]BSY_현지화!#REF!
Name date: [2]BSY_현지화!#REF!
Name date: [2]BSY_현지화!#REF!
Name date: [2]BSY_현지화!#REF!
Name date: [2]BSY_현지화!#REF!
Name date: [2]BSY_현지화!#REF!
Name date: [2]BSY_현지화!#REF!
Name date: [2]BSY_현지화!#REF!
Name date: [2]BSY_현지화!#REF!
Name date: [2]BSY_현지화!#REF!
Name date: [2]BSY_현지화!#REF!
Name date: [2]BSY_현지화!#REF!
Name date: [2]BSY_현지화!#REF!
Name DOMAIN: #REF!

Sheet Summary
B1: Liquidity Coverage Ratio Management | K1: =BS_RE33!N4 -> 46058
B3: LCR (%) | C3: 3M Liquidity Ratio (%)
B4: ='30 days CF Table(ALL)'!$D$119 -> #DIV/0! | C4: ='Liquidity Maturity Gap'!Q73 -> #DIV/0!
B6: KRI | C6: KRI | D6: Ratio (%) | E6: Trigger | F6: Reached ? Y or N | G6: Limit | H6: Breached ? Y or N
B7: Liquidity Gap Ratio | C7: 7D | D7: ='Liquidity Maturity Gap'!J73 -> #DIV/0! | E7: 0 | F7: =IF(D7<E7,"Y","N") -> #DIV/0! | G7: -0.05 | H7: =IF(D7<G7,"Y","N") -> #DIV/0!
C8: 1M | D8: ='Liquidity Maturity Gap'!J74 -> #DIV/0! | E8: -0.15 | F8: =IF(D8<E8,"Y","N") -> #DIV/0! | G8: -0.2 | H8: =IF(D8<G8,"Y","N") -> #DIV/0!
C9: 3M | D9: ='Liquidity Maturity Gap'!J75 -> #DIV/0! | E9: -0.4 | F9: =IF(D9<E9,"Y","N") -> #DIV/0! | G9: -0.45 | H9: =IF(D9<G9,"Y","N") -> #DIV/0!
B12: Liquidity Gap Ratio Forecast
B14: 7 day | C14: From | D14: =BS_RE33!AL9 -> 46081 | E14: =EOMONTH(D14,1) -> 46112 | F14: =EOMONTH(E14,1) -> 46142 | G14: =EOMONTH(F14,1) -> 46173 | H14: =EOMONTH(G14,1) -> 46203 | I14: =EOMONTH(H14,1) -> 46234 | J14: =EOMONTH(I14,1) -> 46265 | K14: =EOMONTH(J14,1) -> 46295
C15: To | D15: =D14+7 -> 46088 | E15: =E14+7 -> 46119 | F15: =F14+7 -> 46149 | G15: =G14+7 -> 46180 | H15: =H14+7 -> 46210 | I15: =I14+7 -> 46241 | J15: =J14+7 -> 46272 | K15: =K14+7 -> 46302
C16: Gap ratio | D16: =BS_RE33!AL17 -> #DIV/0! | E16: =BS_RE33!AM17 -> #DIV/0! | F16: =BS_RE33!AN17 -> #DIV/0! | G16: =BS_RE33!AO17 -> #DIV/0! | H16: =BS_RE33!AP17 -> #DIV/0! | I16: =BS_RE33!AQ17 -> #DIV/0! | J16: =BS_RE33!AR17 -> #DIV/0! | K16: =BS_RE33!AS17 -> #DIV/0!
C17: Trigger | D17: 0 | E17: =D17 -> 0 | F17: =E17 -> 0 | G17: =F17 -> 0 | H17: =G17 -> 0 | I17: =H17 -> 0 | J17: =I17 -> 0 | K17: =J17 -> 0
B19: 1 month | C19: From | D19: =D14 -> 46081 | E19: =EOMONTH(D19,1) -> 46112 | F19: =EOMONTH(E19,1) -> 46142 | G19: =EOMONTH(F19,1) -> 46173 | H19: =EOMONTH(G19,1) -> 46203 | I19: =EOMONTH(H19,1) -> 46234 | J19: =EOMONTH(I19,1) -> 46265 | K19: =EOMONTH(J19,1) -> 46295
C20: To | D20: =EOMONTH(D19,1) -> 46112 | E20: =EOMONTH(E19,1) -> 46142 | F20: =EOMONTH(F19,1) -> 46173 | G20: =EOMONTH(G19,1) -> 46203 | H20: =EOMONTH(H19,1) -> 46234 | I20: =EOMONTH(I19,1) -> 46265 | J20: =EOMONTH(J19,1) -> 46295 | K20: =EOMONTH(K19,1) -> 46326
C21: Gap ratio | D21: =BS_RE33!AL29 -> #DIV/0! | E21: =BS_RE33!AM29 -> #DIV/0! | F21: =BS_RE33!AN29 -> #DIV/0! | G21: =BS_RE33!AO29 -> #DIV/0! | H21: =BS_RE33!AP29 -> #DIV/0! | I21: =BS_RE33!AQ29 -> #DIV/0! | J21: =BS_RE33!AR29 -> #DIV/0! | K21: =BS_RE33!AS29 -> #DIV/0!
C22: Trigger | D22: -0.15 | E22: =D22 -> -0.15 | F22: =E22 -> -0.15 | G22: =F22 -> -0.15 | H22: =G22 -> -0.15 | I22: =H22 -> -0.15 | J22: =I22 -> -0.15 | K22: =J22 -> -0.15
B24: 3 month | C24: From | D24: =D19 -> 46081 | E24: =EOMONTH(D24,1) -> 46112 | F24: =EOMONTH(E24,1) -> 46142 | G24: =EOMONTH(F24,1) -> 46173 | H24: =EOMONTH(G24,1) -> 46203 | I24: =EOMONTH(H24,1) -> 46234 | J24: =EOMONTH(I24,1) -> 46265 | K24: =EOMONTH(J24,1) -> 46295
C25: To | D25: =EOMONTH(D24,3) -> 46173 | E25: =EOMONTH(E24,3) -> 46203 | F25: =EOMONTH(F24,3) -> 46234 | G25: =EOMONTH(G24,3) -> 46265 | H25: =EOMONTH(H24,3) -> 46295 | I25: =EOMONTH(I24,3) -> 46326 | J25: =EOMONTH(J24,3) -> 46356 | K25: =EOMONTH(K24,3) -> 46387
C26: Gap ratio | D26: =BS_RE33!AL41 -> #DIV/0! | E26: =BS_RE33!AM41 -> #DIV/0! | F26: =BS_RE33!AN41 -> #DIV/0! | G26: =BS_RE33!AO41 -> #DIV/0! | H26: =BS_RE33!AP41 -> #DIV/0! | I26: =BS_RE33!AQ41 -> #DIV/0! | J26: =BS_RE33!AR41 -> #DIV/0! | K26: =BS_RE33!AS41 -> #DIV/0!
C27: Trigger | D27: -0.4 | E27: =D27 -> -0.4 | F27: =E27 -> -0.4 | G27: =F27 -> -0.4 | H27: =G27 -> -0.4 | I27: =H27 -> -0.4 | J27: =I27 -> -0.4 | K27: =J27 -> -0.4

Sheet Liquidity Maturity Gap
C2: =BS_RE33!N4 -> 46058 | D2: =ROUND((F24-F51),0)=ROUND(SUM(H52:Q52),0) -> TRUE
C3: Category (1) | D3: Category (2) | E3: Middle Category | F3: Customer Type | G3: Ref. | H3: Overnight (O/N) | I3: 2-7 Days | J3: 8 Days to <1 month | K3: 1 to < 3 months | L3: 3 to < 6 months | M3: 6 to < 12 months | N3: 1 to < 3 years | O3: 3 to < 5 years | P3: 5 to < 10 years | Q3: 10+ years or No Maturity
C4: Asset | D4: Deposit | E4: Deposit_Asset(Our) | G4: Deposit_Asset(Our)_ | H4: =SUMIF(BS_RE33!$P$7:$P$874,G4,BS_RE33!$X$7:$X$874) -> 0 | I4: =SUMIF(BS_RE33!$P$7:$P$874,G4,BS_RE33!$Y$7:$Y$874) -> 0 | J4: =SUMIF(BS_RE33!$P$7:$P$874,G4,BS_RE33!$Z$7:$Z$874) -> 0 | K4: =SUMIF(BS_RE33!$P$7:$P$874,G4,BS_RE33!$AA$7:$AA$874) -> 0 | L4: =SUMIF(BS_RE33!$P$7:$P$874,G4,BS_RE33!$AB$7:$AB$874) -> 0 | M4: =SUMIF(BS_RE33!$P$7:$P$874,G4,BS_RE33!$AC$7:$AC$874) -> 0 | N4: =SUMIF(BS_RE33!$P$7:$P$874,G4,BS_RE33!$AD$7:$AD$874) -> 0 | O4: =SUMIF(BS_RE33!$P$7:$P$874,G4,BS_RE33!$AE$7:$AE$874) -> 0 | P4: =SUMIF(BS_RE33!$P$7:$P$874,G4,BS_RE33!$AF$7:$AF$874) -> 0 | Q4: =SUMIF(BS_RE33!$P$7:$P$874,G4,BS_RE33!$AG$7:$AG$874) -> 0
E5: Deposit_Asset | G5: Deposit_Asset_ | H5: =SUMIF(BS_RE33!$P$7:$P$874,G5,BS_RE33!$X$7:$X$874) -> 0 | I5: =SUMIF(BS_RE33!$P$7:$P$874,G5,BS_RE33!$Y$7:$Y$874) -> 0 | J5: =SUMIF(BS_RE33!$P$7:$P$874,G5,BS_RE33!$Z$7:$Z$874) -> 0 | K5: =SUMIF(BS_RE33!$P$7:$P$874,G5,BS_RE33!$AA$7:$AA$874) -> 0 | L5: =SUMIF(BS_RE33!$P$7:$P$874,G5,BS_RE33!$AB$7:$AB$874) -> 0 | M5: =SUMIF(BS_RE33!$P$7:$P$874,G5,BS_RE33!$AC$7:$AC$874) -> 0 | N5: =SUMIF(BS_RE33!$P$7:$P$874,G5,BS_RE33!$AD$7:$AD$874) -> 0 | O5: =SUMIF(BS_RE33!$P$7:$P$874,G5,BS_RE33!$AE$7:$AE$874) -> 0 | P5: =SUMIF(BS_RE33!$P$7:$P$874,G5,BS_RE33!$AF$7:$AF$874) -> 0 | Q5: =SUMIF(BS_RE33!$P$7:$P$874,G5,BS_RE33!$AG$7:$AG$874) -> 0
D6: HQLA | E6: HQLA | F6: Australian State Government or Territory Central Borrowing Authorities | G6: HQLA_Australian State Government or Territory Central Borrowing Authorities | H6: =SUMIF(BS_RE33!$P$7:$P$874,G6,BS_RE33!$X$7:$X$874) -> 0 | I6: =SUMIF(BS_RE33!$P$7:$P$874,G6,BS_RE33!$Y$7:$Y$874) -> 0 | J6: =SUMIF(BS_RE33!$P$7:$P$874,G6,BS_RE33!$Z$7:$Z$874) -> 0 | K6: =SUMIF(BS_RE33!$P$7:$P$874,G6,BS_RE33!$AA$7:$AA$874) -> 0 | L6: =SUMIF(BS_RE33!$P$7:$P$874,G6,BS_RE33!$AB$7:$AB$874) -> 0 | M6: =SUMIF(BS_RE33!$P$7:$P$874,G6,BS_RE33!$AC$7:$AC$874) -> 0 | N6: =SUMIF(BS_RE33!$P$7:$P$874,G6,BS_RE33!$AD$7:$AD$874) -> 0 | O6: =SUMIF(BS_RE33!$P$7:$P$874,G6,BS_RE33!$AE$7:$AE$874) -> 0 | P6: =SUMIF(BS_RE33!$P$7:$P$874,G6,BS_RE33!$AF$7:$AF$874) -> 0 | Q6: =SUMIF(BS_RE33!$P$7:$P$874,G6,BS_RE33!$AG$7:$AG$874) -> 0
E7: HQLA | F7: Issued or guaranteed by PSEs | G7: HQLA_Issued or guaranteed by PSEs | H7: =SUMIF(BS_RE33!$P$7:$P$874,G7,BS_RE33!$X$7:$X$874) -> 0 | I7: =SUMIF(BS_RE33!$P$7:$P$874,G7,BS_RE33!$Y$7:$Y$874) -> 0 | J7: =SUMIF(BS_RE33!$P$7:$P$874,G7,BS_RE33!$Z$7:$Z$874) -> 0 | K7: =SUMIF(BS_RE33!$P$7:$P$874,G7,BS_RE33!$AA$7:$AA$874) -> 0 | L7: =SUMIF(BS_RE33!$P$7:$P$874,G7,BS_RE33!$AB$7:$AB$874) -> 0 | M7: =SUMIF(BS_RE33!$P$7:$P$874,G7,BS_RE33!$AC$7:$AC$874) -> 0 | N7: =SUMIF(BS_RE33!$P$7:$P$874,G7,BS_RE33!$AD$7:$AD$874) -> 0 | O7: =SUMIF(BS_RE33!$P$7:$P$874,G7,BS_RE33!$AE$7:$AE$874) -> 0 | P7: =SUMIF(BS_RE33!$P$7:$P$874,G7,BS_RE33!$AF$7:$AF$874) -> 0 | Q7: =SUMIF(BS_RE33!$P$7:$P$874,G7,BS_RE33!$AG$7:$AG$874) -> 0
D8: Trade Finance | E8: Trade Finance_Asset | G8: Trade Finance_Asset_ | H8: =SUMIF(BS_RE33!$P$7:$P$874,G8,BS_RE33!$X$7:$X$874) -> 0 | I8: =SUMIF(BS_RE33!$P$7:$P$874,G8,BS_RE33!$Y$7:$Y$874) -> 0 | J8: =SUMIF(BS_RE33!$P$7:$P$874,G8,BS_RE33!$Z$7:$Z$874) -> 0 | K8: =SUMIF(BS_RE33!$P$7:$P$874,G8,BS_RE33!$AA$7:$AA$874) -> 0 | L8: =SUMIF(BS_RE33!$P$7:$P$874,G8,BS_RE33!$AB$7:$AB$874) -> 0 | M8: =SUMIF(BS_RE33!$P$7:$P$874,G8,BS_RE33!$AC$7:$AC$874) -> 0 | N8: =SUMIF(BS_RE33!$P$7:$P$874,G8,BS_RE33!$AD$7:$AD$874) -> 0 | O8: =SUMIF(BS_RE33!$P$7:$P$874,G8,BS_RE33!$AE$7:$AE$874) -> 0 | P8: =SUMIF(BS_RE33!$P$7:$P$874,G8,BS_RE33!$AF$7:$AF$874) -> 0 | Q8: =SUMIF(BS_RE33!$P$7:$P$874,G8,BS_RE33!$AG$7:$AG$874) -> 0
D9: Loan | E9: Loan | F9: Household | G9: Loan_Household | H9: =SUMIF(BS_RE33!$P$7:$P$874,G9,BS_RE33!$X$7:$X$874) -> 0 | I9: =SUMIF(BS_RE33!$P$7:$P$874,G9,BS_RE33!$Y$7:$Y$874) -> 0 | J9: =SUMIF(BS_RE33!$P$7:$P$874,G9,BS_RE33!$Z$7:$Z$874) -> 0 | K9: =SUMIF(BS_RE33!$P$7:$P$874,G9,BS_RE33!$AA$7:$AA$874) -> 0 | L9: =SUMIF(BS_RE33!$P$7:$P$874,G9,BS_RE33!$AB$7:$AB$874) -> 0 | M9: =SUMIF(BS_RE33!$P$7:$P$874,G9,BS_RE33!$AC$7:$AC$874) -> 0 | N9: =SUMIF(BS_RE33!$P$7:$P$874,G9,BS_RE33!$AD$7:$AD$874) -> 0 | O9: =SUMIF(BS_RE33!$P$7:$P$874,G9,BS_RE33!$AE$7:$AE$874) -> 0 | P9: =SUMIF(BS_RE33!$P$7:$P$874,G9,BS_RE33!$AF$7:$AF$874) -> 0 | Q9: =SUMIF(BS_RE33!$P$7:$P$874,G9,BS_RE33!$AG$7:$AG$874) -> 0
E10: Loan | F10: SME | G10: Loan_SME | H10: =SUMIF(BS_RE33!$P$7:$P$874,G10,BS_RE33!$X$7:$X$874) -> 0 | I10: =SUMIF(BS_RE33!$P$7:$P$874,G10,BS_RE33!$Y$7:$Y$874) -> 0 | J10: =SUMIF(BS_RE33!$P$7:$P$874,G10,BS_RE33!$Z$7:$Z$874) -> 0 | K10: =SUMIF(BS_RE33!$P$7:$P$874,G10,BS_RE33!$AA$7:$AA$874) -> 0 | L10: =SUMIF(BS_RE33!$P$7:$P$874,G10,BS_RE33!$AB$7:$AB$874) -> 0 | M10: =SUMIF(BS_RE33!$P$7:$P$874,G10,BS_RE33!$AC$7:$AC$874) -> 0 | N10: =SUMIF(BS_RE33!$P$7:$P$874,G10,BS_RE33!$AD$7:$AD$874) -> 0 | O10: =SUMIF(BS_RE33!$P$7:$P$874,G10,BS_RE33!$AE$7:$AE$874) -> 0 | P10: =SUMIF(BS_RE33!$P$7:$P$874,G10,BS_RE33!$AF$7:$AF$874) -> 0 | Q10: =SUMIF(BS_RE33!$P$7:$P$874,G10,BS_RE33!$AG$7:$AG$874) -> 0
E11: Loan | F11: Non-financialcorporations | G11: Loan_Non-financialcorporations | H11: =SUMIF(BS_RE33!$P$7:$P$874,G11,BS_RE33!$X$7:$X$874) -> 0 | I11: =SUMIF(BS_RE33!$P$7:$P$874,G11,BS_RE33!$Y$7:$Y$874) -> 0 | J11: =SUMIF(BS_RE33!$P$7:$P$874,G11,BS_RE33!$Z$7:$Z$874) -> 0 | K11: =SUMIF(BS_RE33!$P$7:$P$874,G11,BS_RE33!$AA$7:$AA$874) -> 0 | L11: =SUMIF(BS_RE33!$P$7:$P$874,G11,BS_RE33!$AB$7:$AB$874) -> 0 | M11: =SUMIF(BS_RE33!$P$7:$P$874,G11,BS_RE33!$AC$7:$AC$874) -> 0 | N11: =SUMIF(BS_RE33!$P$7:$P$874,G11,BS_RE33!$AD$7:$AD$874) -> 0 | O11: =SUMIF(BS_RE33!$P$7:$P$874,G11,BS_RE33!$AE$7:$AE$874) -> 0 | P11: =SUMIF(BS_RE33!$P$7:$P$874,G11,BS_RE33!$AF$7:$AF$874) -> 0 | Q11: =SUMIF(BS_RE33!$P$7:$P$874,G11,BS_RE33!$AG$7:$AG$874) -> 0
E12: Loan | F12: Advance(Loan Guarantee) | G12: Loan_Advance(Loan Guarantee) | H12: =SUMIF(BS_RE33!$P$7:$P$874,G12,BS_RE33!$X$7:$X$874) -> 0 | I12: =SUMIF(BS_RE33!$P$7:$P$874,G12,BS_RE33!$Y$7:$Y$874) -> 0 | J12: =SUMIF(BS_RE33!$P$7:$P$874,G12,BS_RE33!$Z$7:$Z$874) -> 0 | K12: =SUMIF(BS_RE33!$P$7:$P$874,G12,BS_RE33!$AA$7:$AA$874) -> 0 | L12: =SUMIF(BS_RE33!$P$7:$P$874,G12,BS_RE33!$AB$7:$AB$874) -> 0 | M12: =SUMIF(BS_RE33!$P$7:$P$874,G12,BS_RE33!$AC$7:$AC$874) -> 0 | N12: =SUMIF(BS_RE33!$P$7:$P$874,G12,BS_RE33!$AD$7:$AD$874) -> 0 | O12: =SUMIF(BS_RE33!$P$7:$P$874,G12,BS_RE33!$AE$7:$AE$874) -> 0 | P12: =SUMIF(BS_RE33!$P$7:$P$874,G12,BS_RE33!$AF$7:$AF$874) -> 0 | Q12: =SUMIF(BS_RE33!$P$7:$P$874,G12,BS_RE33!$AG$7:$AG$874) -> 0
E13: Loan | F13: Private placement-Corp Bonds | G13: Loan_Private placement-Corp Bonds | H13: =SUMIF(BS_RE33!$P$7:$P$874,G13,BS_RE33!$X$7:$X$874) -> 0 | I13: =SUMIF(BS_RE33!$P$7:$P$874,G13,BS_RE33!$Y$7:$Y$874) -> 0 | J13: =SUMIF(BS_RE33!$P$7:$P$874,G13,BS_RE33!$Z$7:$Z$874) -> 0 | K13: =SUMIF(BS_RE33!$P$7:$P$874,G13,BS_RE33!$AA$7:$AA$874) -> 0 | L13: =SUMIF(BS_RE33!$P$7:$P$874,G13,BS_RE33!$AB$7:$AB$874) -> 0 | M13: =SUMIF(BS_RE33!$P$7:$P$874,G13,BS_RE33!$AC$7:$AC$874) -> 0 | N13: =SUMIF(BS_RE33!$P$7:$P$874,G13,BS_RE33!$AD$7:$AD$874) -> 0 | O13: =SUMIF(BS_RE33!$P$7:$P$874,G13,BS_RE33!$AE$7:$AE$874) -> 0 | P13: =SUMIF(BS_RE33!$P$7:$P$874,G13,BS_RE33!$AF$7:$AF$874) -> 0 | Q13: =SUMIF(BS_RE33!$P$7:$P$874,G13,BS_RE33!$AG$7:$AG$874) -> 0
E14: Loan | F14: EUBB | G14: Loan_EUBB | H14: =SUMIF(BS_RE33!$P$7:$P$874,G14,BS_RE33!$X$7:$X$874) -> 0 | I14: =SUMIF(BS_RE33!$P$7:$P$874,G14,BS_RE33!$Y$7:$Y$874) -> 0 | J14: =SUMIF(BS_RE33!$P$7:$P$874,G14,BS_RE33!$Z$7:$Z$874) -> 0 | K14: =SUMIF(BS_RE33!$P$7:$P$874,G14,BS_RE33!$AA$7:$AA$874) -> 0 | L14: =SUMIF(BS_RE33!$P$7:$P$874,G14,BS_RE33!$AB$7:$AB$874) -> 0 | M14: =SUMIF(BS_RE33!$P$7:$P$874,G14,BS_RE33!$AC$7:$AC$874) -> 0 | N14: =SUMIF(BS_RE33!$P$7:$P$874,G14,BS_RE33!$AD$7:$AD$874) -> 0 | O14: =SUMIF(BS_RE33!$P$7:$P$874,G14,BS_RE33!$AE$7:$AE$874) -> 0 | P14: =SUMIF(BS_RE33!$P$7:$P$874,G14,BS_RE33!$AF$7:$AF$874) -> 0 | Q14: =SUMIF(BS_RE33!$P$7:$P$874,G14,BS_RE33!$AG$7:$AG$874) -> 0
E15: Loan | F15: Financialinstitutions | G15: Loan_Financialinstitutions | H15: =SUMIF(BS_RE33!$P$7:$P$874,G15,BS_RE33!$X$7:$X$874) -> 0 | I15: =SUMIF(BS_RE33!$P$7:$P$874,G15,BS_RE33!$Y$7:$Y$874) -> 0 | J15: =SUMIF(BS_RE33!$P$7:$P$874,G15,BS_RE33!$Z$7:$Z$874) -> 0 | K15: =SUMIF(BS_RE33!$P$7:$P$874,G15,BS_RE33!$AA$7:$AA$874) -> 0 | L15: =SUMIF(BS_RE33!$P$7:$P$874,G15,BS_RE33!$AB$7:$AB$874) -> 0 | M15: =SUMIF(BS_RE33!$P$7:$P$874,G15,BS_RE33!$AC$7:$AC$874) -> 0 | N15: =SUMIF(BS_RE33!$P$7:$P$874,G15,BS_RE33!$AD$7:$AD$874) -> 0 | O15: =SUMIF(BS_RE33!$P$7:$P$874,G15,BS_RE33!$AE$7:$AE$874) -> 0 | P15: =SUMIF(BS_RE33!$P$7:$P$874,G15,BS_RE33!$AF$7:$AF$874) -> 0 | Q15: =SUMIF(BS_RE33!$P$7:$P$874,G15,BS_RE33!$AG$7:$AG$874) -> 0
D16: Derivative | E16: Derivative_Asset | G16: Derivative_Asset_ | H16: =SUMIF(BS_RE33!$P$7:$P$874,G16,BS_RE33!$X$7:$X$874) -> 0 | I16: =SUMIF(BS_RE33!$P$7:$P$874,G16,BS_RE33!$Y$7:$Y$874) -> 0 | J16: =SUMIF(BS_RE33!$P$7:$P$874,G16,BS_RE33!$Z$7:$Z$874) -> 0 | K16: =SUMIF(BS_RE33!$P$7:$P$874,G16,BS_RE33!$AA$7:$AA$874) -> 0 | L16: =SUMIF(BS_RE33!$P$7:$P$874,G16,BS_RE33!$AB$7:$AB$874) -> 0 | M16: =SUMIF(BS_RE33!$P$7:$P$874,G16,BS_RE33!$AC$7:$AC$874) -> 0 | N16: =SUMIF(BS_RE33!$P$7:$P$874,G16,BS_RE33!$AD$7:$AD$874) -> 0 | O16: =SUMIF(BS_RE33!$P$7:$P$874,G16,BS_RE33!$AE$7:$AE$874) -> 0 | P16: =SUMIF(BS_RE33!$P$7:$P$874,G16,BS_RE33!$AF$7:$AF$874) -> 0 | Q16: =SUMIF(BS_RE33!$P$7:$P$874,G16,BS_RE33!$AG$7:$AG$874) -> 0
D17: Inter-office | E17: Inter-office_Asset (inter-office A) | G17: Inter-office_Asset (inter-office A)_ | H17: =SUMIF(BS_RE33!$P$7:$P$874,G17,BS_RE33!$X$7:$X$874) -> 0 | I17: =SUMIF(BS_RE33!$P$7:$P$874,G17,BS_RE33!$Y$7:$Y$874) -> 0 | J17: =SUMIF(BS_RE33!$P$7:$P$874,G17,BS_RE33!$Z$7:$Z$874) -> 0 | K17: =SUMIF(BS_RE33!$P$7:$P$874,G17,BS_RE33!$AA$7:$AA$874) -> 0 | L17: =SUMIF(BS_RE33!$P$7:$P$874,G17,BS_RE33!$AB$7:$AB$874) -> 0 | M17: =SUMIF(BS_RE33!$P$7:$P$874,G17,BS_RE33!$AC$7:$AC$874) -> 0 | N17: =SUMIF(BS_RE33!$P$7:$P$874,G17,BS_RE33!$AD$7:$AD$874) -> 0 | O17: =SUMIF(BS_RE33!$P$7:$P$874,G17,BS_RE33!$AE$7:$AE$874) -> 0 | P17: =SUMIF(BS_RE33!$P$7:$P$874,G17,BS_RE33!$AF$7:$AF$874) -> 0 | Q17: =SUMIF(BS_RE33!$P$7:$P$874,G17,BS_RE33!$AG$7:$AG$874) -> 0
E18: Inter-office_Asset (inter-office (EUBB)) | G18: Inter-office_Asset (inter-office (EUBB))_ | H18: =SUMIF(BS_RE33!$P$7:$P$874,G18,BS_RE33!$X$7:$X$874) -> 0 | I18: =SUMIF(BS_RE33!$P$7:$P$874,G18,BS_RE33!$Y$7:$Y$874) -> 0 | J18: =SUMIF(BS_RE33!$P$7:$P$874,G18,BS_RE33!$Z$7:$Z$874) -> 0 | K18: =SUMIF(BS_RE33!$P$7:$P$874,G18,BS_RE33!$AA$7:$AA$874) -> 0 | L18: =SUMIF(BS_RE33!$P$7:$P$874,G18,BS_RE33!$AB$7:$AB$874) -> 0 | M18: =SUMIF(BS_RE33!$P$7:$P$874,G18,BS_RE33!$AC$7:$AC$874) -> 0 | N18: =SUMIF(BS_RE33!$P$7:$P$874,G18,BS_RE33!$AD$7:$AD$874) -> 0 | O18: =SUMIF(BS_RE33!$P$7:$P$874,G18,BS_RE33!$AE$7:$AE$874) -> 0 | P18: =SUMIF(BS_RE33!$P$7:$P$874,G18,BS_RE33!$AF$7:$AF$874) -> 0 | Q18: =SUMIF(BS_RE33!$P$7:$P$874,G18,BS_RE33!$AG$7:$AG$874) -> 0
D19: Other Asset | E19: Other_Asset (Receivable) | G19: Other_Asset (Receivable)_ | H19: =SUMIF(BS_RE33!$P$7:$P$874,G19,BS_RE33!$X$7:$X$874) -> 0 | I19: =SUMIF(BS_RE33!$P$7:$P$874,G19,BS_RE33!$Y$7:$Y$874) -> 0 | J19: =SUMIF(BS_RE33!$P$7:$P$874,G19,BS_RE33!$Z$7:$Z$874) -> 0 | K19: =SUMIF(BS_RE33!$P$7:$P$874,G19,BS_RE33!$AA$7:$AA$874) -> 0 | L19: =SUMIF(BS_RE33!$P$7:$P$874,G19,BS_RE33!$AB$7:$AB$874) -> 0 | M19: =SUMIF(BS_RE33!$P$7:$P$874,G19,BS_RE33!$AC$7:$AC$874) -> 0 | N19: =SUMIF(BS_RE33!$P$7:$P$874,G19,BS_RE33!$AD$7:$AD$874) -> 0 | O19: =SUMIF(BS_RE33!$P$7:$P$874,G19,BS_RE33!$AE$7:$AE$874) -> 0 | P19: =SUMIF(BS_RE33!$P$7:$P$874,G19,BS_RE33!$AF$7:$AF$874) -> 0 | Q19: =SUMIF(BS_RE33!$P$7:$P$874,G19,BS_RE33!$AG$7:$AG$874) -> 0
E20: Other_Asset (Accrued Incomes) | G20: Other_Asset (Accrued Incomes)_ | H20: =SUMIF(BS_RE33!$P$7:$P$874,G20,BS_RE33!$X$7:$X$874) -> 0 | I20: =SUMIF(BS_RE33!$P$7:$P$874,G20,BS_RE33!$Y$7:$Y$874) -> 0 | J20: =SUMIF(BS_RE33!$P$7:$P$874,G20,BS_RE33!$Z$7:$Z$874) -> 0 | K20: =SUMIF(BS_RE33!$P$7:$P$874,G20,BS_RE33!$AA$7:$AA$874) -> 0 | L20: =SUMIF(BS_RE33!$P$7:$P$874,G20,BS_RE33!$AB$7:$AB$874) -> 0 | M20: =SUMIF(BS_RE33!$P$7:$P$874,G20,BS_RE33!$AC$7:$AC$874) -> 0 | N20: =SUMIF(BS_RE33!$P$7:$P$874,G20,BS_RE33!$AD$7:$AD$874) -> 0 | O20: =SUMIF(BS_RE33!$P$7:$P$874,G20,BS_RE33!$AE$7:$AE$874) -> 0 | P20: =SUMIF(BS_RE33!$P$7:$P$874,G20,BS_RE33!$AF$7:$AF$874) -> 0 | Q20: =SUMIF(BS_RE33!$P$7:$P$874,G20,BS_RE33!$AG$7:$AG$874) -> 0
E21: Other_Asset (Other assets) | G21: Other_Asset (Other assets)_ | H21: =SUMIF(BS_RE33!$P$7:$P$874,G21,BS_RE33!$X$7:$X$874) -> 0 | I21: =SUMIF(BS_RE33!$P$7:$P$874,G21,BS_RE33!$Y$7:$Y$874) -> 0 | J21: =SUMIF(BS_RE33!$P$7:$P$874,G21,BS_RE33!$Z$7:$Z$874) -> 0 | K21: =SUMIF(BS_RE33!$P$7:$P$874,G21,BS_RE33!$AA$7:$AA$874) -> 0 | L21: =SUMIF(BS_RE33!$P$7:$P$874,G21,BS_RE33!$AB$7:$AB$874) -> 0 | M21: =SUMIF(BS_RE33!$P$7:$P$874,G21,BS_RE33!$AC$7:$AC$874) -> 0 | N21: =SUMIF(BS_RE33!$P$7:$P$874,G21,BS_RE33!$AD$7:$AD$874) -> 0 | O21: =SUMIF(BS_RE33!$P$7:$P$874,G21,BS_RE33!$AE$7:$AE$874) -> 0 | P21: =SUMIF(BS_RE33!$P$7:$P$874,G21,BS_RE33!$AF$7:$AF$874) -> 0 | Q21: =SUMIF(BS_RE33!$P$7:$P$874,G21,BS_RE33!$AG$7:$AG$874) -> 0
E22: Other_Asset (Fixed assets) | G22: Other_Asset (Fixed assets)_ | H22: =SUMIF(BS_RE33!$P$7:$P$874,G22,BS_RE33!$X$7:$X$874) -> 0 | I22: =SUMIF(BS_RE33!$P$7:$P$874,G22,BS_RE33!$Y$7:$Y$874) -> 0 | J22: =SUMIF(BS_RE33!$P$7:$P$874,G22,BS_RE33!$Z$7:$Z$874) -> 0 | K22: =SUMIF(BS_RE33!$P$7:$P$874,G22,BS_RE33!$AA$7:$AA$874) -> 0 | L22: =SUMIF(BS_RE33!$P$7:$P$874,G22,BS_RE33!$AB$7:$AB$874) -> 0 | M22: =SUMIF(BS_RE33!$P$7:$P$874,G22,BS_RE33!$AC$7:$AC$874) -> 0 | N22: =SUMIF(BS_RE33!$P$7:$P$874,G22,BS_RE33!$AD$7:$AD$874) -> 0 | O22: =SUMIF(BS_RE33!$P$7:$P$874,G22,BS_RE33!$AE$7:$AE$874) -> 0 | P22: =SUMIF(BS_RE33!$P$7:$P$874,G22,BS_RE33!$AF$7:$AF$874) -> 0 | Q22: =SUMIF(BS_RE33!$P$7:$P$874,G22,BS_RE33!$AG$7:$AG$874) -> 0
E23: Other_Asset (Lease) | G23: Other_Asset (Lease)_ | H23: =SUMIF(BS_RE33!$P$7:$P$874,G23,BS_RE33!$X$7:$X$874) -> 0 | I23: =SUMIF(BS_RE33!$P$7:$P$874,G23,BS_RE33!$Y$7:$Y$874) -> 0 | J23: =SUMIF(BS_RE33!$P$7:$P$874,G23,BS_RE33!$Z$7:$Z$874) -> 0 | K23: =SUMIF(BS_RE33!$P$7:$P$874,G23,BS_RE33!$AA$7:$AA$874) -> 0 | L23: =SUMIF(BS_RE33!$P$7:$P$874,G23,BS_RE33!$AB$7:$AB$874) -> 0 | M23: =SUMIF(BS_RE33!$P$7:$P$874,G23,BS_RE33!$AC$7:$AC$874) -> 0 | N23: =SUMIF(BS_RE33!$P$7:$P$874,G23,BS_RE33!$AD$7:$AD$874) -> 0 | O23: =SUMIF(BS_RE33!$P$7:$P$874,G23,BS_RE33!$AE$7:$AE$874) -> 0 | P23: =SUMIF(BS_RE33!$P$7:$P$874,G23,BS_RE33!$AF$7:$AF$874) -> 0 | Q23: =SUMIF(BS_RE33!$P$7:$P$874,G23,BS_RE33!$AG$7:$AG$874) -> 0
D24: Total Asset : | F24: =SUM(H24:Q24) -> 0 | H24: =SUM(H4:H23) -> 0 | I24: =SUM(I4:I23) -> 0 | J24: =SUM(J4:J23) -> 0 | K24: =SUM(K4:K23) -> 0 | L24: =SUM(L4:L23) -> 0 | M24: =SUM(M4:M23) -> 0 | N24: =SUM(N4:N23) -> 0 | O24: =SUM(O4:O23) -> 0 | ... Q24: =SUM(Q4:Q23) -> 0
C25: Liability | D25: Deposit | E25: On-demand Deposit | F25: Household | G25: On-demand Deposit_Household | H25: =SUMIF(BS_RE33!$P$7:$P$874,G25,BS_RE33!$X$7:$X$874) -> 0 | I25: =SUMIF(BS_RE33!$P$7:$P$874,G25,BS_RE33!$Y$7:$Y$874) -> 0 | J25: =SUMIF(BS_RE33!$P$7:$P$874,G25,BS_RE33!$Z$7:$Z$874) -> 0 | K25: =SUMIF(BS_RE33!$P$7:$P$874,G25,BS_RE33!$AA$7:$AA$874) -> 0 | L25: =SUMIF(BS_RE33!$P$7:$P$874,G25,BS_RE33!$AB$7:$AB$874) -> 0 | M25: =SUMIF(BS_RE33!$P$7:$P$874,G25,BS_RE33!$AC$7:$AC$874) -> 0 | N25: =SUMIF(BS_RE33!$P$7:$P$874,G25,BS_RE33!$AD$7:$AD$874) -> 0 | O25: =SUMIF(BS_RE33!$P$7:$P$874,G25,BS_RE33!$AE$7:$AE$874) -> 0 | P25: =SUMIF(BS_RE33!$P$7:$P$874,G25,BS_RE33!$AF$7:$AF$874) -> 0 | Q25: =SUMIF(BS_RE33!$P$7:$P$874,G25,BS_RE33!$AG$7:$AG$874) -> 0
E26: On-demand Deposit | F26: SME | G26: On-demand Deposit_SME | H26: =SUMIF(BS_RE33!$P$7:$P$874,G26,BS_RE33!$X$7:$X$874) -> 0 | I26: =SUMIF(BS_RE33!$P$7:$P$874,G26,BS_RE33!$Y$7:$Y$874) -> 0 | J26: =SUMIF(BS_RE33!$P$7:$P$874,G26,BS_RE33!$Z$7:$Z$874) -> 0 | K26: =SUMIF(BS_RE33!$P$7:$P$874,G26,BS_RE33!$AA$7:$AA$874) -> 0 | L26: =SUMIF(BS_RE33!$P$7:$P$874,G26,BS_RE33!$AB$7:$AB$874) -> 0 | M26: =SUMIF(BS_RE33!$P$7:$P$874,G26,BS_RE33!$AC$7:$AC$874) -> 0 | N26: =SUMIF(BS_RE33!$P$7:$P$874,G26,BS_RE33!$AD$7:$AD$874) -> 0 | O26: =SUMIF(BS_RE33!$P$7:$P$874,G26,BS_RE33!$AE$7:$AE$874) -> 0 | P26: =SUMIF(BS_RE33!$P$7:$P$874,G26,BS_RE33!$AF$7:$AF$874) -> 0 | Q26: =SUMIF(BS_RE33!$P$7:$P$874,G26,BS_RE33!$AG$7:$AG$874) -> 0
E27: On-demand Deposit | F27: Non-financialcorporations | G27: On-demand Deposit_Non-financialcorporations | H27: =SUMIF(BS_RE33!$P$7:$P$874,G27,BS_RE33!$X$7:$X$874) -> 0 | I27: =SUMIF(BS_RE33!$P$7:$P$874,G27,BS_RE33!$Y$7:$Y$874) -> 0 | J27: =SUMIF(BS_RE33!$P$7:$P$874,G27,BS_RE33!$Z$7:$Z$874) -> 0 | K27: =SUMIF(BS_RE33!$P$7:$P$874,G27,BS_RE33!$AA$7:$AA$874) -> 0 | L27: =SUMIF(BS_RE33!$P$7:$P$874,G27,BS_RE33!$AB$7:$AB$874) -> 0 | M27: =SUMIF(BS_RE33!$P$7:$P$874,G27,BS_RE33!$AC$7:$AC$874) -> 0 | N27: =SUMIF(BS_RE33!$P$7:$P$874,G27,BS_RE33!$AD$7:$AD$874) -> 0 | O27: =SUMIF(BS_RE33!$P$7:$P$874,G27,BS_RE33!$AE$7:$AE$874) -> 0 | P27: =SUMIF(BS_RE33!$P$7:$P$874,G27,BS_RE33!$AF$7:$AF$874) -> 0 | Q27: =SUMIF(BS_RE33!$P$7:$P$874,G27,BS_RE33!$AG$7:$AG$874) -> 0
E28: On-demand Deposit | F28: Other Institution | G28: On-demand Deposit_Other Institution | H28: =SUMIF(BS_RE33!$P$7:$P$874,G28,BS_RE33!$X$7:$X$874) -> 0 | I28: =SUMIF(BS_RE33!$P$7:$P$874,G28,BS_RE33!$Y$7:$Y$874) -> 0 | J28: =SUMIF(BS_RE33!$P$7:$P$874,G28,BS_RE33!$Z$7:$Z$874) -> 0 | K28: =SUMIF(BS_RE33!$P$7:$P$874,G28,BS_RE33!$AA$7:$AA$874) -> 0 | L28: =SUMIF(BS_RE33!$P$7:$P$874,G28,BS_RE33!$AB$7:$AB$874) -> 0 | M28: =SUMIF(BS_RE33!$P$7:$P$874,G28,BS_RE33!$AC$7:$AC$874) -> 0 | N28: =SUMIF(BS_RE33!$P$7:$P$874,G28,BS_RE33!$AD$7:$AD$874) -> 0 | O28: =SUMIF(BS_RE33!$P$7:$P$874,G28,BS_RE33!$AE$7:$AE$874) -> 0 | P28: =SUMIF(BS_RE33!$P$7:$P$874,G28,BS_RE33!$AF$7:$AF$874) -> 0 | Q28: =SUMIF(BS_RE33!$P$7:$P$874,G28,BS_RE33!$AG$7:$AG$874) -> 0
E29: On-demand Deposit | F29: Financialinstitutions | G29: On-demand Deposit_Financialinstitutions | H29: =SUMIF(BS_RE33!$P$7:$P$874,G29,BS_RE33!$X$7:$X$874) -> 0 | I29: =SUMIF(BS_RE33!$P$7:$P$874,G29,BS_RE33!$Y$7:$Y$874) -> 0 | J29: =SUMIF(BS_RE33!$P$7:$P$874,G29,BS_RE33!$Z$7:$Z$874) -> 0 | K29: =SUMIF(BS_RE33!$P$7:$P$874,G29,BS_RE33!$AA$7:$AA$874) -> 0 | L29: =SUMIF(BS_RE33!$P$7:$P$874,G29,BS_RE33!$AB$7:$AB$874) -> 0 | M29: =SUMIF(BS_RE33!$P$7:$P$874,G29,BS_RE33!$AC$7:$AC$874) -> 0 | N29: =SUMIF(BS_RE33!$P$7:$P$874,G29,BS_RE33!$AD$7:$AD$874) -> 0 | O29: =SUMIF(BS_RE33!$P$7:$P$874,G29,BS_RE33!$AE$7:$AE$874) -> 0 | P29: =SUMIF(BS_RE33!$P$7:$P$874,G29,BS_RE33!$AF$7:$AF$874) -> 0 | Q29: =SUMIF(BS_RE33!$P$7:$P$874,G29,BS_RE33!$AG$7:$AG$874) -> 0
E30: Other deposit (Time deposit) | F30: Household | G30: Other deposit (Time deposit)_Household | H30: =SUMIF(BS_RE33!$P$7:$P$874,G30,BS_RE33!$X$7:$X$874) -> 0 | I30: =SUMIF(BS_RE33!$P$7:$P$874,G30,BS_RE33!$Y$7:$Y$874) -> 0 | J30: =SUMIF(BS_RE33!$P$7:$P$874,G30,BS_RE33!$Z$7:$Z$874) -> 0 | K30: =SUMIF(BS_RE33!$P$7:$P$874,G30,BS_RE33!$AA$7:$AA$874) -> 0 | L30: =SUMIF(BS_RE33!$P$7:$P$874,G30,BS_RE33!$AB$7:$AB$874) -> 0 | M30: =SUMIF(BS_RE33!$P$7:$P$874,G30,BS_RE33!$AC$7:$AC$874) -> 0 | N30: =SUMIF(BS_RE33!$P$7:$P$874,G30,BS_RE33!$AD$7:$AD$874) -> 0 | O30: =SUMIF(BS_RE33!$P$7:$P$874,G30,BS_RE33!$AE$7:$AE$874) -> 0 | P30: =SUMIF(BS_RE33!$P$7:$P$874,G30,BS_RE33!$AF$7:$AF$874) -> 0 | Q30: =SUMIF(BS_RE33!$P$7:$P$874,G30,BS_RE33!$AG$7:$AG$874) -> 0
E31: Other deposit (Time deposit) | F31: SME | G31: Other deposit (Time deposit)_SME | H31: =SUMIF(BS_RE33!$P$7:$P$874,G31,BS_RE33!$X$7:$X$874) -> 0 | I31: =SUMIF(BS_RE33!$P$7:$P$874,G31,BS_RE33!$Y$7:$Y$874) -> 0 | J31: =SUMIF(BS_RE33!$P$7:$P$874,G31,BS_RE33!$Z$7:$Z$874) -> 0 | K31: =SUMIF(BS_RE33!$P$7:$P$874,G31,BS_RE33!$AA$7:$AA$874) -> 0 | L31: =SUMIF(BS_RE33!$P$7:$P$874,G31,BS_RE33!$AB$7:$AB$874) -> 0 | M31: =SUMIF(BS_RE33!$P$7:$P$874,G31,BS_RE33!$AC$7:$AC$874) -> 0 | N31: =SUMIF(BS_RE33!$P$7:$P$874,G31,BS_RE33!$AD$7:$AD$874) -> 0 | O31: =SUMIF(BS_RE33!$P$7:$P$874,G31,BS_RE33!$AE$7:$AE$874) -> 0 | P31: =SUMIF(BS_RE33!$P$7:$P$874,G31,BS_RE33!$AF$7:$AF$874) -> 0 | Q31: =SUMIF(BS_RE33!$P$7:$P$874,G31,BS_RE33!$AG$7:$AG$874) -> 0
E32: Other deposit (Time deposit) | F32: Non-financialcorporations | G32: Other deposit (Time deposit)_Non-financialcorporations | H32: =SUMIF(BS_RE33!$P$7:$P$874,G32,BS_RE33!$X$7:$X$874) -> 0 | I32: =SUMIF(BS_RE33!$P$7:$P$874,G32,BS_RE33!$Y$7:$Y$874) -> 0 | J32: =SUMIF(BS_RE33!$P$7:$P$874,G32,BS_RE33!$Z$7:$Z$874) -> 0 | K32: =SUMIF(BS_RE33!$P$7:$P$874,G32,BS_RE33!$AA$7:$AA$874) -> 0 | L32: =SUMIF(BS_RE33!$P$7:$P$874,G32,BS_RE33!$AB$7:$AB$874) -> 0 | M32: =SUMIF(BS_RE33!$P$7:$P$874,G32,BS_RE33!$AC$7:$AC$874) -> 0 | N32: =SUMIF(BS_RE33!$P$7:$P$874,G32,BS_RE33!$AD$7:$AD$874) -> 0 | O32: =SUMIF(BS_RE33!$P$7:$P$874,G32,BS_RE33!$AE$7:$AE$874) -> 0 | P32: =SUMIF(BS_RE33!$P$7:$P$874,G32,BS_RE33!$AF$7:$AF$874) -> 0 | Q32: =SUMIF(BS_RE33!$P$7:$P$874,G32,BS_RE33!$AG$7:$AG$874) -> 0
E33: Other deposit (Time deposit) | F33: Other Institution | G33: Other deposit (Time deposit)_Other Institution | H33: =SUMIF(BS_RE33!$P$7:$P$874,G33,BS_RE33!$X$7:$X$874) -> 0 | I33: =SUMIF(BS_RE33!$P$7:$P$874,G33,BS_RE33!$Y$7:$Y$874) -> 0 | J33: =SUMIF(BS_RE33!$P$7:$P$874,G33,BS_RE33!$Z$7:$Z$874) -> 0 | K33: =SUMIF(BS_RE33!$P$7:$P$874,G33,BS_RE33!$AA$7:$AA$874) -> 0 | L33: =SUMIF(BS_RE33!$P$7:$P$874,G33,BS_RE33!$AB$7:$AB$874) -> 0 | M33: =SUMIF(BS_RE33!$P$7:$P$874,G33,BS_RE33!$AC$7:$AC$874) -> 0 | N33: =SUMIF(BS_RE33!$P$7:$P$874,G33,BS_RE33!$AD$7:$AD$874) -> 0 | O33: =SUMIF(BS_RE33!$P$7:$P$874,G33,BS_RE33!$AE$7:$AE$874) -> 0 | P33: =SUMIF(BS_RE33!$P$7:$P$874,G33,BS_RE33!$AF$7:$AF$874) -> 0 | Q33: =SUMIF(BS_RE33!$P$7:$P$874,G33,BS_RE33!$AG$7:$AG$874) -> 0
E34: Other deposit (Time deposit) | F34: Financialinstitutions | G34: Other deposit (Time deposit)_Financialinstitutions | H34: =SUMIF(BS_RE33!$P$7:$P$874,G34,BS_RE33!$X$7:$X$874) -> 0 | I34: =SUMIF(BS_RE33!$P$7:$P$874,G34,BS_RE33!$Y$7:$Y$874) -> 0 | J34: =SUMIF(BS_RE33!$P$7:$P$874,G34,BS_RE33!$Z$7:$Z$874) -> 0 | K34: =SUMIF(BS_RE33!$P$7:$P$874,G34,BS_RE33!$AA$7:$AA$874) -> 0 | L34: =SUMIF(BS_RE33!$P$7:$P$874,G34,BS_RE33!$AB$7:$AB$874) -> 0 | M34: =SUMIF(BS_RE33!$P$7:$P$874,G34,BS_RE33!$AC$7:$AC$874) -> 0 | N34: =SUMIF(BS_RE33!$P$7:$P$874,G34,BS_RE33!$AD$7:$AD$874) -> 0 | O34: =SUMIF(BS_RE33!$P$7:$P$874,G34,BS_RE33!$AE$7:$AE$874) -> 0 | P34: =SUMIF(BS_RE33!$P$7:$P$874,G34,BS_RE33!$AF$7:$AF$874) -> 0 | Q34: =SUMIF(BS_RE33!$P$7:$P$874,G34,BS_RE33!$AG$7:$AG$874) -> 0
D35: Certificate of Deposit (CD) | E35: Deposit (Certificate of Deposit) | G35: Deposit (Certificate of Deposit)_ | H35: =SUMIF(BS_RE33!$P$7:$P$874,G35,BS_RE33!$X$7:$X$874) -> 0 | I35: =SUMIF(BS_RE33!$P$7:$P$874,G35,BS_RE33!$Y$7:$Y$874) -> 0 | J35: =SUMIF(BS_RE33!$P$7:$P$874,G35,BS_RE33!$Z$7:$Z$874) -> 0 | K35: =SUMIF(BS_RE33!$P$7:$P$874,G35,BS_RE33!$AA$7:$AA$874) -> 0 | L35: =SUMIF(BS_RE33!$P$7:$P$874,G35,BS_RE33!$AB$7:$AB$874) -> 0 | M35: =SUMIF(BS_RE33!$P$7:$P$874,G35,BS_RE33!$AC$7:$AC$874) -> 0 | N35: =SUMIF(BS_RE33!$P$7:$P$874,G35,BS_RE33!$AD$7:$AD$874) -> 0 | O35: =SUMIF(BS_RE33!$P$7:$P$874,G35,BS_RE33!$AE$7:$AE$874) -> 0 | P35: =SUMIF(BS_RE33!$P$7:$P$874,G35,BS_RE33!$AF$7:$AF$874) -> 0 | Q35: =SUMIF(BS_RE33!$P$7:$P$874,G35,BS_RE33!$AG$7:$AG$874) -> 0
E36: Deposit (Term Certificate of Deposit) | G36: Deposit (Term Certificate of Deposit)_ | H36: =SUMIF(BS_RE33!$P$7:$P$874,G36,BS_RE33!$X$7:$X$874) -> 0 | I36: =SUMIF(BS_RE33!$P$7:$P$874,G36,BS_RE33!$Y$7:$Y$874) -> 0 | J36: =SUMIF(BS_RE33!$P$7:$P$874,G36,BS_RE33!$Z$7:$Z$874) -> 0 | K36: =SUMIF(BS_RE33!$P$7:$P$874,G36,BS_RE33!$AA$7:$AA$874) -> 0 | L36: =SUMIF(BS_RE33!$P$7:$P$874,G36,BS_RE33!$AB$7:$AB$874) -> 0 | M36: =SUMIF(BS_RE33!$P$7:$P$874,G36,BS_RE33!$AC$7:$AC$874) -> 0 | N36: =SUMIF(BS_RE33!$P$7:$P$874,G36,BS_RE33!$AD$7:$AD$874) -> 0 | O36: =SUMIF(BS_RE33!$P$7:$P$874,G36,BS_RE33!$AE$7:$AE$874) -> 0 | P36: =SUMIF(BS_RE33!$P$7:$P$874,G36,BS_RE33!$AF$7:$AF$874) -> 0 | Q36: =SUMIF(BS_RE33!$P$7:$P$874,G36,BS_RE33!$AG$7:$AG$874) -> 0
D37: Borrowing | E37: Borrowing (Short term borrowoing) | G37: Borrowing (Short term borrowoing)_ | H37: =SUMIF(BS_RE33!$P$7:$P$874,G37,BS_RE33!$X$7:$X$874) -> 0 | I37: =SUMIF(BS_RE33!$P$7:$P$874,G37,BS_RE33!$Y$7:$Y$874) -> 0 | J37: =SUMIF(BS_RE33!$P$7:$P$874,G37,BS_RE33!$Z$7:$Z$874) -> 0 | K37: =SUMIF(BS_RE33!$P$7:$P$874,G37,BS_RE33!$AA$7:$AA$874) -> 0 | L37: =SUMIF(BS_RE33!$P$7:$P$874,G37,BS_RE33!$AB$7:$AB$874) -> 0 | M37: =SUMIF(BS_RE33!$P$7:$P$874,G37,BS_RE33!$AC$7:$AC$874) -> 0 | N37: =SUMIF(BS_RE33!$P$7:$P$874,G37,BS_RE33!$AD$7:$AD$874) -> 0 | O37: =SUMIF(BS_RE33!$P$7:$P$874,G37,BS_RE33!$AE$7:$AE$874) -> 0 | P37: =SUMIF(BS_RE33!$P$7:$P$874,G37,BS_RE33!$AF$7:$AF$874) -> 0 | Q37: =SUMIF(BS_RE33!$P$7:$P$874,G37,BS_RE33!$AG$7:$AG$874) -> 0
E38: Borrowing (Long term borrowoing) | G38: Borrowing (Long term borrowoing)_ | H38: =SUMIF(BS_RE33!$P$7:$P$874,G38,BS_RE33!$X$7:$X$874) -> 0 | I38: =SUMIF(BS_RE33!$P$7:$P$874,G38,BS_RE33!$Y$7:$Y$874) -> 0 | J38: =SUMIF(BS_RE33!$P$7:$P$874,G38,BS_RE33!$Z$7:$Z$874) -> 0 | K38: =SUMIF(BS_RE33!$P$7:$P$874,G38,BS_RE33!$AA$7:$AA$874) -> 0 | L38: =SUMIF(BS_RE33!$P$7:$P$874,G38,BS_RE33!$AB$7:$AB$874) -> 0 | M38: =SUMIF(BS_RE33!$P$7:$P$874,G38,BS_RE33!$AC$7:$AC$874) -> 0 | N38: =SUMIF(BS_RE33!$P$7:$P$874,G38,BS_RE33!$AD$7:$AD$874) -> 0 | O38: =SUMIF(BS_RE33!$P$7:$P$874,G38,BS_RE33!$AE$7:$AE$874) -> 0 | P38: =SUMIF(BS_RE33!$P$7:$P$874,G38,BS_RE33!$AF$7:$AF$874) -> 0 | Q38: =SUMIF(BS_RE33!$P$7:$P$874,G38,BS_RE33!$AG$7:$AG$874) -> 0
D39: Bond | E39: Bond issued | G39: Bond issued_ | H39: =SUMIF(BS_RE33!$P$7:$P$874,G39,BS_RE33!$X$7:$X$874) -> 0 | I39: =SUMIF(BS_RE33!$P$7:$P$874,G39,BS_RE33!$Y$7:$Y$874) -> 0 | J39: =SUMIF(BS_RE33!$P$7:$P$874,G39,BS_RE33!$Z$7:$Z$874) -> 0 | K39: =SUMIF(BS_RE33!$P$7:$P$874,G39,BS_RE33!$AA$7:$AA$874) -> 0 | L39: =SUMIF(BS_RE33!$P$7:$P$874,G39,BS_RE33!$AB$7:$AB$874) -> 0 | M39: =SUMIF(BS_RE33!$P$7:$P$874,G39,BS_RE33!$AC$7:$AC$874) -> 0 | N39: =SUMIF(BS_RE33!$P$7:$P$874,G39,BS_RE33!$AD$7:$AD$874) -> 0 | O39: =SUMIF(BS_RE33!$P$7:$P$874,G39,BS_RE33!$AE$7:$AE$874) -> 0 | P39: =SUMIF(BS_RE33!$P$7:$P$874,G39,BS_RE33!$AF$7:$AF$874) -> 0 | Q39: =SUMIF(BS_RE33!$P$7:$P$874,G39,BS_RE33!$AG$7:$AG$874) -> 0
D40: Derivative | E40: Derivative_Liability | G40: Derivative_Liability_ | H40: =SUMIF(BS_RE33!$P$7:$P$874,G40,BS_RE33!$X$7:$X$874) -> 0 | I40: =SUMIF(BS_RE33!$P$7:$P$874,G40,BS_RE33!$Y$7:$Y$874) -> 0 | J40: =SUMIF(BS_RE33!$P$7:$P$874,G40,BS_RE33!$Z$7:$Z$874) -> 0 | K40: =SUMIF(BS_RE33!$P$7:$P$874,G40,BS_RE33!$AA$7:$AA$874) -> 0 | L40: =SUMIF(BS_RE33!$P$7:$P$874,G40,BS_RE33!$AB$7:$AB$874) -> 0 | M40: =SUMIF(BS_RE33!$P$7:$P$874,G40,BS_RE33!$AC$7:$AC$874) -> 0 | N40: =SUMIF(BS_RE33!$P$7:$P$874,G40,BS_RE33!$AD$7:$AD$874) -> 0 | O40: =SUMIF(BS_RE33!$P$7:$P$874,G40,BS_RE33!$AE$7:$AE$874) -> 0 | P40: =SUMIF(BS_RE33!$P$7:$P$874,G40,BS_RE33!$AF$7:$AF$874) -> 0 | Q40: =SUMIF(BS_RE33!$P$7:$P$874,G40,BS_RE33!$AG$7:$AG$874) -> 0
D41: Inter-office | E41: Inter-office (Inter-office A/Paid-in capital) | G41: Inter-office (Inter-office A/Paid-in capital)_ | H41: =SUMIF(BS_RE33!$P$7:$P$874,G41,BS_RE33!$X$7:$X$874) -> 0 | I41: =SUMIF(BS_RE33!$P$7:$P$874,G41,BS_RE33!$Y$7:$Y$874) -> 0 | J41: =SUMIF(BS_RE33!$P$7:$P$874,G41,BS_RE33!$Z$7:$Z$874) -> 0 | K41: =SUMIF(BS_RE33!$P$7:$P$874,G41,BS_RE33!$AA$7:$AA$874) -> 0 | L41: =SUMIF(BS_RE33!$P$7:$P$874,G41,BS_RE33!$AB$7:$AB$874) -> 0 | M41: =SUMIF(BS_RE33!$P$7:$P$874,G41,BS_RE33!$AC$7:$AC$874) -> 0 | N41: =SUMIF(BS_RE33!$P$7:$P$874,G41,BS_RE33!$AD$7:$AD$874) -> 0 | O41: =SUMIF(BS_RE33!$P$7:$P$874,G41,BS_RE33!$AE$7:$AE$874) -> 0 | P41: =SUMIF(BS_RE33!$P$7:$P$874,G41,BS_RE33!$AF$7:$AF$874) -> 0 | Q41: =SUMIF(BS_RE33!$P$7:$P$874,G41,BS_RE33!$AG$7:$AG$874) -> 0
...

Sheet BS_RE33
V3: Liquidity Maturity Gap Management | X3: Overnight (O/N) | Y3: 2-7 Days | Z3: 8 Days to <1 month | AA3: 1 to < 3 months | AB3: 3 to < 6 months | AC3: 6 to < 12 months | AD3: 1 to < 3 years | AE3: 3 to < 5 years | AF3: 5 to < 10 years | AG3: 10+ years or No Maturity
M4: Mannual Entry!!! ☞ | N4: 46058 | W4: From | X4: =N4 -> 46058 | Y4: =X5+1 -> 46060 | Z4: =Y5+1 -> 46066 | AA4: =Z5+1 -> 46087 | AB4: =AA5+1 -> 46148 | AC4: =AB5+1 -> 46240 | AD4: =AC5+1 -> 46424 | AE4: =AD5+1 -> 47155 | AF4: =AE5+1 -> 47885 | AG4: =AF5+1 -> 49711
A5: 10212001 | B5: Due from Domestic Banks on Demand | C5: RCH3001AUD | D5: 100000006 | E5: AUSTRALIA AND NEW ZEALAND BANKING GROUP LTD | F5: AUD | G5: 19661.8 | H5: 19661.8 | R5: LCR Information | W5: To | X5: =$X$4+1 -> 46059 | Y5: =$X$4+7 -> 46065 | Z5: =EDATE($X$4,1) -> 46086 | AA5: =EDATE($X$4,3) -> 46147 | AB5: =EDATE($X$4,6) -> 46239 | AC5: =EDATE($X$4,12) -> 46423 | AD5: =EDATE($X$4,36) -> 47154 | AE5: =EDATE($X$4,60) -> 47884 | AF5: =EDATE($X$4,120) -> 49710 | AG5: ='Maturity Adjustment'!C6 -> 401768 | AH5: =AND(AH7:AH874) -> TRUE
A6: 10212001 | B6: Due from Domestic Banks on Demand | C6: RCH3002AUD | D6: 100000006 | E6: AUSTRALIA AND NEW ZEALAND BANKING GROUP LTD | F6: AUD | G6: 4896.04 | H6: 4896.04 | L6: Category | M6: Middle Category | N6: HQLA/Non Cash Flow Cash Inflow /Outflow | O6: Customer Type | P6: Ref. | Q6: Adjusted Base Ccy Amt | R6: Assumptions (%) | S6: LCR Maturity | T6: # of Days | U6: HQLA or Weighted Amount | V6: Liquidity Maturity | W6: Asset / Liability | X6: CA / CL AMT | Y6: CA / CL AMT | Z6: CA / CL AMT | AA6: CA / CL AMT | AB6: CA / CL AMT | AC6: CA / CL AMT | AD6: CA / CL AMT | AE6: CA / CL AMT | AF6: CA / CL AMT | AG6: CA / CL AMT | AH6: True OR False
A7: 10212001 | B7: Due from Domestic Banks on Demand | C7: RCH3003AUD | D7: 100000006 | E7: AUSTRALIA AND NEW ZEALAND BANKING GROUP LTD | F7: AUD | G7: 87377.23 | H7: 87377.23 | L7: =VLOOKUP(A7,'Account Mapping'!$A$2:$E$216,3,0) -> #N/A | M7: =VLOOKUP(A7,'Account Mapping'!$A$2:$E$216,4,0) -> #N/A | N7: =IF(OR(C7='Account Mapping'!$H$4,C7='Account Mapping'!$H$5,C7='Account Mapping'!$H$6),'Account Mapping'!$I$4,VLOOKUP(A7,'Account Mapping'!$A$2:$E$216,5,0)) -> #N/A | O7: =IF(OR(L7="Loan",L7="Deposit_Liability",L7="OFF_Unused Loan Commitment",L7="HQLA"),VLOOKUP(D7,'Customer Type'!$A$3:$C$38,3,0),"") -> #N/A | P7: =M7&"_"&O7 -> #N/A | Q7: =IF(COUNTIF('Account Mapping'!$H$12:$H$45,A7)>0,-H7,H7) -> 87377.23 | R7: =VLOOKUP(P7,Assumptions!$C$2:$D$64,2,0) -> #N/A | S7: =IFERROR(VLOOKUP(A7,'Maturity Adjustment'!$A$3:$C$81,3,0),(IF(J7<$N$4,"Tomorrow",J7))) -> Tomorrow | T7: =IF(S7="Tomorrow",1,(S7-$N$4)) -> 1 | U7: =Q7*R7 -> #N/A | V7: =IFERROR(VLOOKUP(A7,'Maturity Adjustment'!$A$86:$C$91,3,0),S7) -> Tomorrow | W7: =VLOOKUP(A7,'Account Mapping'!$A$2:$F$216,6,0) -> #N/A | X7: =IF(V7="Tomorrow",Q7,IF(AND(V7>$X$4-1,V7<$X$5),Q7,IF(V7=$X$5,Q7,0))) -> 87377.23 | Y7: =IF(AND(V7>$Y$4-1,V7<$Y$5),Q7,IF(V7=$Y$5,Q7,0)) -> 0 | Z7: =IF(AND(V7>$Z$4-1,V7<$Z$5),Q7,IF(V7=$Z$5,Q7,0)) -> 0 | AA7: =IF(AND(V7>$AA$4-1,V7<$AA$5),Q7,IF(V7=$AA$5,Q7,0)) -> 0 | AB7: =IF(AND(V7>$AB$4-1,V7<$AB$5),Q7,IF(V7=$AB$5,Q7,0)) -> 0 | AC7: =IF(AND(V7>$AC$4-1,V7<$AC$5),Q7,IF(V7=$AC$5,Q7,0)) -> 0 | AD7: =IF(AND(V7>$AD$4-1,V7<$AD$5),Q7,IF(V7=$AD$5,Q7,0)) -> 0 | AE7: =IF(AND(V7>$AE$4-1,V7<$AE$5),Q7,IF(V7=$AE$5,Q7,0)) -> 0 | AF7: =IF(AND(V7>$AF$4-1,V7<$AF$5),Q7,IF(V7=$AF$5,Q7,0)) -> 0 | AG7: =IF(AND(V7>$AG$4-1,V7<$AG$5),Q7,IF(V7=$AG$5,Q7,0)) -> 0 | AH7: =Q7=SUM(X7:AG7) -> TRUE | AJ7: Liquidity Gap Ratio
A8: 10212001 | B8: Due from Domestic Banks on Demand | C8: RCH3004AUD | D8: 100000013 | E8: KEB HANA BANK | F8: AUD | G8: 4600972.1 | H8: 4600972.1 | L8: =VLOOKUP(A8,'Account Mapping'!$A$2:$E$216,3,0) -> #N/A | M8: =VLOOKUP(A8,'Account Mapping'!$A$2:$E$216,4,0) -> #N/A | N8: =IF(OR(C8='Account Mapping'!$H$4,C8='Account Mapping'!$H$5,C8='Account Mapping'!$H$6),'Account Mapping'!$I$4,VLOOKUP(A8,'Account Mapping'!$A$2:$E$216,5,0)) -> #N/A | O8: =IF(OR(L8="Loan",L8="Deposit_Liability",L8="OFF_Unused Loan Commitment",L8="HQLA"),VLOOKUP(D8,'Customer Type'!$A$3:$C$38,3,0),"") -> #N/A | P8: =M8&"_"&O8 -> #N/A | Q8: =IF(COUNTIF('Account Mapping'!$H$12:$H$45,A8)>0,-H8,H8) -> 4600972.1 | R8: =VLOOKUP(P8,Assumptions!$C$2:$D$64,2,0) -> #N/A | S8: =IFERROR(VLOOKUP(A8,'Maturity Adjustment'!$A$3:$C$81,3,0),(IF(J8<$N$4,"Tomorrow",J8))) -> Tomorrow | T8: =IF(S8="Tomorrow",1,(S8-$N$4)) -> 1 | U8: =Q8*R8 -> #N/A | V8: =IFERROR(VLOOKUP(A8,'Maturity Adjustment'!$A$86:$C$91,3,0),S8) -> Tomorrow | W8: =VLOOKUP(A8,'Account Mapping'!$A$2:$F$216,6,0) -> #N/A | X8: =IF(V8="Tomorrow",Q8,IF(AND(V8>$X$4-1,V8<$X$5),Q8,IF(V8=$X$5,Q8,0))) -> 4600972.1 | Y8: =IF(AND(V8>$Y$4-1,V8<$Y$5),Q8,IF(V8=$Y$5,Q8,0)) -> 0 | Z8: =IF(AND(V8>$Z$4-1,V8<$Z$5),Q8,IF(V8=$Z$5,Q8,0)) -> 0 | AA8: =IF(AND(V8>$AA$4-1,V8<$AA$5),Q8,IF(V8=$AA$5,Q8,0)) -> 0 | AB8: =IF(AND(V8>$AB$4-1,V8<$AB$5),Q8,IF(V8=$AB$5,Q8,0)) -> 0 | AC8: =IF(AND(V8>$AC$4-1,V8<$AC$5),Q8,IF(V8=$AC$5,Q8,0)) -> 0 | AD8: =IF(AND(V8>$AD$4-1,V8<$AD$5),Q8,IF(V8=$AD$5,Q8,0)) -> 0 | AE8: =IF(AND(V8>$AE$4-1,V8<$AE$5),Q8,IF(V8=$AE$5,Q8,0)) -> 0 | AF8: =IF(AND(V8>$AF$4-1,V8<$AF$5),Q8,IF(V8=$AF$5,Q8,0)) -> 0 | AG8: =IF(AND(V8>$AG$4-1,V8<$AG$5),Q8,IF(V8=$AG$5,Q8,0)) -> 0 | AH8: =Q8=SUM(X8:AG8) -> TRUE
A9: 10212001 | B9: Due from Domestic Banks on Demand | C9: RCH3004USD | D9: 100000013 | E9: KEB HANA BANK | F9: USD | G9: 1351406.1 | H9: 1923983.7 | L9: =VLOOKUP(A9,'Account Mapping'!$A$2:$E$216,3,0) -> #N/A | M9: =VLOOKUP(A9,'Account Mapping'!$A$2:$E$216,4,0) -> #N/A | N9: =IF(OR(C9='Account Mapping'!$H$4,C9='Account Mapping'!$H$5,C9='Account Mapping'!$H$6),'Account Mapping'!$I$4,VLOOKUP(A9,'Account Mapping'!$A$2:$E$216,5,0)) -> #N/A | O9: =IF(OR(L9="Loan",L9="Deposit_Liability",L9="OFF_Unused Loan Commitment",L9="HQLA"),VLOOKUP(D9,'Customer Type'!$A$3:$C$38,3,0),"") -> #N/A | P9: =M9&"_"&O9 -> #N/A | Q9: =IF(COUNTIF('Account Mapping'!$H$12:$H$45,A9)>0,-H9,H9) -> 1923983.7 | R9: =VLOOKUP(P9,Assumptions!$C$2:$D$64,2,0) -> #N/A | S9: =IFERROR(VLOOKUP(A9,'Maturity Adjustment'!$A$3:$C$81,3,0),(IF(J9<$N$4,"Tomorrow",J9))) -> Tomorrow | T9: =IF(S9="Tomorrow",1,(S9-$N$4)) -> 1 | U9: =Q9*R9 -> #N/A | V9: =IFERROR(VLOOKUP(A9,'Maturity Adjustment'!$A$86:$C$91,3,0),S9) -> Tomorrow | W9: =VLOOKUP(A9,'Account Mapping'!$A$2:$F$216,6,0) -> #N/A | X9: =IF(V9="Tomorrow",Q9,IF(AND(V9>$X$4-1,V9<$X$5),Q9,IF(V9=$X$5,Q9,0))) -> 1923983.7 | Y9: =IF(AND(V9>$Y$4-1,V9<$Y$5),Q9,IF(V9=$Y$5,Q9,0)) -> 0 | Z9: =IF(AND(V9>$Z$4-1,V9<$Z$5),Q9,IF(V9=$Z$5,Q9,0)) -> 0 | AA9: =IF(AND(V9>$AA$4-1,V9<$AA$5),Q9,IF(V9=$AA$5,Q9,0)) -> 0 | AB9: =IF(AND(V9>$AB$4-1,V9<$AB$5),Q9,IF(V9=$AB$5,Q9,0)) -> 0 | AC9: =IF(AND(V9>$AC$4-1,V9<$AC$5),Q9,IF(V9=$AC$5,Q9,0)) -> 0 | AD9: =IF(AND(V9>$AD$4-1,V9<$AD$5),Q9,IF(V9=$AD$5,Q9,0)) -> 0 | AE9: =IF(AND(V9>$AE$4-1,V9<$AE$5),Q9,IF(V9=$AE$5,Q9,0)) -> 0 | AF9: =IF(AND(V9>$AF$4-1,V9<$AF$5),Q9,IF(V9=$AF$5,Q9,0)) -> 0 | AG9: =IF(AND(V9>$AG$4-1,V9<$AG$5),Q9,IF(V9=$AG$5,Q9,0)) -> 0 | AH9: =Q9=SUM(X9:AG9) -> TRUE | AJ9: 7 day | AK9: From | AL9: =EOMONTH(N4,0) -> 46081 | AM9: =EOMONTH(AL9,1) -> 46112 | AN9: =EOMONTH(AM9,1) -> 46142 | AO9: =EOMONTH(AN9,1) -> 46173 | AP9: =EOMONTH(AO9,1) -> 46203 | AQ9: =EOMONTH(AP9,1) -> 46234 | AR9: =EOMONTH(AQ9,1) -> 46265 | AS9: =EOMONTH(AR9,1) -> 46295
A10: 10212002 | B10: Due from Oversea Banks on Demand | C10: RCH4001USD | D10: 100000016 | E10: BANK OF AMERICA N.A.(H.O.) | F10: USD | G10: 495563.29 | H10: 705528.6 | L10: =VLOOKUP(A10,'Account Mapping'!$A$2:$E$216,3,0) -> #N/A | M10: =VLOOKUP(A10,'Account Mapping'!$A$2:$E$216,4,0) -> #N/A | N10: =IF(OR(C10='Account Mapping'!$H$4,C10='Account Mapping'!$H$5,C10='Account Mapping'!$H$6),'Account Mapping'!$I$4,VLOOKUP(A10,'Account Mapping'!$A$2:$E$216,5,0)) -> Non Cash Flow | O10: =IF(OR(L10="Loan",L10="Deposit_Liability",L10="OFF_Unused Loan Commitment",L10="HQLA"),VLOOKUP(D10,'Customer Type'!$A$3:$C$38,3,0),"") -> #N/A | P10: =M10&"_"&O10 -> #N/A | Q10: =IF(COUNTIF('Account Mapping'!$H$12:$H$45,A10)>0,-H10,H10) -> 705528.6 | R10: =VLOOKUP(P10,Assumptions!$C$2:$D$64,2,0) -> #N/A | S10: =IFERROR(VLOOKUP(A10,'Maturity Adjustment'!$A$3:$C$81,3,0),(IF(J10<$N$4,"Tomorrow",J10))) -> Tomorrow | T10: =IF(S10="Tomorrow",1,(S10-$N$4)) -> 1 | U10: =Q10*R10 -> #N/A | V10: =IFERROR(VLOOKUP(A10,'Maturity Adjustment'!$A$86:$C$91,3,0),S10) -> Tomorrow | W10: =VLOOKUP(A10,'Account Mapping'!$A$2:$F$216,6,0) -> #N/A | X10: =IF(V10="Tomorrow",Q10,IF(AND(V10>$X$4-1,V10<$X$5),Q10,IF(V10=$X$5,Q10,0))) -> 705528.6 | Y10: =IF(AND(V10>$Y$4-1,V10<$Y$5),Q10,IF(V10=$Y$5,Q10,0)) -> 0 | Z10: =IF(AND(V10>$Z$4-1,V10<$Z$5),Q10,IF(V10=$Z$5,Q10,0)) -> 0 | AA10: =IF(AND(V10>$AA$4-1,V10<$AA$5),Q10,IF(V10=$AA$5,Q10,0)) -> 0 | AB10: =IF(AND(V10>$AB$4-1,V10<$AB$5),Q10,IF(V10=$AB$5,Q10,0)) -> 0 | AC10: =IF(AND(V10>$AC$4-1,V10<$AC$5),Q10,IF(V10=$AC$5,Q10,0)) -> 0 | AD10: =IF(AND(V10>$AD$4-1,V10<$AD$5),Q10,IF(V10=$AD$5,Q10,0)) -> 0 | AE10: =IF(AND(V10>$AE$4-1,V10<$AE$5),Q10,IF(V10=$AE$5,Q10,0)) -> 0 | AF10: =IF(AND(V10>$AF$4-1,V10<$AF$5),Q10,IF(V10=$AF$5,Q10,0)) -> 0 | AG10: =IF(AND(V10>$AG$4-1,V10<$AG$5),Q10,IF(V10=$AG$5,Q10,0)) -> 0 | AH10: =Q10=SUM(X10:AG10) -> TRUE | AK10: To | AL10: =AL9+7 -> 46088 | AM10: =AM9+7 -> 46119 | AN10: =AN9+7 -> 46149 | AO10: =AO9+7 -> 46180 | AP10: =AP9+7 -> 46210 | AQ10: =AQ9+7 -> 46241 | AR10: =AR9+7 -> 46272 | AS10: =AS9+7 -> 46302
A11: 10251002 | B11: Call Loan within 3M - Domestic | C11: FM5904250000051 | D11: 100000008 | E11: E.SUN COMMERCIAL BANK LTD | F11: AUD | G11: 10000000 | H11: 10000000 | I11: 46015 | J11: 46106 | K11: 46106 | L11: =VLOOKUP(A11,'Account Mapping'!$A$2:$E$216,3,0) -> #N/A | M11: =VLOOKUP(A11,'Account Mapping'!$A$2:$E$216,4,0) -> #N/A | N11: =IF(OR(C11='Account Mapping'!$H$4,C11='Account Mapping'!$H$5,C11='Account Mapping'!$H$6),'Account Mapping'!$I$4,VLOOKUP(A11,'Account Mapping'!$A$2:$E$216,5,0)) -> #N/A | O11: =IF(OR(L11="Loan",L11="Deposit_Liability",L11="OFF_Unused Loan Commitment",L11="HQLA"),VLOOKUP(D11,'Customer Type'!$A$3:$C$38,3,0),"") -> #N/A | P11: =M11&"_"&O11 -> #N/A | Q11: =IF(COUNTIF('Account Mapping'!$H$12:$H$45,A11)>0,-H11,H11) -> 10000000 | R11: =VLOOKUP(P11,Assumptions!$C$2:$D$64,2,0) -> #N/A | S11: =IFERROR(VLOOKUP(A11,'Maturity Adjustment'!$A$3:$C$81,3,0),(IF(J11<$N$4,"Tomorrow",J11))) -> 46106 | T11: =IF(S11="Tomorrow",1,(S11-$N$4)) -> 48 | U11: =Q11*R11 -> #N/A | V11: =IFERROR(VLOOKUP(A11,'Maturity Adjustment'!$A$86:$C$91,3,0),S11) -> 46106 | W11: =VLOOKUP(A11,'Account Mapping'!$A$2:$F$216,6,0) -> #N/A | X11: =IF(V11="Tomorrow",Q11,IF(AND(V11>$X$4-1,V11<$X$5),Q11,IF(V11=$X$5,Q11,0))) -> 0 | Y11: =IF(AND(V11>$Y$4-1,V11<$Y$5),Q11,IF(V11=$Y$5,Q11,0)) -> 0 | Z11: =IF(AND(V11>$Z$4-1,V11<$Z$5),Q11,IF(V11=$Z$5,Q11,0)) -> 0 | AA11: =IF(AND(V11>$AA$4-1,V11<$AA$5),Q11,IF(V11=$AA$5,Q11,0)) -> 10000000 | AB11: =IF(AND(V11>$AB$4-1,V11<$AB$5),Q11,IF(V11=$AB$5,Q11,0)) -> 0 | AC11: =IF(AND(V11>$AC$4-1,V11<$AC$5),Q11,IF(V11=$AC$5,Q11,0)) -> 0 | AD11: =IF(AND(V11>$AD$4-1,V11<$AD$5),Q11,IF(V11=$AD$5,Q11,0)) -> 0 | AE11: =IF(AND(V11>$AE$4-1,V11<$AE$5),Q11,IF(V11=$AE$5,Q11,0)) -> 0 | AF11: =IF(AND(V11>$AF$4-1,V11<$AF$5),Q11,IF(V11=$AF$5,Q11,0)) -> 0 | AG11: =IF(AND(V11>$AG$4-1,V11<$AG$5),Q11,IF(V11=$AG$5,Q11,0)) -> 0 | AH11: =Q11=SUM(X11:AG11) -> TRUE
A12: 10251002 | B12: Call Loan within 3M - Domestic | C12: FM5904260000003 | D12: 100000008 | E12: E.SUN COMMERCIAL BANK LTD | F12: AUD | G12: 3000000 | H12: 3000000 | I12: 46035 | J12: 46090 | K12: 46090 | L12: =VLOOKUP(A12,'Account Mapping'!$A$2:$E$216,3,0) -> #N/A | M12: =VLOOKUP(A12,'Account Mapping'!$A$2:$E$216,4,0) -> #N/A | N12: =IF(OR(C12='Account Mapping'!$H$4,C12='Account Mapping'!$H$5,C12='Account Mapping'!$H$6),'Account Mapping'!$I$4,VLOOKUP(A12,'Account Mapping'!$A$2:$E$216,5,0)) -> #N/A | O12: =IF(OR(L12="Loan",L12="Deposit_Liability",L12="OFF_Unused Loan Commitment",L12="HQLA"),VLOOKUP(D12,'Customer Type'!$A$3:$C$38,3,0),"") -> #N/A | P12: =M12&"_"&O12 -> #N/A | Q12: =IF(COUNTIF('Account Mapping'!$H$12:$H$45,A12)>0,-H12,H12) -> 3000000 | R12: =VLOOKUP(P12,Assumptions!$C$2:$D$64,2,0) -> #N/A | S12: =IFERROR(VLOOKUP(A12,'Maturity Adjustment'!$A$3:$C$81,3,0),(IF(J12<$N$4,"Tomorrow",J12))) -> 46090 | T12: =IF(S12="Tomorrow",1,(S12-$N$4)) -> 32 | U12: =Q12*R12 -> #N/A | V12: =IFERROR(VLOOKUP(A12,'Maturity Adjustment'!$A$86:$C$91,3,0),S12) -> 46090 | W12: =VLOOKUP(A12,'Account Mapping'!$A$2:$F$216,6,0) -> #N/A | X12: =IF(V12="Tomorrow",Q12,IF(AND(V12>$X$4-1,V12<$X$5),Q12,IF(V12=$X$5,Q12,0))) -> 0 | Y12: =IF(AND(V12>$Y$4-1,V12<$Y$5),Q12,IF(V12=$Y$5,Q12,0)) -> 0 | Z12: =IF(AND(V12>$Z$4-1,V12<$Z$5),Q12,IF(V12=$Z$5,Q12,0)) -> 0 | AA12: =IF(AND(V12>$AA$4-1,V12<$AA$5),Q12,IF(V12=$AA$5,Q12,0)) -> 3000000 | AB12: =IF(AND(V12>$AB$4-1,V12<$AB$5),Q12,IF(V12=$AB$5,Q12,0)) -> 0 | AC12: =IF(AND(V12>$AC$4-1,V12<$AC$5),Q12,IF(V12=$AC$5,Q12,0)) -> 0 | AD12: =IF(AND(V12>$AD$4-1,V12<$AD$5),Q12,IF(V12=$AD$5,Q12,0)) -> 0 | AE12: =IF(AND(V12>$AE$4-1,V12<$AE$5),Q12,IF(V12=$AE$5,Q12,0)) -> 0 | AF12: =IF(AND(V12>$AF$4-1,V12<$AF$5),Q12,IF(V12=$AF$5,Q12,0)) -> 0 | AG12: =IF(AND(V12>$AG$4-1,V12<$AG$5),Q12,IF(V12=$AG$5,Q12,0)) -> 0 | AH12: =Q12=SUM(X12:AG12) -> TRUE | AL12: =AL9 -> 46081 | AM12: =AM9 -> 46112 | AN12: =AN9 -> 46142 | AO12: =AO9 -> 46173 | AP12: =AP9 -> 46203 | AQ12: =AQ9 -> 46234 | AR12: =AR9 -> 46265 | AS12: =AS9 -> 46295
A13: 10251002 | B13: Call Loan within 3M - Domestic | C13: FM5904260000004 | D13: 100000008 | E13: E.SUN COMMERCIAL BANK LTD | F13: AUD | G13: 4000000 | H13: 4000000 | I13: 46035 | J13: 46125 | K13: 46125 | L13: =VLOOKUP(A13,'Account Mapping'!$A$2:$E$216,3,0) -> #N/A | M13: =VLOOKUP(A13,'Account Mapping'!$A$2:$E$216,4,0) -> #N/A | N13: =IF(OR(C13='Account Mapping'!$H$4,C13='Account Mapping'!$H$5,C13='Account Mapping'!$H$6),'Account Mapping'!$I$4,VLOOKUP(A13,'Account Mapping'!$A$2:$E$216,5,0)) -> #N/A | O13: =IF(OR(L13="Loan",L13="Deposit_Liability",L13="OFF_Unused Loan Commitment",L13="HQLA"),VLOOKUP(D13,'Customer Type'!$A$3:$C$38,3,0),"") -> #N/A | P13: =M13&"_"&O13 -> #N/A | Q13: =IF(COUNTIF('Account Mapping'!$H$12:$H$45,A13)>0,-H13,H13) -> 4000000 | R13: =VLOOKUP(P13,Assumptions!$C$2:$D$64,2,0) -> #N/A | S13: =IFERROR(VLOOKUP(A13,'Maturity Adjustment'!$A$3:$C$81,3,0),(IF(J13<$N$4,"Tomorrow",J13))) -> 46125 | T13: =IF(S13="Tomorrow",1,(S13-$N$4)) -> 67 | U13: =Q13*R13 -> #N/A | V13: =IFERROR(VLOOKUP(A13,'Maturity Adjustment'!$A$86:$C$91,3,0),S13) -> 46125 | W13: =VLOOKUP(A13,'Account Mapping'!$A$2:$F$216,6,0) -> #N/A | X13: =IF(V13="Tomorrow",Q13,IF(AND(V13>$X$4-1,V13<$X$5),Q13,IF(V13=$X$5,Q13,0))) -> 0 | Y13: =IF(AND(V13>$Y$4-1,V13<$Y$5),Q13,IF(V13=$Y$5,Q13,0)) -> 0 | Z13: =IF(AND(V13>$Z$4-1,V13<$Z$5),Q13,IF(V13=$Z$5,Q13,0)) -> 0 | AA13: =IF(AND(V13>$AA$4-1,V13<$AA$5),Q13,IF(V13=$AA$5,Q13,0)) -> 4000000 | AB13: =IF(AND(V13>$AB$4-1,V13<$AB$5),Q13,IF(V13=$AB$5,Q13,0)) -> 0 | AC13: =IF(AND(V13>$AC$4-1,V13<$AC$5),Q13,IF(V13=$AC$5,Q13,0)) -> 0 | AD13: =IF(AND(V13>$AD$4-1,V13<$AD$5),Q13,IF(V13=$AD$5,Q13,0)) -> 0 | AE13: =IF(AND(V13>$AE$4-1,V13<$AE$5),Q13,IF(V13=$AE$5,Q13,0)) -> 0 | AF13: =IF(AND(V13>$AF$4-1,V13<$AF$5),Q13,IF(V13=$AF$5,Q13,0)) -> 0 | AG13: =IF(AND(V13>$AG$4-1,V13<$AG$5),Q13,IF(V13=$AG$5,Q13,0)) -> 0 | AH13: =Q13=SUM(X13:AG13) -> TRUE | AK13: Asset | AL13: =SUMIFS($H$7:$H$874,$W$7:$W$874,AK13,$V$7:$V$874,">"&AL9,$V$7:$V$874,"<="&AL10)+SUMIFS($H$7:$H$874,$W$7:$W$874,AK13,$V$7:$V$874,"Tomorrow") -> 0 | AM13: =SUMIFS($H$7:$H$874,$W$7:$W$874,AK13,$V$7:$V$874,">"&AM9,$V$7:$V$874,"<="&AM10)+SUMIFS($H$7:$H$874,$W$7:$W$874,AK13,$V$7:$V$874,"Tomorrow") -> 0 | AN13: =SUMIFS($H$7:$H$874,$W$7:$W$874,AK13,$V$7:$V$874,">"&AN9,$V$7:$V$874,"<="&AN10)+SUMIFS($H$7:$H$874,$W$7:$W$874,AK13,$V$7:$V$874,"Tomorrow") -> 0 | AO13: =SUMIFS($H$7:$H$874,$W$7:$W$874,AK13,$V$7:$V$874,">"&AO9,$V$7:$V$874,"<="&AO10)+SUMIFS($H$7:$H$874,$W$7:$W$874,AK13,$V$7:$V$874,"Tomorrow") -> 0 | AP13: =SUMIFS($H$7:$H$874,$W$7:$W$874,AK13,$V$7:$V$874,">"&AP9,$V$7:$V$874,"<="&AP10)+SUMIFS($H$7:$H$874,$W$7:$W$874,AK13,$V$7:$V$874,"Tomorrow") -> 0 | AQ13: =SUMIFS($H$7:$H$874,$W$7:$W$874,AK13,$V$7:$V$874,">"&AQ9,$V$7:$V$874,"<="&AQ10)+SUMIFS($H$7:$H$874,$W$7:$W$874,AK13,$V$7:$V$874,"Tomorrow") -> 0 | AR13: =SUMIFS($H$7:$H$874,$W$7:$W$874,AK13,$V$7:$V$874,">"&AR9,$V$7:$V$874,"<="&AR10)+SUMIFS($H$7:$H$874,$W$7:$W$874,AK13,$V$7:$V$874,"Tomorrow") -> 0 | AS13: =SUMIFS($H$7:$H$874,$W$7:$W$874,AK13,$V$7:$V$874,">"&AS9,$V$7:$V$874,"<="&AS10)+SUMIFS($H$7:$H$874,$W$7:$W$874,AK13,$V$7:$V$874,"Tomorrow") -> 0
A14: 10310002 | B14: Securities - FVOCI State | C14: FB5904240000001 | D14: 100000027 | E14: TREASURY CORPORATION OF VICTORIA | F14: AUD | G14: 5054150 | H14: 5054150 | I14: 45387 | J14: 46343 | K14: 46342 | L14: =VLOOKUP(A14,'Account Mapping'!$A$2:$E$216,3,0) -> #N/A | M14: =VLOOKUP(A14,'Account Mapping'!$A$2:$E$216,4,0) -> #N/A | N14: =IF(OR(C14='Account Mapping'!$H$4,C14='Account Mapping'!$H$5,C14='Account Mapping'!$H$6),'Account Mapping'!$I$4,VLOOKUP(A14,'Account Mapping'!$A$2:$E$216,5,0)) -> #N/A | O14: =IF(OR(L14="Loan",L14="Deposit_Liability",L14="OFF_Unused Loan Commitment",L14="HQLA"),VLOOKUP(D14,'Customer Type'!$A$3:$C$38,3,0),"") -> #N/A | P14: =M14&"_"&O14 -> #N/A | Q14: =IF(COUNTIF('Account Mapping'!$H$12:$H$45,A14)>0,-H14,H14) -> 5054150 | R14: =VLOOKUP(P14,Assumptions!$C$2:$D$64,2,0) -> #N/A | S14: =IFERROR(VLOOKUP(A14,'Maturity Adjustment'!$A$3:$C$81,3,0),(IF(J14<$N$4,"Tomorrow",J14))) -> 46343 | T14: =IF(S14="Tomorrow",1,(S14-$N$4)) -> 285 | U14: =Q14*R14 -> #N/A | V14: =IFERROR(VLOOKUP(A14,'Maturity Adjustment'!$A$86:$C$91,3,0),S14) -> 46343 | W14: =VLOOKUP(A14,'Account Mapping'!$A$2:$F$216,6,0) -> #N/A | X14: =IF(V14="Tomorrow",Q14,IF(AND(V14>$X$4-1,V14<$X$5),Q14,IF(V14=$X$5,Q14,0))) -> 0 | Y14: =IF(AND(V14>$Y$4-1,V14<$Y$5),Q14,IF(V14=$Y$5,Q14,0)) -> 0 | Z14: =IF(AND(V14>$Z$4-1,V14<$Z$5),Q14,IF(V14=$Z$5,Q14,0)) -> 0 | AA14: =IF(AND(V14>$AA$4-1,V14<$AA$5),Q14,IF(V14=$AA$5,Q14,0)) -> 0 | AB14: =IF(AND(V14>$AB$4-1,V14<$AB$5),Q14,IF(V14=$AB$5,Q14,0)) -> 0 | AC14: =IF(AND(V14>$AC$4-1,V14<$AC$5),Q14,IF(V14=$AC$5,Q14,0)) -> 5054150 | AD14: =IF(AND(V14>$AD$4-1,V14<$AD$5),Q14,IF(V14=$AD$5,Q14,0)) -> 0 | AE14: =IF(AND(V14>$AE$4-1,V14<$AE$5),Q14,IF(V14=$AE$5,Q14,0)) -> 0 | AF14: =IF(AND(V14>$AF$4-1,V14<$AF$5),Q14,IF(V14=$AF$5,Q14,0)) -> 0 | AG14: =IF(AND(V14>$AG$4-1,V14<$AG$5),Q14,IF(V14=$AG$5,Q14,0)) -> 0 | AH14: =Q14=SUM(X14:AG14) -> TRUE | AK14: Liability | AL14: =SUMIFS($H$7:$H$874,$W$7:$W$874,AK14,$V$7:$V$874,">"&AL9,$V$7:$V$874,"<="&AL10)+SUMIFS($H$7:$H$874,$W$7:$W$874,AK14,$V$7:$V$874,"Tomorrow") -> 0 | AM14: =SUMIFS($H$7:$H$874,$W$7:$W$874,AK14,$V$7:$V$874,">"&AM9,$V$7:$V$874,"<="&AM10)+SUMIFS($H$7:$H$874,$W$7:$W$874,AK14,$V$7:$V$874,"Tomorrow") -> 0 | AN14: =SUMIFS($H$7:$H$874,$W$7:$W$874,AK14,$V$7:$V$874,">"&AN9,$V$7:$V$874,"<="&AN10)+SUMIFS($H$7:$H$874,$W$7:$W$874,AK14,$V$7:$V$874,"Tomorrow") -> 0 | AO14: =SUMIFS($H$7:$H$874,$W$7:$W$874,AK14,$V$7:$V$874,">"&AO9,$V$7:$V$874,"<="&AO10)+SUMIFS($H$7:$H$874,$W$7:$W$874,AK14,$V$7:$V$874,"Tomorrow") -> 0 | AP14: =SUMIFS($H$7:$H$874,$W$7:$W$874,AK14,$V$7:$V$874,">"&AP9,$V$7:$V$874,"<="&AP10)+SUMIFS($H$7:$H$874,$W$7:$W$874,AK14,$V$7:$V$874,"Tomorrow") -> 0 | AQ14: =SUMIFS($H$7:$H$874,$W$7:$W$874,AK14,$V$7:$V$874,">"&AQ9,$V$7:$V$874,"<="&AQ10)+SUMIFS($H$7:$H$874,$W$7:$W$874,AK14,$V$7:$V$874,"Tomorrow") -> 0 | AR14: =SUMIFS($H$7:$H$874,$W$7:$W$874,AK14,$V$7:$V$874,">"&AR9,$V$7:$V$874,"<="&AR10)+SUMIFS($H$7:$H$874,$W$7:$W$874,AK14,$V$7:$V$874,"Tomorrow") -> 0 | AS14: =SUMIFS($H$7:$H$874,$W$7:$W$874,AK14,$V$7:$V$874,">"&AS9,$V$7:$V$874,"<="&AS10)+SUMIFS($H$7:$H$874,$W$7:$W$874,AK14,$V$7:$V$874,"Tomorrow") -> 0
A15: 10310002 | B15: Securities - FVOCI State | C15: FB5904240000003 | D15: 100000034 | E15: WESTERN AUSTRALIAN TREASURY CORPORATION | F15: AUD | G15: 4000353.9 | H15: 4000353.9 | I15: 45552 | J15: 46091 | K15: 46090 | L15: =VLOOKUP(A15,'Account Mapping'!$A$2:$E$216,3,0) -> #N/A | M15: =VLOOKUP(A15,'Account Mapping'!$A$2:$E$216,4,0) -> #N/A | N15: =IF(OR(C15='Account Mapping'!$H$4,C15='Account Mapping'!$H$5,C15='Account Mapping'!$H$6),'Account Mapping'!$I$4,VLOOKUP(A15,'Account Mapping'!$A$2:$E$216,5,0)) -> #N/A | O15: =IF(OR(L15="Loan",L15="Deposit_Liability",L15="OFF_Unused Loan Commitment",L15="HQLA"),VLOOKUP(D15,'Customer Type'!$A$3:$C$38,3,0),"") -> #N/A | P15: =M15&"_"&O15 -> #N/A | Q15: =IF(COUNTIF('Account Mapping'!$H$12:$H$45,A15)>0,-H15,H15) -> 4000353.9 | R15: =VLOOKUP(P15,Assumptions!$C$2:$D$64,2,0) -> #N/A | S15: =IFERROR(VLOOKUP(A15,'Maturity Adjustment'!$A$3:$C$81,3,0),(IF(J15<$N$4,"Tomorrow",J15))) -> 46091 | T15: =IF(S15="Tomorrow",1,(S15-$N$4)) -> 33 | U15: =Q15*R15 -> #N/A | V15: =IFERROR(VLOOKUP(A15,'Maturity Adjustment'!$A$86:$C$91,3,0),S15) -> 46091 | W15: =VLOOKUP(A15,'Account Mapping'!$A$2:$F$216,6,0) -> #N/A | X15: =IF(V15="Tomorrow",Q15,IF(AND(V15>$X$4-1,V15<$X$5),Q15,IF(V15=$X$5,Q15,0))) -> 0 | Y15: =IF(AND(V15>$Y$4-1,V15<$Y$5),Q15,IF(V15=$Y$5,Q15,0)) -> 0 | Z15: =IF(AND(V15>$Z$4-1,V15<$Z$5),Q15,IF(V15=$Z$5,Q15,0)) -> 0 | AA15: =IF(AND(V15>$AA$4-1,V15<$AA$5),Q15,IF(V15=$AA$5,Q15,0)) -> 4000353.9 | AB15: =IF(AND(V15>$AB$4-1,V15<$AB$5),Q15,IF(V15=$AB$5,Q15,0)) -> 0 | AC15: =IF(AND(V15>$AC$4-1,V15<$AC$5),Q15,IF(V15=$AC$5,Q15,0)) -> 0 | AD15: =IF(AND(V15>$AD$4-1,V15<$AD$5),Q15,IF(V15=$AD$5,Q15,0)) -> 0 | AE15: =IF(AND(V15>$AE$4-1,V15<$AE$5),Q15,IF(V15=$AE$5,Q15,0)) -> 0 | AF15: =IF(AND(V15>$AF$4-1,V15<$AF$5),Q15,IF(V15=$AF$5,Q15,0)) -> 0 | AG15: =IF(AND(V15>$AG$4-1,V15<$AG$5),Q15,IF(V15=$AG$5,Q15,0)) -> 0 | AH15: =Q15=SUM(X15:AG15) -> TRUE | AK15: Gap | AL15: =AL13-AL14 -> 0 | AM15: =AM13-AM14 -> 0 | AN15: =AN13-AN14 -> 0 | AO15: =AO13-AO14 -> 0 | AP15: =AP13-AP14 -> 0 | AQ15: =AQ13-AQ14 -> 0 | AR15: =AR13-AR14 -> 0 | AS15: =AS13-AS14 -> 0
A16: 10310002 | B16: Securities - FVOCI State | C16: FB5904250000003 | D16: 100000038 | E16: TASMANIAN PUBLIC FINANCE CORPORATION | F16: AUD | G16: 4891616.1 | H16: 4891616.1 | I16: 45755 | J16: 46776 | K16: 46775 | L16: =VLOOKUP(A16,'Account Mapping'!$A$2:$E$216,3,0) -> #N/A | M16: =VLOOKUP(A16,'Account Mapping'!$A$2:$E$216,4,0) -> #N/A | N16: =IF(OR(C16='Account Mapping'!$H$4,C16='Account Mapping'!$H$5,C16='Account Mapping'!$H$6),'Account Mapping'!$I$4,VLOOKUP(A16,'Account Mapping'!$A$2:$E$216,5,0)) -> #N/A | O16: =IF(OR(L16="Loan",L16="Deposit_Liability",L16="OFF_Unused Loan Commitment",L16="HQLA"),VLOOKUP(D16,'Customer Type'!$A$3:$C$38,3,0),"") -> #N/A | P16: =M16&"_"&O16 -> #N/A | Q16: =IF(COUNTIF('Account Mapping'!$H$12:$H$45,A16)>0,-H16,H16) -> 4891616.1 | R16: =VLOOKUP(P16,Assumptions!$C$2:$D$64,2,0) -> #N/A | S16: =IFERROR(VLOOKUP(A16,'Maturity Adjustment'!$A$3:$C$81,3,0),(IF(J16<$N$4,"Tomorrow",J16))) -> 46776 | T16: =IF(S16="Tomorrow",1,(S16-$N$4)) -> 718 | U16: =Q16*R16 -> #N/A | V16: =IFERROR(VLOOKUP(A16,'Maturity Adjustment'!$A$86:$C$91,3,0),S16) -> 46776 | W16: =VLOOKUP(A16,'Account Mapping'!$A$2:$F$216,6,0) -> #N/A | X16: =IF(V16="Tomorrow",Q16,IF(AND(V16>$X$4-1,V16<$X$5),Q16,IF(V16=$X$5,Q16,0))) -> 0 | Y16: =IF(AND(V16>$Y$4-1,V16<$Y$5),Q16,IF(V16=$Y$5,Q16,0)) -> 0 | Z16: =IF(AND(V16>$Z$4-1,V16<$Z$5),Q16,IF(V16=$Z$5,Q16,0)) -> 0 | AA16: =IF(AND(V16>$AA$4-1,V16<$AA$5),Q16,IF(V16=$AA$5,Q16,0)) -> 0 | AB16: =IF(AND(V16>$AB$4-1,V16<$AB$5),Q16,IF(V16=$AB$5,Q16,0)) -> 0 | AC16: =IF(AND(V16>$AC$4-1,V16<$AC$5),Q16,IF(V16=$AC$5,Q16,0)) -> 0 | AD16: =IF(AND(V16>$AD$4-1,V16<$AD$5),Q16,IF(V16=$AD$5,Q16,0)) -> 4891616.1 | AE16: =IF(AND(V16>$AE$4-1,V16<$AE$5),Q16,IF(V16=$AE$5,Q16,0)) -> 0 | AF16: =IF(AND(V16>$AF$4-1,V16<$AF$5),Q16,IF(V16=$AF$5,Q16,0)) -> 0 | AG16: =IF(AND(V16>$AG$4-1,V16<$AG$5),Q16,IF(V16=$AG$5,Q16,0)) -> 0 | AH16: =Q16=SUM(X16:AG16) -> TRUE | AK16: Total Asset | AL16: =SUMIF($W$7:$W$874,AK13,$H$7:$H$874) -> 0 | AM16: =AL16 -> 0 | AN16: =AM16 -> 0 | AO16: =AN16 -> 0 | AP16: =AO16 -> 0 | AQ16: =AP16 -> 0 | AR16: =AQ16 -> 0 | AS16: =AR16 -> 0
A17: 10310003 | B17: Foreign GovT & Official Institution - FVOCI | C17: FB5904240000005 | D17: 100000037 | E17: THE EXPORT-IMPORT BANK OF KOREA | F17: USD | G17: 5027374.5 | H17: 7157423.8 | I17: 45624 | J17: 46677 | K17: 46128 | L17: =VLOOKUP(A17,'Account Mapping'!$A$2:$E$216,3,0) -> #N/A | M17: =VLOOKUP(A17,'Account Mapping'!$A$2:$E$216,4,0) -> #N/A | N17: =IF(OR(C17='Account Mapping'!$H$4,C17='Account Mapping'!$H$5,C17='Account Mapping'!$H$6),'Account Mapping'!$I$4,VLOOKUP(A17,'Account Mapping'!$A$2:$E$216,5,0)) -> #N/A | O17: =IF(OR(L17="Loan",L17="Deposit_Liability",L17="OFF_Unused Loan Commitment",L17="HQLA"),VLOOKUP(D17,'Customer Type'!$A$3:$C$38,3,0),"") -> #N/A | P17: =M17&"_"&O17 -> #N/A | Q17: =IF(COUNTIF('Account Mapping'!$H$12:$H$45,A17)>0,-H17,H17) -> 7157423.8 | R17: =VLOOKUP(P17,Assumptions!$C$2:$D$64,2,0) -> #N/A | S17: =IFERROR(VLOOKUP(A17,'Maturity Adjustment'!$A$3:$C$81,3,0),(IF(J17<$N$4,"Tomorrow",J17))) -> 46677 | T17: =IF(S17="Tomorrow",1,(S17-$N$4)) -> 619 | U17: =Q17*R17 -> #N/A | V17: =IFERROR(VLOOKUP(A17,'Maturity Adjustment'!$A$86:$C$91,3,0),S17) -> 46677 | W17: =VLOOKUP(A17,'Account Mapping'!$A$2:$F$216,6,0) -> #N/A | X17: =IF(V17="Tomorrow",Q17,IF(AND(V17>$X$4-1,V17<$X$5),Q17,IF(V17=$X$5,Q17,0))) -> 0 | Y17: =IF(AND(V17>$Y$4-1,V17<$Y$5),Q17,IF(V17=$Y$5,Q17,0)) -> 0 | Z17: =IF(AND(V17>$Z$4-1,V17<$Z$5),Q17,IF(V17=$Z$5,Q17,0)) -> 0 | AA17: =IF(AND(V17>$AA$4-1,V17<$AA$5),Q17,IF(V17=$AA$5,Q17,0)) -> 0 | AB17: =IF(AND(V17>$AB$4-1,V17<$AB$5),Q17,IF(V17=$AB$5,Q17,0)) -> 0 | AC17: =IF(AND(V17>$AC$4-1,V17<$AC$5),Q17,IF(V17=$AC$5,Q17,0)) -> 0 | AD17: =IF(AND(V17>$AD$4-1,V17<$AD$5),Q17,IF(V17=$AD$5,Q17,0)) -> 7157423.8 | AE17: =IF(AND(V17>$AE$4-1,V17<$AE$5),Q17,IF(V17=$AE$5,Q17,0)) -> 0 | AF17: =IF(AND(V17>$AF$4-1,V17<$AF$5),Q17,IF(V17=$AF$5,Q17,0)) -> 0 | AG17: =IF(AND(V17>$AG$4-1,V17<$AG$5),Q17,IF(V17=$AG$5,Q17,0)) -> 0 | AH17: =Q17=SUM(X17:AG17) -> TRUE | AK17: Gap ratio | AL17: =AL15/AL16 -> #DIV/0! | AM17: =AM15/AM16 -> #DIV/0! | AN17: =AN15/AN16 -> #DIV/0! | AO17: =AO15/AO16 -> #DIV/0! | AP17: =AP15/AP16 -> #DIV/0! | AQ17: =AQ15/AQ16 -> #DIV/0! | AR17: =AR15/AR16 -> #DIV/0! | AS17: =AS15/AS16 -> #DIV/0!
